Workbook

Sheet ★ぼんぼり戦略表
A2: ぼんぼり | B2: 45870 | C2: =MONTH(B2) -> 8
B3: =B15 -> 45892 | D3: =TEXT(B3, "aaa") -> 土
B4: 目標売上 | C4: =_xlfn.XLOOKUP(D3, B7:B12, C7:C12, "該当なし") -> 0
B6: 7月 曜日毎の目標売上 | D6: 傾向 | G6: 対策考察
B7: 月 | C7: =SUMIFS('2025(¥)'!$AE$22:$AE$104, '2025(¥)'!$AA$22:$AA$104, MONTH($B$2), '2025(¥)'!$AB$22:$AB$104, B7) -> 0 | D7: 意外と売上高め（法人接待 or 週始め会食？） | G7: 週始め利用促進で「月曜だけの一品」など限定打ち出しも有効
B8: 火 | C8: =SUMIFS('2025(¥)'!$AE$22:$AE$104, '2025(¥)'!$AA$22:$AA$104, MONTH($B$2), '2025(¥)'!$AB$22:$AB$104, B8) -> 0 | D8: 平均値付近でやや波あり | G8: 予約状況に応じて割引率の調整やSNSリマインド配信
B9: 水 | C9: =SUMIFS('2025(¥)'!$AE$22:$AE$104, '2025(¥)'!$AA$22:$AA$104, MONTH($B$2), '2025(¥)'!$AB$22:$AB$104, B9) -> 0 | D9: 最も売上が高く安定、大口予約が入りやすい傾向 | G9: コース・飲み放題準備強化／人員厚め配置を検討
B10: 木 | C10: =SUMIFS('2025(¥)'!$AE$22:$AE$104, '2025(¥)'!$AA$22:$AA$104, MONTH($B$2), '2025(¥)'!$AB$22:$AB$104, B10) -> 0 | D10: 週後半に売上が高まる流れ | G10: 平日限定キャンペーン（早割／ワンドリンク付）で集客拡張
B11: 金 | C11: =SUMIFS('2025(¥)'!$AE$22:$AE$104, '2025(¥)'!$AA$22:$AA$104, MONTH($B$2), '2025(¥)'!$AB$22:$AB$104, B11) -> 0 | D11: 週末需要で高水準安定 | G11: 新規客向けにGoogle口コミ促進（来店時カード配布）
B12: 土 | C12: =SUMIFS('2025(¥)'!$AE$22:$AE$104, '2025(¥)'!$AA$22:$AA$104, MONTH($B$2), '2025(¥)'!$AB$22:$AB$104, B12) -> 0 | D12: 週末は思ったよりも苦戦 | G12: 家族・若年層向け投稿（インスタで昼飲み・記念日訴求など）
B15: 45892 | C15: =TEXT(B15, "aaa") -> 土
A16: 日次 | B16: 売上 | C16: =_xlfn.XLOOKUP(B15, '2025(¥)'!F21:F385,'2025(¥)'!J21:J385,"該当なし") -> 114770 | E16: 月次目標売上 | F16: =INDEX('2025(¥)'!I7:I18, MATCH(MONTH(B2), '2025(¥)'!R7:R18, 0)) -> 5034965 | N16: 月 | O16: 傾向分析
B17: 平均目標売上 | C17: =INDEX('2025(¥)'!K7:K18, MATCH(C2, '2025(¥)'!R7:R18, 0)) -> 251748.25 | E17: 月次累計実績売上 | F17: =C22 -> 3248670
B18: 目標売上 | C18: =_xlfn.XLOOKUP(C15, B7:B12, C7:C12, "該当なし") -> 0 | E18: 差額 | F18: =F16-F17 -> 1786295 | N18: 1月 | O18: A: 月初・末が強い（中旬落ち）
B19: 差額 | C19: =C16-C18 -> 114770 | E19: 当月残営業日 | F19: {=(SUMPRODUCT(('2025(¥)'!F21:F385>=B15)*('2025(¥)'!E21:E385=C2)*('2025(¥)'!D21:D385=1)))-1} -> 6 | N19: 2月 | O19: B: 月末にかけて上がる
B20: 達成率 | C20: =IFERROR(C16/C18,0) -> 0 | E20: 今月1日あたりの目標売上 | F20: =IFERROR(F18/F19,0) -> 297715.84 | N20: 3月 | O20: B: 同様に右肩上がり傾向
N21: 4月 | O21: A: 月初も末も強く安定感あり
A22: 月次 | B22: 累積売上 | C22: =_xlfn.XLOOKUP(B15, '2025(¥)'!F21:F385,'2025(¥)'!Q21:Q385,"該当なし") -> 3248670 | N22: 5月 | O22: B: 徐々に上がる
B23: 累積目標売上 | C23: =_xlfn.XLOOKUP(B15, '2025(¥)'!F21:F385,'2025(¥)'!P21:P385,"該当なし") -> 3521812.2 | N23: 分類 | O23: 説明
B24: 差額 | C24: =C22-C23 -> -273142.16 | N24: A: 初・末が強い | O24: 月初・月末の売上が高く、中旬が落ちるパターン
B25: 達成率 | C25: =IFERROR(C22/C23,0) -> 0.92244272 | N25: B: 徐々に上がる | O25: 月初が弱く、末に向かって売上が上がる
N26: C: 平均的 or 中旬強い | O26: 大きな偏りがない or 中旬が強いパターン
A27: 年次 | B27: 累積売上 | C27: =_xlfn.XLOOKUP(B15, '2025(¥)'!F21:F385,'2025(¥)'!V21:V385,"該当なし") -> 45999488
B28: 累積目標売上 | C28: =_xlfn.XLOOKUP(B15, '2025(¥)'!F21:F385,'2025(¥)'!U21:U385,"該当なし") -> 44091043
B29: 差額 | C29: =C27-C28 -> 1908445.1
B30: 達成率 | C30: =IFERROR(C27/C28,0) -> 1.0432842
B32: 年次目標売上 | C32: ='2025(¥)'!G3 -> 72000000
B33: 目標達成までの残額 | C33: =C32-C27 -> 26000512
B34: 今年の残営業日数 | C34: {=(SUMPRODUCT(('2025(¥)'!F21:F385>=B15)*('2025(¥)'!D21:D385=1)))-1} -> 103
B35: 1日あたりの売上額 | C35: =IFERROR(C33/C34,0) -> 252432.15
B36: 年間達成率 | C36: =1-(C33/C32) -> 0.63888178
B38: 2025年7月の情報
B39: 曜日 | C39: 出現回数 | D39: 加重比率 | E39: 曜日別割当額 | F39: 1日あたり目標
B40: 月 | C40: 4 | D40: 0.1193 | E40: 894636 | F40: 223659
B41: 火 | C41: 5 | D41: 0.1404 | E41: 1053371 | F41: 210674
B42: 水 | C42: 5 | D42: 0.2035 | E42: 1526394 | F42: 305279
B43: 木 | C43: 5 | D43: 0.2281 | E43: 1710568 | F43: 342114
B44: 金 | C44: 4 | D44: 0.2189 | E44: 1641933 | F44: 410483
B45: 土 | C45: 4 | D45: 0.0897 | E45: 673097 | F45: 168274
B46: 日 | D46: 0 | E46: 0 | F46: 0
...

Sheet 2024(¥)
B2: 45292 | E2: ①年間営業日 | G2: ②年間目標売上 | I2: 年間売上％設定 | M2: 年間売上合計 | O2: 年間実質売上 | Q2: 年間利益率 | R2: 年間予想利益額
E3: =SUM(F6:F17) -> 289 | G3: 71220821 | I3: =SUM(AP6:AP17)*100 -> 0.9999996 | K3: =G3*I3 -> 71220793 | M3: =SUM(J20:J385) -> 71220821 | O3: =M3-G3 -> 0 | Q3: 0.21 | R3: =M3*Q3 -> 14956372
B5: 平均日次売上目標額 | E5: 月 | F5: 月次営業日数 | G5: 平均月間売上目標額 | H5: 月次繁閑期%設定 | J5: 月次目標売上 | K5: 日次目標売上 | M5: 月次売上 | N5: 月間差額 | P5: 月次実質% | R5: 1日の売上目標値 参考例 | AO5: =TEXT(K6,"¥0") -> ¥221795
B6: ② ÷ ① | E6: 1月 | F6: =COUNTIF(D20:D50,1) -> 22 | G6: =$B$7*F6 -> 5421654.2 | H6: 0.9 | J6: =G6*H6 -> 4879488.8 | K6: =J6/F6 -> 221794.94 | M6: =SUM(J20:J50) -> 4982374 | N6: =M6-J6 -> 102885.23 | P6: =M6/G6 -> 0.91897672 | R6: 目標売上 | T6: ¥233564 | V6: 0.76 | AO6: =TEXT(K7,"¥0") -> ¥209473 | AP6: =(H6/100)*AQ6 -> 0.0007499997 | AQ6: 0.0833333
B7: =G3/E3 -> 246438.83 | E7: 2月 | F7: =COUNTIF(D51:D79,1) -> 23 | G7: =$B$7*F7 -> 5668093 | H7: 0.85 | J7: =G7*H7 -> 4817879.1 | K7: =J7/F7 -> 209473 | M7: =SUM(J51:J79) -> 5001830 | N7: =M7-J7 -> 183950.93 | P7: =M7/G7 -> 0.88245376 | T7: =T6*V6 -> 177508.64 | AO7: =TEXT(K8,"¥0") -> ¥246439 | AP7: =(H7/100)*AQ7 -> 0.00070833305 | AQ7: 0.0833333
E8: 3月 | F8: =COUNTIF(D80:D110,1) -> 25 | G8: =$B$7*F8 -> 6160970.7 | H8: 1 | J8: =G8*H8 -> 6160970.7 | K8: =J8/F8 -> 246438.83 | M8: =SUM(J80:J110) -> 6460608 | N8: =M8-J8 -> 299637.33 | P8: =M8/G8 -> 1.0486348 | R8: 差額 | T8: =T9-T6 -> 87436 | AO8: =TEXT(K9,"¥0") -> ¥258761 | AP8: =(H8/100)*AQ8 -> 0.000833333 | AQ8: 0.0833333
E9: 4月 | F9: =COUNTIF(D111:D140,1) -> 25 | G9: =$B$7*F9 -> 6160970.7 | H9: 1.05 | J9: =G9*H9 -> 6469019.2 | K9: =J9/F9 -> 258760.77 | M9: =SUM(J111:J140) -> 6676657 | N9: =M9-J9 -> 207637.79 | P9: =M9/G9 -> 1.0837021 | R9: 仮1日売上総合計 | T9: =SUM(V11:V16) -> 321000 | AO9: =TEXT(K10,"¥0") -> ¥246439 | AP9: =(H9/100)*AQ9 -> 0.00087499965 | AQ9: 0.0833333
E10: 5月 | F10: =COUNTIF(D141:D171,1) -> 24 | G10: =$B$7*F10 -> 5914531.8 | H10: 1 | J10: =G10*H10 -> 5914531.8 | K10: =J10/F10 -> 246438.83 | M10: =SUM(J141:J171) -> 6165010 | N10: =M10-J10 -> 250478.15 | P10: =M10/G10 -> 1.0423496 | R10: 項目 | S10: 仮客単価 | T10: 集客数 | V10: 仮1日の売上小計 | AO10: =TEXT(K11,"¥0") -> ¥221795 | AP10: =(H10/100)*AQ10 -> 0.000833333 | AQ10: 0.0833333
E11: 6月 | F11: =COUNTIF(D172:D201,1) -> 25 | G11: =$B$7*F11 -> 6160970.7 | H11: 0.9 | J11: =G11*H11 -> 5544873.6 | K11: =J11/F11 -> 221794.94 | M11: =SUM(J172:J201) -> 5907950 | N11: =M11-J11 -> 363076.39 | P11: =M11/G11 -> 0.95893169 | R11: ランチ | S11: 1100 | T11: 60 | V11: =S11*T11 -> 66000 | AO11: =TEXT(K12,"¥0") -> ¥234117 | AP11: =(H11/100)*AQ11 -> 0.0007499997 | AQ11: 0.0833333
E12: 7月 | F12: =COUNTIF(D202:D232,1) -> 26 | G12: =$B$7*F12 -> 6407409.5 | H12: 0.95 | J12: =G12*H12 -> 6087039 | K12: =J12/F12 -> 234116.89 | M12: =SUM(J202:J232) -> 6522185 | N12: =M12-J12 -> 435145.97 | P12: =M12/G12 -> 1.0179129 | R12: ディナー | S12: 4500 | T12: 20 | V12: =S12*T12 -> 90000 | AO12: =TEXT(K13,"¥0") -> ¥197151 | AP12: =(H12/100)*AQ12 -> 0.00079166635 | AQ12: 0.0833333
E13: 8月 | F13: =COUNTIF(D233:D263,1) -> 22 | G13: =$B$7*F13 -> 5421654.2 | H13: 0.8 | J13: =G13*H13 -> 4337323.4 | K13: =J13/F13 -> 197151.06 | M13: =SUM(J233:J263) -> 4512002 | N13: =M13-J13 -> 174678.64 | P13: =M13/G13 -> 0.8322187 | R13: Party 5500 | S13: 5500 | T13: 30 | V13: =S13*T13 -> 165000 | AO13: =TEXT(K14,"¥0") -> ¥234117 | AP13: =(H13/100)*AQ13 -> 0.0006666664 | AQ13: 0.0833333
E14: 9 月 | F14: =COUNTIF(D264:D293,1) -> 23 | G14: =$B$7*F14 -> 5668093 | H14: 0.95 | J14: =G14*H14 -> 5384688.4 | K14: =J14/F14 -> 234116.89 | M14: =SUM(J264:J293) -> 5425075 | N14: =M14-J14 -> 40386.63 | P14: =M14/G14 -> 0.95712526 | T14: 0 | V14: =S14*T14 -> 0 | AO14: =TEXT(K15,"¥0") -> ¥308049 | AP14: =(H14/100)*AQ14 -> 0.00079166635 | AQ14: 0.0833333
E15: 10月 | F15: =COUNTIF(D294:D324,1) -> 26 | G15: =$B$7*F15 -> 6407409.5 | H15: 1.25 | J15: =G15*H15 -> 8009261.9 | K15: =J15/F15 -> 308048.53 | M15: =SUM(J294:J324) -> 5555530 | N15: =M15-J15 -> -2453731.9 | P15: =M15/G15 -> 0.86704775 | T15: 0 | V15: =S15*T15 -> 0 | AO15: =TEXT(K16,"¥0") -> ¥258761 | AP15: =(H15/100)*AQ15 -> 0.0010416662 | AQ15: 0.0833333
E16: 11月 | F16: =COUNTIF(D325:D354,1) -> 24 | G16: =$B$7*F16 -> 5914531.8 | H16: 1.05 | J16: =G16*H16 -> 6210258.4 | K16: =J16/F16 -> 258760.77 | M16: =SUM(J325:J354) -> 6112150 | N16: =M16-J16 -> -98108.44 | P16: =M16/G16 -> 1.0334123 | T16: 0 | V16: =S16*T16 -> 0 | AO16: =TEXT(K17,"¥0") -> ¥320370 | AP16: =(H16/100)*AQ16 -> 0.00087499965 | AQ16: 0.0833333
E17: 12月 | F17: =COUNTIF(D355:D385,1) -> 24 | G17: =$B$7*F17 -> 5914531.8 | H17: 1.3 | J17: =G17*H17 -> 7688891.4 | K17: =J17/F17 -> 320370.48 | M17: =SUM(J355:J385) -> 7899450 | N17: =M17-J17 -> 210558.6 | P17: =M17/G17 -> 1.3356002 | AP17: =(H17/100)*AQ17 -> 0.0010833329 | AQ17: 0.0833333
E19: 月 | F19: 日程 | G19: 曜日 | H19: 休店日理由 | J19: Daily売上入力 | L19: 目標売上 KPI | M19: 日次実質売上 | N19: 実質% | P19: 月次目標売上 | Q19: 月次実質売上 | R19: 月次差額(勝率) | S19: 月次実質% | U19: 年次目標売上 | V19: 年次実質売上 | W19: 年次差額(勝率) | X19: 年次実質% | AC19: 月 | AD19: 曜日 | AE19: 平均売上 | AF19: 曜日回数 | AH19: 曜日合計額 | AI19: 加重比率
C20: 1 | D20: 0 | E20: =TEXT(AA20,"m") -> 1 | F20: =B2 -> 45292 | G20: =TEXT(AS20,"ddd") -> Mon | H20: 元旦 | J20: 0 | L20: =IF(D20=0,0,$K$6) -> 0 | M20: =IF(D20=0,0,J20-L20) -> 0 | N20: =IFERROR(J20/L20,"0%") -> 0% | P20: =IF(D20=0,0,$K$6) -> 0 | Q20: =IF(D20=0,0,$J$20) -> 0 | R20: =IF(D20=0,0,Q20-P20) -> 0 | S20: =IFERROR(Q20/P20,"0%") -> 0% | U20: =IF(D20=0,0,$L$20) -> 0 | V20: =IF(D20=0,0,$J$20) -> 0 | W20: =IF(D20=0,0,V20-U20) -> 0 | X20: =IFERROR(V20/U20,"0%") -> 0% | Z20: =B2 -> 45292 | AA20: =B2 -> 45292 | AB20: 45292 | AC20: 1 | AD20: 月 | AE20: =IFERROR(AVERAGEIFS(J20:J50,D20:D50,1,G20:G50,"mon"),0) -> 253025 | AF20: =COUNTIFS(D20:D50,1,G20:G50,"Mon") -> 4 | AG20: =SUMIFS(J20:J50,D20:D50,1,G20:G50,"mon") -> 1012100 | AH20: =AE20*AF20 -> 1012100 | AI20: =AH20/$M$6 -> 0.2031361 | AJ20: =SUM(AI20:AI26) -> 1 | AS20: =B2 -> 45292
C21: =C20+1 -> 2 | D21: 0 | E21: =TEXT(AA21,"m") -> 1 | F21: =F20+1 -> 45293 | G21: =TEXT(AS21,"ddd") -> Tue | H21: 休み | J21: 0 | L21: =IF(D21=0,0,$K$6) -> 0 | M21: =IF(D21=0,0,J21-L21) -> 0 | N21: =IFERROR(J21/L21,"0%") -> 0% | P21: =IF(D21=0,0,SUM($L$20:L21)) -> 0 | Q21: =IF(D21=0,0,SUM($J$20:J21)) -> 0 | R21: =IF(D21=0,0,Q21-P21) -> 0 | S21: =IFERROR(Q21/P21,"0%") -> 0% | U21: =IF(D21=0,0,SUM($L$20:L21)) -> 0 | V21: =IF(D21=0,0,SUM($J$20:J21)) -> 0 | W21: =IF(D21=0,0,V21-U21) -> 0 | X21: =IFERROR(V21/U21,"0%") -> 0% | Z21: =Z20+1 -> 45293 | AA21: =AA20+1 -> 45293 | AB21: 45293 | AC21: 1 | AD21: 火 | AE21: =IFERROR(AVERAGEIFS(J20:J50,D20:D50,1,G20:G50,"tue"),0) -> 214411 | AF21: =COUNTIFS(D20:D50,1,G20:G50,"Tue") -> 4 | AH21: =AE21*AF21 -> 857644 | AI21: =AH21/$M$6 -> 0.17213561 | AS21: =AS20+1 -> 45293
C22: =C21+1 -> 3 | D22: 0 | E22: =TEXT(AA22,"m") -> 1 | F22: =F21+1 -> 45294 | G22: =TEXT(AS22,"ddd") -> Wed | H22: 休み | J22: 0 | L22: =IF(D22=0,0,$K$6) -> 0 | M22: =IF(D22=0,0,J22-L22) -> 0 | N22: =IFERROR(J22/L22,"0%") -> 0% | P22: =IF(D22=0,0,SUM($L$20:L22)) -> 0 | Q22: =IF(D22=0,0,SUM($J$20:J22)) -> 0 | R22: =IF(D22=0,0,Q22-P22) -> 0 | S22: =IFERROR(Q22/P22,"0%") -> 0% | U22: =IF(D22=0,0,SUM($L$20:L22)) -> 0 | V22: =IF(D22=0,0,SUM($J$20:J22)) -> 0 | W22: =IF(D22=0,0,V22-U22) -> 0 | X22: =IFERROR(V22/U22,"0%") -> 0% | Z22: =Z21+1 -> 45294 | AA22: =AA21+1 -> 45294 | AB22: 45294 | AC22: 1 | AD22: 水 | AE22: =IFERROR(AVERAGEIFS(J20:J50,D20:D50,1,G20:G50,"wed"),0) -> 241500 | AF22: =COUNTIFS(D20:D50,1,G20:G50,"wed") -> 4 | AH22: =AE22*AF22 -> 966000 | AI22: =AH22/$M$6 -> 0.19388348 | AS22: =AS21+1 -> 45294
C23: =C22+1 -> 4 | D23: 0 | E23: =TEXT(AA23,"m") -> 1 | F23: =F22+1 -> 45295 | G23: =TEXT(AS23,"ddd") -> Thu | H23: 祝日 | J23: 0 | L23: =IF(D23=0,0,$K$6) -> 0 | M23: =IF(D23=0,0,J23-L23) -> 0 | N23: =IFERROR(J23/L23,"0%") -> 0% | P23: =IF(D23=0,0,SUM($L$20:L23)) -> 0 | Q23: =IF(D23=0,0,SUM($J$20:J23)) -> 0 | R23: =IF(D23=0,0,Q23-P23) -> 0 | S23: =IFERROR(Q23/P23,"0%") -> 0% | U23: =IF(D23=0,0,SUM($L$20:L23)) -> 0 | V23: =IF(D23=0,0,SUM($J$20:J23)) -> 0 | W23: =IF(D23=0,0,V23-U23) -> 0 | X23: =IFERROR(V23/U23,"0%") -> 0% | Z23: =Z22+1 -> 45295 | AA23: =AA22+1 -> 45295 | AB23: 45295 | AC23: 1 | AD23: 木 | AE23: =IFERROR(AVERAGEIFS(J20:J50,D20:D50,1,G20:G50,"thu"),0) -> 223706.67 | AF23: =COUNTIFS(D20:D50,1,G20:G50,"thu") -> 3 | AH23: =AE23*AF23 -> 671120 | AI23: =AH23/$M$6 -> 0.13469884 | AS23: =AS22+1 -> 45295
C24: =C23+1 -> 5 | D24: 1 | E24: =TEXT(AA24,"m") -> 1 | F24: =F23+1 -> 45296 | G24: =TEXT(AS24,"ddd") -> Fri | J24: 365950 | L24: =IF(D24=0,0,$K$6) -> 221794.94 | M24: =IF(D24=0,0,J24-L24) -> 144155.06 | N24: =IFERROR(J24/L24,"0%") -> 1.6499474 | P24: =IF(D24=0,0,SUM($L$20:L24)) -> 221794.94 | Q24: =IF(D24=0,0,SUM($J$20:J24)) -> 365950 | R24: =IF(D24=0,0,Q24-P24) -> 144155.06 | S24: =IFERROR(Q24/P24,"0%") -> 1.6499474 | U24: =IF(D24=0,0,SUM($L$20:L24)) -> 221794.94 | V24: =IF(D24=0,0,SUM($J$20:J24)) -> 365950 | W24: =IF(D24=0,0,V24-U24) -> 144155.06 | X24: =IFERROR(V24/U24,"0%") -> 1.6499474 | Z24: =Z23+1 -> 45296 | AA24: =AA23+1 -> 45296 | AB24: 45296 | AC24: 1 | AD24: 金 | AE24: =IFERROR(AVERAGEIFS(J20:J50,D20:D50,1,G20:G50,"fri"),0) -> 292927.5 | AF24: =COUNTIFS(D20:D50,1,G20:G50,"fri") -> 4 | AH24: =AE24*AF24 -> 1171710 | AI24: =AH24/$M$6 -> 0.23517102 | AS24: =AS23+1 -> 45296
C25: =C24+1 -> 6 | D25: 0 | E25: =TEXT(AA25,"m") -> 1 | F25: =F24+1 -> 45297 | G25: =TEXT(AS25,"ddd") -> Sat | J25: 0 | L25: =IF(D25=0,0,$K$6) -> 0 | M25: =IF(D25=0,0,J25-L25) -> 0 | N25: =IFERROR(J25/L25,"0%") -> 0% | P25: =IF(D25=0,0,SUM($L$20:L25)) -> 0 | Q25: =IF(D25=0,0,SUM($J$20:J25)) -> 0 | R25: =IF(D25=0,0,Q25-P25) -> 0 | S25: =IFERROR(Q25/P25,"0%") -> 0% | U25: =IF(D25=0,0,SUM($L$20:L25)) -> 0 | V25: =IF(D25=0,0,SUM($J$20:J25)) -> 0 | W25: =IF(D25=0,0,V25-U25) -> 0 | X25: =IFERROR(V25/U25,"0%") -> 0% | Z25: =Z24+1 -> 45297 | AA25: =AA24+1 -> 45297 | AB25: 45297 | AC25: 1 | AD25: 土 | AE25: =IFERROR(AVERAGEIFS(J20:J50,D20:D50,1,G20:G50,"sat"),0) -> 101266.67 | AF25: =COUNTIFS(D20:D50,1,G20:G50,"sat") -> 3 | AH25: =AE25*AF25 -> 303800 | AI25: =AH25/$M$6 -> 0.060974949 | AS25: =AS24+1 -> 45297
C26: =C25+1 -> 7 | D26: 0 | E26: =TEXT(AA26,"m") -> 1 | F26: =F25+1 -> 45298 | G26: =TEXT(AS26,"ddd") -> Sun | H26: 日曜日 | J26: 0 | L26: =IF(D26=0,0,$K$6) -> 0 | M26: =IF(D26=0,0,J26-L26) -> 0 | N26: =IFERROR(J26/L26,"0%") -> 0% | P26: =IF(D26=0,0,SUM($L$20:L26)) -> 0 | Q26: =IF(D26=0,0,SUM($J$20:J26)) -> 0 | R26: =IF(D26=0,0,Q26-P26) -> 0 | S26: =IFERROR(Q26/P26,"0%") -> 0% | U26: =IF(D26=0,0,SUM($L$20:L26)) -> 0 | V26: =IF(D26=0,0,SUM($J$20:J26)) -> 0 | W26: =IF(D26=0,0,V26-U26) -> 0 | X26: =IFERROR(V26/U26,"0%") -> 0% | Z26: =Z25+1 -> 45298 | AA26: =AA25+1 -> 45298 | AB26: 45298 | AC26: 1 | AD26: 日 | AE26: =IFERROR(AVERAGEIFS(J20:J50,D20:D50,1,G20:G50,"sun"),0) -> 0 | AF26: =IFERROR(COUNTIFS(D20:D50,1,G20:G50,"sun"),0) -> 0 | AH26: =AE26*AF26 -> 0 | AI26: =AH26/$M$6 -> 0 | AS26: =AS25+1 -> 45298
C27: =C26+1 -> 8 | D27: 1 | E27: =TEXT(AA27,"m") -> 1 | F27: =F26+1 -> 45299 | G27: =TEXT(AS27,"ddd") -> Mon | J27: 250000 | L27: =IF(D27=0,0,$K$6) -> 221794.94 | M27: =IF(D27=0,0,J27-L27) -> 28205.056 | N27: =IFERROR(J27/L27,"0%") -> 1.1271673 | P27: =IF(D27=0,0,SUM($L$20:L27)) -> 443589.89 | Q27: =IF(D27=0,0,SUM($J$20:J27)) -> 615950 | R27: =IF(D27=0,0,Q27-P27) -> 172360.11 | S27: =IFERROR(Q27/P27,"0%") -> 1.3885573 | U27: =IF(D27=0,0,SUM($L$20:L27)) -> 443589.89 | V27: =IF(D27=0,0,SUM($J$20:J27)) -> 615950 | W27: =IF(D27=0,0,V27-U27) -> 172360.11 | X27: =IFERROR(V27/U27,"0%") -> 1.3885573 | Z27: =Z26+1 -> 45299 | AA27: =AA26+1 -> 45299 | AB27: 45299 | AC27: 2 | AD27: 月 | AE27: =AVERAGEIFS(J51:J79,D51:D79,1,G51:G79,"mon") -> 231250 | AF27: =COUNTIFS(D51:D79,1,G51:G79,"Mon") -> 3 | AH27: =AE27*AF27 -> 693750 | AI27: =AH27/$M$7 -> 0.13869924 | AJ27: =SUM(AI27:AI33) -> 1 | AK27: 51〜79 | AS27: =AS26+1 -> 45299
C28: =C27+1 -> 9 | D28: 1 | E28: =TEXT(AA28,"m") -> 1 | F28: =F27+1 -> 45300 | G28: =TEXT(AS28,"ddd") -> Tue | J28: 143850 | L28: =IF(D28=0,0,$K$6) -> 221794.94 | M28: =IF(D28=0,0,J28-L28) -> -77944.944 | N28: =IFERROR(J28/L28,"0%") -> 0.64857204 | P28: =IF(D28=0,0,SUM($L$20:L28)) -> 665384.83 | Q28: =IF(D28=0,0,SUM($J$20:J28)) -> 759800 | R28: =IF(D28=0,0,Q28-P28) -> 94415.167 | S28: =IFERROR(Q28/P28,"0%") -> 1.1418956 | U28: =IF(D28=0,0,SUM($L$20:L28)) -> 665384.83 | V28: =IF(D28=0,0,SUM($J$20:J28)) -> 759800 | W28: =IF(D28=0,0,V28-U28) -> 94415.167 | X28: =IFERROR(V28/U28,"0%") -> 1.1418956 | Z28: =Z27+1 -> 45300 | AA28: =AA27+1 -> 45300 | AB28: 45300 | AC28: 2 | AD28: 火 | AE28: =AVERAGEIFS(J51:J79,D51:D79,1,G51:G79,"tue") -> 214245 | AF28: =COUNTIFS(D51:D79,1,G51:G79,"tue") -> 4 | AH28: =AE28*AF28 -> 856980 | AI28: =AH28/$M$7 -> 0.17133329 | AS28: =AS27+1 -> 45300
C29: =C28+1 -> 10 | D29: 1 | E29: =TEXT(AA29,"m") -> 1 | F29: =F28+1 -> 45301 | G29: =TEXT(AS29,"ddd") -> Wed | J29: 331400 | L29: =IF(D29=0,0,$K$6) -> 221794.94 | M29: =IF(D29=0,0,J29-L29) -> 109605.06 | N29: =IFERROR(J29/L29,"0%") -> 1.4941729 | P29: =IF(D29=0,0,SUM($L$20:L29)) -> 887179.78 | Q29: =IF(D29=0,0,SUM($J$20:J29)) -> 1091200 | R29: =IF(D29=0,0,Q29-P29) -> 204020.22 | S29: =IFERROR(Q29/P29,"0%") -> 1.2299649 | U29: =IF(D29=0,0,SUM($L$20:L29)) -> 887179.78 | V29: =IF(D29=0,0,SUM($J$20:J29)) -> 1091200 | W29: =IF(D29=0,0,V29-U29) -> 204020.22 | X29: =IFERROR(V29/U29,"0%") -> 1.2299649 | Z29: =Z28+1 -> 45301 | AA29: =AA28+1 -> 45301 | AB29: 45301 | AC29: 2 | AD29: 水 | AE29: =AVERAGEIFS(J51:J79,D51:D79,1,G51:G79,"wed") -> 221717.5 | AF29: =COUNTIFS(D51:D79,1,G51:G79,"wed") -> 4 | AH29: =AE29*AF29 -> 886870 | AI29: =AH29/$M$7 -> 0.1773091 | AS29: =AS28+1 -> 45301
C30: =C29+1 -> 11 | D30: 1 | E30: =TEXT(AA30,"m") -> 1 | F30: =F29+1 -> 45302 | G30: =TEXT(AS30,"ddd") -> Thu | J30: 263220 | L30: =IF(D30=0,0,$K$6) -> 221794.94 | M30: =IF(D30=0,0,J30-L30) -> 41425.056 | N30: =IFERROR(J30/L30,"0%") -> 1.1867719 | P30: =IF(D30=0,0,SUM($L$20:L30)) -> 1108974.7 | Q30: =IF(D30=0,0,SUM($J$20:J30)) -> 1354420 | R30: =IF(D30=0,0,Q30-P30) -> 245445.28 | S30: =IFERROR(Q30/P30,"0%") -> 1.2213263 | U30: =IF(D30=0,0,SUM($L$20:L30)) -> 1108974.7 | V30: =IF(D30=0,0,SUM($J$20:J30)) -> 1354420 | W30: =IF(D30=0,0,V30-U30) -> 245445.28 | X30: =IFERROR(V30/U30,"0%") -> 1.2213263 | Z30: =Z29+1 -> 45302 | AA30: =AA29+1 -> 45302 | AB30: 45302 | AC30: 2 | AD30: 木 | AE30: =AVERAGEIFS(J51:J79,D51:D79,1,G51:G79,"thu") -> 233396 | AF30: =COUNTIFS(D51:D79,1,G51:G79,"thu") -> 5 | AH30: =AE30*AF30 -> 1166980 | AI30: =AH30/$M$7 -> 0.23331061 | AS30: =AS29+1 -> 45302
C31: =C30+1 -> 12 | D31: 1 | E31: =TEXT(AA31,"m") -> 1 | F31: =F30+1 -> 45303 | G31: =TEXT(AS31,"ddd") -> Fri | J31: 230860 | L31: =IF(D31=0,0,$K$6) -> 221794.94 | M31: =IF(D31=0,0,J31-L31) -> 9065.0557 | N31: =IFERROR(J31/L31,"0%") -> 1.0408713 | P31: =IF(D31=0,0,SUM($L$20:L31)) -> 1330769.7 | Q31: =IF(D31=0,0,SUM($J$20:J31)) -> 1585280 | R31: =IF(D31=0,0,Q31-P31) -> 254510.33 | S31: =IFERROR(Q31/P31,"0%") -> 1.1912505 | U31: =IF(D31=0,0,SUM($L$20:L31)) -> 1330769.7 | V31: =IF(D31=0,0,SUM($J$20:J31)) -> 1585280 | W31: =IF(D31=0,0,V31-U31) -> 254510.33 | X31: =IFERROR(V31/U31,"0%") -> 1.1912505 | Z31: =Z30+1 -> 45303 | AA31: =AA30+1 -> 45303 | AB31: 45303 | AC31: 2 | AD31: 金 | AE31: =AVERAGEIFS(J51:J79,D51:D79,1,G51:G79,"fri") -> 283893.33 | AF31: =COUNTIFS(D51:D79,1,G51:G79,"fri") -> 3 | AH31: =AE31*AF31 -> 851680 | AI31: =AH31/$M$7 -> 0.17027368 | AS31: =AS30+1 -> 45303
C32: =C31+1 -> 13 | D32: 1 | E32: =TEXT(AA32,"m") -> 1 | F32: =F31+1 -> 45304 | G32: =TEXT(AS32,"ddd") -> Sat | J32: 50050 | L32: =IF(D32=0,0,$K$6) -> 221794.94 | M32: =IF(D32=0,0,J32-L32) -> -171744.94 | N32: =IFERROR(J32/L32,"0%") -> 0.22565889 | P32: =IF(D32=0,0,SUM($L$20:L32)) -> 1552564.6 | Q32: =IF(D32=0,0,SUM($J$20:J32)) -> 1635330 | R32: =IF(D32=0,0,Q32-P32) -> 82765.39 | S32: =IFERROR(Q32/P32,"0%") -> 1.0533088 | U32: =IF(D32=0,0,SUM($L$20:L32)) -> 1552564.6 | V32: =IF(D32=0,0,SUM($J$20:J32)) -> 1635330 | W32: =IF(D32=0,0,V32-U32) -> 82765.39 | X32: =IFERROR(V32/U32,"0%") -> 1.0533088 | Z32: =Z31+1 -> 45304 | AA32: =AA31+1 -> 45304 | AB32: 45304 | AC32: 2 | AD32: 土 | AE32: =AVERAGEIFS(J51:J79,D51:D79,1,G51:G79,"sat") -> 136392.5 | AF32: =COUNTIFS(D51:D79,1,G51:G79,"sat") -> 4 | AH32: =AE32*AF32 -> 545570 | AI32: =AH32/$M$7 -> 0.10907408 | AS32: =AS31+1 -> 45304
C33: =C32+1 -> 14 | D33: 0 | E33: =TEXT(AA33,"m") -> 1 | F33: =F32+1 -> 45305 | G33: =TEXT(AS33,"ddd") -> Sun | J33: 0 | L33: =IF(D33=0,0,$K$6) -> 0 | M33: =IF(D33=0,0,J33-L33) -> 0 | N33: =IFERROR(J33/L33,"0%") -> 0% | P33: =IF(D33=0,0,SUM($L$20:L33)) -> 0 | Q33: =IF(D33=0,0,SUM($J$20:J33)) -> 0 | R33: =IF(D33=0,0,Q33-P33) -> 0 | S33: =IFERROR(Q33/P33,"0%") -> 0% | U33: =IF(D33=0,0,SUM($L$20:L33)) -> 0 | V33: =IF(D33=0,0,SUM($J$20:J33)) -> 0 | W33: =IF(D33=0,0,V33-U33) -> 0 | X33: =IFERROR(V33/U33,"0%") -> 0% | Z33: =Z32+1 -> 45305 | AA33: =AA32+1 -> 45305 | AB33: 45305 | AC33: 2 | AD33: 日 | AE33: =IFERROR(AVERAGEIFS(J51:J79,D51:D79,1,G51:G79,"sun"),0) -> 0 | AF33: =IFERROR(COUNTIFS(D51:D79,1,G51:G79,"sun"),0) -> 0 | AH33: =AE33*AF33 -> 0 | AI33: =AH33/$M$7 -> 0 | AS33: =AS32+1 -> 45305
C34: =C33+1 -> 15 | D34: 1 | E34: =TEXT(AA34,"m") -> 1 | F34: =F33+1 -> 45306 | G34: =TEXT(AS34,"ddd") -> Mon | J34: 189100 | L34: =IF(D34=0,0,$K$6) -> 221794.94 | M34: =IF(D34=0,0,J34-L34) -> -32694.944 | N34: =IFERROR(J34/L34,"0%") -> 0.85258932 | P34: =IF(D34=0,0,SUM($L$20:L34)) -> 1774359.6 | Q34: =IF(D34=0,0,SUM($J$20:J34)) -> 1824430 | R34: =IF(D34=0,0,Q34-P34) -> 50070.446 | S34: =IFERROR(Q34/P34,"0%") -> 1.0282189 | U34: =IF(D34=0,0,SUM($L$20:L34)) -> 1774359.6 | V34: =IF(D34=0,0,SUM($J$20:J34)) -> 1824430 | W34: =IF(D34=0,0,V34-U34) -> 50070.446 | X34: =IFERROR(V34/U34,"0%") -> 1.0282189 | Z34: =Z33+1 -> 45306 | AA34: =AA33+1 -> 45306 | AB34: 45306 | AC34: 3 | AD34: 月 | AE34: =AVERAGEIFS(J80:J110,D80:D110,1,G80:G110,"mon") -> 228962.5 | AF34: =COUNTIFS( D80:D110,1,G80:G110,"Mon") -> 4 | AH34: =AE34*AF34 -> 915850 | AI34: =AH34/$M$8 -> 0.1417591 | AJ34: =SUM(AI34:AI40) -> 1 | AK34: 80〜110 | AS34: =AS33+1 -> 45306
C35: =C34+1 -> 16 | D35: 1 | E35: =TEXT(AA35,"m") -> 1 | F35: =F34+1 -> 45307 | G35: =TEXT(AS35,"ddd") -> Tue | J35: 212700 | L35: =IF(D35=0,0,$K$6) -> 221794.94 | M35: =IF(D35=0,0,J35-L35) -> -9094.9443 | N35: =IFERROR(J35/L35,"0%") -> 0.95899391 | P35: =IF(D35=0,0,SUM($L$20:L35)) -> 1996154.5 | Q35: =IF(D35=0,0,SUM($J$20:J35)) -> 2037130 | R35: =IF(D35=0,0,Q35-P35) -> 40975.501 | S35: =IFERROR(Q35/P35,"0%") -> 1.0205272 | U35: =IF(D35=0,0,SUM($L$20:L35)) -> 1996154.5 | V35: =IF(D35=0,0,SUM($J$20:J35)) -> 2037130 | W35: =IF(D35=0,0,V35-U35) -> 40975.501 | X35: =IFERROR(V35/U35,"0%") -> 1.0205272 | Z35: =Z34+1 -> 45307 | AA35: =AA34+1 -> 45307 | AB35: 45307 | AC35: 3 | AD35: 火 | AE35: =AVERAGEIFS(J80:J110,D80:D110,1,G80:G110,"tue") -> 263967.5 | AF35: =COUNTIFS( D80:D110,1,G80:G110,"tue") -> 4 | AH35: =AE35*AF35 -> 1055870 | AI35: =AH35/$M$8 -> 0.16343199 | AS35: =AS34+1 -> 45307
C36: =C35+1 -> 17 | D36: 1 | E36: =TEXT(AA36,"m") -> 1 | F36: =F35+1 -> 45308 | G36: =TEXT(AS36,"ddd") -> Wed | J36: 172600 | L36: =IF(D36=0,0,$K$6) -> 221794.94 | M36: =IF(D36=0,0,J36-L36) -> -49194.944 | N36: =IFERROR(J36/L36,"0%") -> 0.77819628 | P36: =IF(D36=0,0,SUM($L$20:L36)) -> 2217949.4 | Q36: =IF(D36=0,0,SUM($J$20:J36)) -> 2209730 | R36: =IF(D36=0,0,Q36-P36) -> -8219.4429 | S36: =IFERROR(Q36/P36,"0%") -> 0.99629413 | U36: =IF(D36=0,0,SUM($L$20:L36)) -> 2217949.4 | V36: =IF(D36=0,0,SUM($J$20:J36)) -> 2209730 | W36: =IF(D36=0,0,V36-U36) -> -8219.4429 | X36: =IFERROR(V36/U36,"0%") -> 0.99629413 | Z36: =Z35+1 -> 45308 | AA36: =AA35+1 -> 45308 | AB36: 45308 | AC36: 3 | AD36: 水 | AE36: =AVERAGEIFS(J80:J110,D80:D110,1,G80:G110,"wed") -> 293950 | AF36: =COUNTIFS( D80:D110,1,G80:G110,"wed") -> 3 | AH36: =AE36*AF36 -> 881850 | AI36: =AH36/$M$8 -> 0.13649644 | AS36: =AS35+1 -> 45308
C37: =C36+1 -> 18 | D37: 1 | E37: =TEXT(AA37,"m") -> 1 | F37: =F36+1 -> 45309 | G37: =TEXT(AS37,"ddd") -> Thu | J37: 155450 | L37: =IF(D37=0,0,$K$6) -> 221794.94 | M37: =IF(D37=0,0,J37-L37) -> -66344.944 | N37: =IFERROR(J37/L37,"0%") -> 0.7008726 | P37: =IF(D37=0,0,SUM($L$20:L37)) -> 2439744.4 | Q37: =IF(D37=0,0,SUM($J$20:J37)) -> 2365180 | R37: =IF(D37=0,0,Q37-P37) -> -74564.387 | S37: =IFERROR(Q37/P37,"0%") -> 0.96943762 | U37: =IF(D37=0,0,SUM($L$20:L37)) -> 2439744.4 | V37: =IF(D37=0,0,SUM($J$20:J37)) -> 2365180 | W37: =IF(D37=0,0,V37-U37) -> -74564.387 | X37: =IFERROR(V37/U37,"0%") -> 0.96943762 | Z37: =Z36+1 -> 45309 | AA37: =AA36+1 -> 45309 | AB37: 45309 | AC37: 3 | AD37: 木 | AE37: =AVERAGEIFS(J80:J110,D80:D110,1,G80:G110,"thu") -> 308607.5 | AF37: =COUNTIFS( D80:D110,1,G80:G110,"thu") -> 4 | AH37: =AE37*AF37 -> 1234430 | AI37: =AH37/$M$8 -> 0.19107025 | AS37: =AS36+1 -> 45309
C38: =C37+1 -> 19 | D38: 1 | E38: =TEXT(AA38,"m") -> 1 | F38: =F37+1 -> 45310 | G38: =TEXT(AS38,"ddd") -> Fri | J38: 286750 | L38: =IF(D38=0,0,$K$6) -> 221794.94 | M38: =IF(D38=0,0,J38-L38) -> 64955.056 | N38: =IFERROR(J38/L38,"0%") -> 1.2928608 | P38: =IF(D38=0,0,SUM($L$20:L38)) -> 2661539.3 | Q38: =IF(D38=0,0,SUM($J$20:J38)) -> 2651930 | R38: =IF(D38=0,0,Q38-P38) -> -9609.3315 | S38: =IFERROR(Q38/P38,"0%") -> 0.99638956 | U38: =IF(D38=0,0,SUM($L$20:L38)) -> 2661539.3 | V38: =IF(D38=0,0,SUM($J$20:J38)) -> 2651930 | W38: =IF(D38=0,0,V38-U38) -> -9609.3315 | X38: =IFERROR(V38/U38,"0%") -> 0.99638956 | Z38: =Z37+1 -> 45310 | AA38: =AA37+1 -> 45310 | AB38: 45310 | AC38: 3 | AD38: 金 | AE38: =AVERAGEIFS(J80:J110,D80:D110,1,G80:G110,"fri") -> 322626 | AF38: =COUNTIFS( D80:D110,1,G80:G110,"fri") -> 5 | AH38: =AE38*AF38 -> 1613130 | AI38: =AH38/$M$8 -> 0.24968703 | AS38: =AS37+1 -> 45310
C39: =C38+1 -> 20 | D39: 1 | E39: =TEXT(AA39,"m") -> 1 | F39: =F38+1 -> 45311 | G39: =TEXT(AS39,"ddd") -> Sat | J39: 139100 | L39: =IF(D39=0,0,$K$6) -> 221794.94 | M39: =IF(D39=0,0,J39-L39) -> -82694.944 | N39: =IFERROR(J39/L39,"0%") -> 0.62715586 | P39: =IF(D39=0,0,SUM($L$20:L39)) -> 2883334.3 | Q39: =IF(D39=0,0,SUM($J$20:J39)) -> 2791030 | R39: =IF(D39=0,0,Q39-P39) -> -92304.276 | S39: =IFERROR(Q39/P39,"0%") -> 0.96798697 | U39: =IF(D39=0,0,SUM($L$20:L39)) -> 2883334.3 | V39: =IF(D39=0,0,SUM($J$20:J39)) -> 2791030 | W39: =IF(D39=0,0,V39-U39) -> -92304.276 | X39: =IFERROR(V39/U39,"0%") -> 0.96798697 | Z39: =Z38+1 -> 45311 | AA39: =AA38+1 -> 45311 | AB39: 45311 | AC39: 3 | AD39: 土 | AE39: =AVERAGEIFS(J80:J110,D80:D110,1,G80:G110,"sat") -> 151895.6 | AF39: =COUNTIFS( D80:D110,1,G80:G110,"sat") -> 5 | AH39: =AE39*AF39 -> 759478 | AI39: =AH39/$M$8 -> 0.11755519 | AS39: =AS38+1 -> 45311
C40: =C39+1 -> 21 | D40: 0 | E40: =TEXT(AA40,"m") -> 1 | F40: =F39+1 -> 45312 | G40: =TEXT(AS40,"ddd") -> Sun | H40: 日曜日 | J40: 0 | L40: =IF(D40=0,0,$K$6) -> 0 | M40: =IF(D40=0,0,J40-L40) -> 0 | N40: =IFERROR(J40/L40,"0%") -> 0% | P40: =IF(D40=0,0,SUM($L$20:L40)) -> 0 | Q40: =IF(D40=0,0,SUM($J$20:J40)) -> 0 | R40: =IF(D40=0,0,Q40-P40) -> 0 | S40: =IFERROR(Q40/P40,"0%") -> 0% | U40: =IF(D40=0,0,SUM($L$20:L40)) -> 0 | V40: =IF(D40=0,0,SUM($J$20:J40)) -> 0 | W40: =IF(D40=0,0,V40-U40) -> 0 | X40: =IFERROR(V40/U40,"0%") -> 0% | Z40: =Z39+1 -> 45312 | AA40: =AA39+1 -> 45312 | AB40: 45312 | AC40: 3 | AD40: 日 | AE40: =IFERROR(AVERAGEIFS(J80:J110,D80:D110,3,G80:G110,"sun"),0) -> 0 | AF40: =IFERROR(COUNTIFS( D80:D110,1,G80:G110,"sun"),0) -> 0 | AH40: =AE40*AF40 -> 0 | AI40: =AH40/$M$8 -> 0 | AS40: =AS39+1 -> 45312
C41: =C40+1 -> 22 | D41: 1 | E41: =TEXT(AA41,"m") -> 1 | F41: =F40+1 -> 45313 | G41: =TEXT(AS41,"ddd") -> Mon | J41: 250550 | L41: =IF(D41=0,0,$K$6) -> 221794.94 | M41: =IF(D41=0,0,J41-L41) -> 28755.056 | N41: =IFERROR(J41/L41,"0%") -> 1.129647 | P41: =IF(D41=0,0,SUM($L$20:L41)) -> 3105129.2 | Q41: =IF(D41=0,0,SUM($J$20:J41)) -> 3041580 | R41: =IF(D41=0,0,Q41-P41) -> -63549.22 | S41: =IFERROR(Q41/P41,"0%") -> 0.97953411 | U41: =IF(D41=0,0,SUM($L$20:L41)) -> 3105129.2 | V41: =IF(D41=0,0,SUM($J$20:J41)) -> 3041580 | W41: =IF(D41=0,0,V41-U41) -> -63549.22 | X41: =IFERROR(V41/U41,"0%") -> 0.97953411 | Z41: =Z40+1 -> 45313 | AA41: =AA40+1 -> 45313 | AB41: 45313 | AC41: 4 | AD41: 月 | AE41: =AVERAGEIFS(J111:J140,D111:D140,1,G111:G140,"mon") -> 228365 | AF41: =COUNTIFS(D111:D140,1,G111:G140,"Mon") -> 4 | AH41: =AE41*AF41 -> 913460 | AI41: =AH41/$M$9 -> 0.13681398 | AJ41: =SUM(AI41:AI47) -> 1 | AK41: 111〜140 | AS41: =AS40+1 -> 45313
C42: =C41+1 -> 23 | D42: 1 | E42: =TEXT(AA42,"m") -> 1 | F42: =F41+1 -> 45314 | G42: =TEXT(AS42,"ddd") -> Tue | J42: 312544 | L42: =IF(D42=0,0,$K$6) -> 221794.94 | M42: =IF(D42=0,0,J42-L42) -> 90749.056 | N42: =IFERROR(J42/L42,"0%") -> 1.4091575 | P42: =IF(D42=0,0,SUM($L$20:L42)) -> 3326924.2 | Q42: =IF(D42=0,0,SUM($J$20:J42)) -> 3354124 | R42: =IF(D42=0,0,Q42-P42) -> 27199.836 | S42: =IFERROR(Q42/P42,"0%") -> 1.0081757 | U42: =IF(D42=0,0,SUM($L$20:L42)) -> 3326924.2 | V42: =IF(D42=0,0,SUM($J$20:J42)) -> 3354124 | W42: =IF(D42=0,0,V42-U42) -> 27199.836 | X42: =IFERROR(V42/U42,"0%") -> 1.0081757 | Z42: =Z41+1 -> 45314 | AA42: =AA41+1 -> 45314 | AB42: 45314 | AC42: 4 | AD42: 火 | AE42: =AVERAGEIFS(J111:J140,D111:D140,1,G111:G140,"tue") -> 269807.4 | AF42: =COUNTIFS(D111:D140,1,G111:G140,"tue") -> 5 | AH42: =AE42*AF42 -> 1349037 | AI42: =AH42/$M$9 -> 0.20205276 | AS42: =AS41+1 -> 45314
C43: =C42+1 -> 24 | D43: 1 | E43: =TEXT(AA43,"m") -> 1 | F43: =F42+1 -> 45315 | G43: =TEXT(AS43,"ddd") -> Wed | J43: 255500 | L43: =IF(D43=0,0,$K$6) -> 221794.94 | M43: =IF(D43=0,0,J43-L43) -> 33705.056 | N43: =IFERROR(J43/L43,"0%") -> 1.1519649 | P43: =IF(D43=0,0,SUM($L$20:L43)) -> 3548719.1 | Q43: =IF(D43=0,0,SUM($J$20:J43)) -> 3609624 | R43: =IF(D43=0,0,Q43-P43) -> 60904.891 | S43: =IFERROR(Q43/P43,"0%") -> 1.0171625 | U43: =IF(D43=0,0,SUM($L$20:L43)) -> 3548719.1 | V43: =IF(D43=0,0,SUM($J$20:J43)) -> 3609624 | W43: =IF(D43=0,0,V43-U43) -> 60904.891 | X43: =IFERROR(V43/U43,"0%") -> 1.0171625 | Z43: =Z42+1 -> 45315 | AA43: =AA42+1 -> 45315 | AB43: 45315 | AC43: 4 | AD43: 水 | AE43: =AVERAGEIFS(J111:J140,D111:D140,1,G111:G140,"wed") -> 292710 | AF43: =COUNTIFS(D111:D140,1,G111:G140,"wed") -> 4 | AH43: =AE43*AF43 -> 1170840 | AI43: =AH43/$M$9 -> 0.17536321 | AS43: =AS42+1 -> 45315
...

Sheet 2024($)
B2: 45292 | E2: ①年間営業日 | G2: ②年間目標売上 | I2: 年間売上％設定 | M2: 年間売上合計 | O2: 年間実質売上 | Q2: 年間利益率 | R2: 年間予想利益額
E3: =SUM(F6:F17) -> 289 | G3: =71220821/B13 -> 645466.93 | I3: =SUM(AP6:AP17)*100 -> 0.9999996 | K3: =G3*I3 -> 645466.67 | M3: =SUM(J20:J385) -> 645466.93 | O3: =M3-G3 -> 0 | Q3: 0.21 | R3: =M3*Q3 -> 135548.06
B5: 平均日次売上目標額 | E5: 月 | F5: 月次営業日数 | G5: 平均月間売上目標額 | H5: 月次繁閑期%設定 | J5: 月次目標売上 | K5: 日次目標売上 | M5: 月次売上 | N5: 月間差額 | P5: 月次実質% | R5: 1日の売上目標値 参考例 | AO5: =TEXT(K6,"¥0") -> ¥2010
B6: ② ÷ ① | E6: 1月 | F6: =COUNTIF(D20:D50,1) -> 22 | G6: =$B$7*F6 -> 49135.891 | H6: 0.9 | J6: =G6*H6 -> 44222.302 | K6: =J6/F6 -> 2010.1046 | M6: =SUM(J20:J50) -> 45154.74 | N6: =M6-J6 -> 932.43815 | P6: =M6/G6 -> 0.91897672 | R6: 目標売上 | T6: ¥233564 | V6: 0.76 | AO6: =TEXT(K7,"¥0") -> ¥1898 | AP6: =(H6/100)*AQ6 -> 0.0007499997 | AQ6: 0.0833333
B7: =G3/E3 -> 2233.4496 | E7: 2月 | F7: =COUNTIF(D51:D79,1) -> 23 | G7: =$B$7*F7 -> 51369.34 | H7: 0.85 | J7: =G7*H7 -> 43663.939 | K7: =J7/F7 -> 1898.4321 | M7: =SUM(J51:J79) -> 45331.068 | N7: =M7-J7 -> 1667.1283 | P7: =M7/G7 -> 0.88245376 | T7: =T6*V6 -> 177508.64 | AO7: =TEXT(K8,"¥0") -> ¥2233 | AP7: =(H7/100)*AQ7 -> 0.00070833305 | AQ7: 0.0833333
E8: 3月 | F8: =COUNTIF(D80:D110,1) -> 25 | G8: =$B$7*F8 -> 55836.24 | H8: 1 | J8: =G8*H8 -> 55836.24 | K8: =J8/F8 -> 2233.4496 | M8: =SUM(J80:J110) -> 58551.822 | N8: =M8-J8 -> 2715.5821 | P8: =M8/G8 -> 1.0486348 | R8: 差額 | T8: =T9-T6 -> 87436 | AO8: =TEXT(K9,"¥0") -> ¥2345 | AP8: =(H8/100)*AQ8 -> 0.000833333 | AQ8: 0.0833333
E9: 4月 | F9: =COUNTIF(D111:D140,1) -> 25 | G9: =$B$7*F9 -> 55836.24 | H9: 1.05 | J9: =G9*H9 -> 58628.052 | K9: =J9/F9 -> 2345.1221 | M9: =SUM(J111:J140) -> 60509.851 | N9: =M9-J9 -> 1881.7998 | P9: =M9/G9 -> 1.0837021 | R9: 仮1日売上総合計 | T9: =SUM(V11:V16) -> 321000 | AO9: =TEXT(K10,"¥0") -> ¥2233 | AP9: =(H9/100)*AQ9 -> 0.00087499965 | AQ9: 0.0833333
E10: 5月 | F10: =COUNTIF(D141:D171,1) -> 24 | G10: =$B$7*F10 -> 53602.79 | H10: 1 | J10: =G10*H10 -> 53602.79 | K10: =J10/F10 -> 2233.4496 | M10: =SUM(J141:J171) -> 55872.848 | N10: =M10-J10 -> 2270.0576 | P10: =M10/G10 -> 1.0423496 | R10: 項目 | S10: 仮客単価 | T10: 集客数 | V10: 仮1日の売上小計 | AO10: =TEXT(K11,"¥0") -> ¥2010 | AP10: =(H10/100)*AQ10 -> 0.000833333 | AQ10: 0.0833333
E11: 6月 | F11: =COUNTIF(D172:D201,1) -> 25 | G11: =$B$7*F11 -> 55836.24 | H11: 0.9 | J11: =G11*H11 -> 50252.616 | K11: =J11/F11 -> 2010.1046 | M11: =SUM(J172:J201) -> 53543.139 | N11: =M11-J11 -> 3290.5238 | P11: =M11/G11 -> 0.95893169 | R11: ランチ | S11: 1100 | T11: 60 | V11: =S11*T11 -> 66000 | AO11: =TEXT(K12,"¥0") -> ¥2122 | AP11: =(H11/100)*AQ11 -> 0.0007499997 | AQ11: 0.0833333
E12: 7月 | F12: =COUNTIF(D202:D232,1) -> 26 | G12: =$B$7*F12 -> 58069.689 | H12: 0.95 | J12: =G12*H12 -> 55166.205 | K12: =J12/F12 -> 2121.7771 | M12: =SUM(J202:J232) -> 59109.888 | N12: =M12-J12 -> 3943.6829 | P12: =M12/G12 -> 1.0179129 | R12: ディナー | S12: 4500 | T12: 20 | V12: =S12*T12 -> 90000 | AO12: =TEXT(K13,"¥0") -> ¥1787 | AP12: =(H12/100)*AQ12 -> 0.00079166635 | AQ12: 0.0833333
B13: 110.34 | E13: 8月 | F13: =COUNTIF(D233:D263,1) -> 22 | G13: =$B$7*F13 -> 49135.891 | H13: 0.8 | J13: =G13*H13 -> 39308.713 | K13: =J13/F13 -> 1786.7597 | M13: =SUM(J233:J263) -> 40891.807 | N13: =M13-J13 -> 1583.0945 | P13: =M13/G13 -> 0.8322187 | R13: Party 5500 | S13: 5500 | T13: 30 | V13: =S13*T13 -> 165000 | AO13: =TEXT(K14,"¥0") -> ¥2122 | AP13: =(H13/100)*AQ13 -> 0.0006666664 | AQ13: 0.0833333
E14: 9 月 | F14: =COUNTIF(D264:D293,1) -> 23 | G14: =$B$7*F14 -> 51369.34 | H14: 0.95 | J14: =G14*H14 -> 48800.873 | K14: =J14/F14 -> 2121.7771 | M14: =SUM(J264:J293) -> 49166.893 | N14: =M14-J14 -> 366.01985 | P14: =M14/G14 -> 0.95712526 | T14: 0 | V14: =S14*T14 -> 0 | AO14: =TEXT(K15,"¥0") -> ¥2792 | AP14: =(H14/100)*AQ14 -> 0.00079166635 | AQ14: 0.0833333
E15: 10月 | F15: =COUNTIF(D294:D324,1) -> 26 | G15: =$B$7*F15 -> 58069.689 | H15: 1.25 | J15: =G15*H15 -> 72587.111 | K15: =J15/F15 -> 2791.812 | M15: =SUM(J294:J324) -> 50349.193 | N15: =M15-J15 -> -22237.918 | P15: =M15/G15 -> 0.86704775 | T15: 0 | V15: =S15*T15 -> 0 | AO15: =TEXT(K16,"¥0") -> ¥2345 | AP15: =(H15/100)*AQ15 -> 0.0010416662 | AQ15: 0.0833333
E16: 11月 | F16: =COUNTIF(D325:D354,1) -> 24 | G16: =$B$7*F16 -> 53602.79 | H16: 1.05 | J16: =G16*H16 -> 56282.929 | K16: =J16/F16 -> 2345.1221 | M16: =SUM(J325:J354) -> 55393.783 | N16: =M16-J16 -> -889.14664 | P16: =M16/G16 -> 1.0334123 | T16: 0 | V16: =S16*T16 -> 0 | AO16: =TEXT(K17,"¥0") -> ¥2903 | AP16: =(H16/100)*AQ16 -> 0.00087499965 | AQ16: 0.0833333
E17: 12月 | F17: =COUNTIF(D355:D385,1) -> 24 | G17: =$B$7*F17 -> 53602.79 | H17: 1.3 | J17: =G17*H17 -> 69683.627 | K17: =J17/F17 -> 2903.4845 | M17: =SUM(J355:J385) -> 71591.898 | N17: =M17-J17 -> 1908.2708 | P17: =M17/G17 -> 1.3356002 | AP17: =(H17/100)*AQ17 -> 0.0010833329 | AQ17: 0.0833333
E19: 月 | F19: 日程 | G19: 曜日 | H19: 休店日理由 | J19: Daily売上入力 | L19: 目標売上 KPI | M19: 日次実質売上 | N19: 実質% | P19: 月次目標売上 | Q19: 月次実質売上 | R19: 月次差額(勝率) | S19: 月次実質% | U19: 年次目標売上 | V19: 年次実質売上 | W19: 年次差額(勝率) | X19: 年次実質% | AC19: 月 | AD19: 曜日 | AE19: 平均売上 | AF19: 曜日回数 | AH19: 曜日合計額 | AI19: 加重比率
C20: 1 | D20: 0 | E20: =TEXT(AA20,"m") -> 1 | F20: =B2 -> 45292 | G20: =TEXT(AS20,"ddd") -> Mon | H20: 元旦 | L20: =IF(D20=0,0,$K$6) -> 0 | M20: =IF(D20=0,0,J20-L20) -> 0 | N20: =IFERROR(J20/L20,"0%") -> 0% | P20: =IF(D20=0,0,$K$6) -> 0 | Q20: =IF(D20=0,0,$J$20) -> 0 | R20: =IF(D20=0,0,Q20-P20) -> 0 | S20: =IFERROR(Q20/P20,"0%") -> 0% | U20: =IF(D20=0,0,$L$20) -> 0 | V20: =IF(D20=0,0,$J$20) -> 0 | W20: =IF(D20=0,0,V20-U20) -> 0 | X20: =IFERROR(V20/U20,"0%") -> 0% | Z20: =B2 -> 45292 | AA20: =B2 -> 45292 | AB20: 45292 | AC20: 1 | AD20: 月 | AE20: =IFERROR(AVERAGEIFS(J20:J50,D20:D50,1,G20:G50,"mon"),0) -> 2293.1394 | AF20: =COUNTIFS(D20:D50,1,G20:G50,"Mon") -> 4 | AG20: =SUMIFS(J20:J50,D20:D50,1,G20:G50,"mon") -> 9172.5575 | AH20: =AE20*AF20 -> 9172.5575 | AI20: =AH20/$M$6 -> 0.2031361 | AJ20: =SUM(AI20:AI26) -> 1 | AS20: =B2 -> 45292
C21: =C20+1 -> 2 | D21: 0 | E21: =TEXT(AA21,"m") -> 1 | F21: =F20+1 -> 45293 | G21: =TEXT(AS21,"ddd") -> Tue | H21: 休み | L21: =IF(D21=0,0,$K$6) -> 0 | M21: =IF(D21=0,0,J21-L21) -> 0 | N21: =IFERROR(J21/L21,"0%") -> 0% | P21: =IF(D21=0,0,SUM($L$20:L21)) -> 0 | Q21: =IF(D21=0,0,SUM($J$20:J21)) -> 0 | R21: =IF(D21=0,0,Q21-P21) -> 0 | S21: =IFERROR(Q21/P21,"0%") -> 0% | U21: =IF(D21=0,0,SUM($L$20:L21)) -> 0 | V21: =IF(D21=0,0,SUM($J$20:J21)) -> 0 | W21: =IF(D21=0,0,V21-U21) -> 0 | X21: =IFERROR(V21/U21,"0%") -> 0% | Z21: =Z20+1 -> 45293 | AA21: =AA20+1 -> 45293 | AB21: 45293 | AC21: 1 | AD21: 火 | AE21: =IFERROR(AVERAGEIFS(J20:J50,D20:D50,1,G20:G50,"tue"),0) -> 1943.1847 | AF21: =COUNTIFS(D20:D50,1,G20:G50,"Tue") -> 4 | AH21: =AE21*AF21 -> 7772.7388 | AI21: =AH21/$M$6 -> 0.17213561 | AS21: =AS20+1 -> 45293
C22: =C21+1 -> 3 | D22: 0 | E22: =TEXT(AA22,"m") -> 1 | F22: =F21+1 -> 45294 | G22: =TEXT(AS22,"ddd") -> Wed | H22: 休み | L22: =IF(D22=0,0,$K$6) -> 0 | M22: =IF(D22=0,0,J22-L22) -> 0 | N22: =IFERROR(J22/L22,"0%") -> 0% | P22: =IF(D22=0,0,SUM($L$20:L22)) -> 0 | Q22: =IF(D22=0,0,SUM($J$20:J22)) -> 0 | R22: =IF(D22=0,0,Q22-P22) -> 0 | S22: =IFERROR(Q22/P22,"0%") -> 0% | U22: =IF(D22=0,0,SUM($L$20:L22)) -> 0 | V22: =IF(D22=0,0,SUM($J$20:J22)) -> 0 | W22: =IF(D22=0,0,V22-U22) -> 0 | X22: =IFERROR(V22/U22,"0%") -> 0% | Z22: =Z21+1 -> 45294 | AA22: =AA21+1 -> 45294 | AB22: 45294 | AC22: 1 | AD22: 水 | AE22: =IFERROR(AVERAGEIFS(J20:J50,D20:D50,1,G20:G50,"wed"),0) -> 2188.6895 | AF22: =COUNTIFS(D20:D50,1,G20:G50,"wed") -> 4 | AH22: =AE22*AF22 -> 8754.758 | AI22: =AH22/$M$6 -> 0.19388348 | AS22: =AS21+1 -> 45294
C23: =C22+1 -> 4 | D23: 0 | E23: =TEXT(AA23,"m") -> 1 | F23: =F22+1 -> 45295 | G23: =TEXT(AS23,"ddd") -> Thu | H23: 祝日 | L23: =IF(D23=0,0,$K$6) -> 0 | M23: =IF(D23=0,0,J23-L23) -> 0 | N23: =IFERROR(J23/L23,"0%") -> 0% | P23: =IF(D23=0,0,SUM($L$20:L23)) -> 0 | Q23: =IF(D23=0,0,SUM($J$20:J23)) -> 0 | R23: =IF(D23=0,0,Q23-P23) -> 0 | S23: =IFERROR(Q23/P23,"0%") -> 0% | U23: =IF(D23=0,0,SUM($L$20:L23)) -> 0 | V23: =IF(D23=0,0,SUM($J$20:J23)) -> 0 | W23: =IF(D23=0,0,V23-U23) -> 0 | X23: =IFERROR(V23/U23,"0%") -> 0% | Z23: =Z22+1 -> 45295 | AA23: =AA22+1 -> 45295 | AB23: 45295 | AC23: 1 | AD23: 木 | AE23: =IFERROR(AVERAGEIFS(J20:J50,D20:D50,1,G20:G50,"thu"),0) -> 2027.4304 | AF23: =COUNTIFS(D20:D50,1,G20:G50,"thu") -> 3 | AH23: =AE23*AF23 -> 6082.2911 | AI23: =AH23/$M$6 -> 0.13469884 | AS23: =AS22+1 -> 45295
C24: =C23+1 -> 5 | D24: 1 | E24: =TEXT(AA24,"m") -> 1 | F24: =F23+1 -> 45296 | G24: =TEXT(AS24,"ddd") -> Fri | J24: =365950/$B$13 -> 3316.567 | L24: =IF(D24=0,0,$K$6) -> 2010.1046 | M24: =IF(D24=0,0,J24-L24) -> 1306.4624 | N24: =IFERROR(J24/L24,"0%") -> 1.6499474 | P24: =IF(D24=0,0,SUM($L$20:L24)) -> 2010.1046 | Q24: =IF(D24=0,0,SUM($J$20:J24)) -> 3316.567 | R24: =IF(D24=0,0,Q24-P24) -> 1306.4624 | S24: =IFERROR(Q24/P24,"0%") -> 1.6499474 | U24: =IF(D24=0,0,SUM($L$20:L24)) -> 2010.1046 | V24: =IF(D24=0,0,SUM($J$20:J24)) -> 3316.567 | W24: =IF(D24=0,0,V24-U24) -> 1306.4624 | X24: =IFERROR(V24/U24,"0%") -> 1.6499474 | Z24: =Z23+1 -> 45296 | AA24: =AA23+1 -> 45296 | AB24: 45296 | AC24: 1 | AD24: 金 | AE24: =IFERROR(AVERAGEIFS(J20:J50,D20:D50,1,G20:G50,"fri"),0) -> 2654.7716 | AF24: =COUNTIFS(D20:D50,1,G20:G50,"fri") -> 4 | AH24: =AE24*AF24 -> 10619.086 | AI24: =AH24/$M$6 -> 0.23517102 | AS24: =AS23+1 -> 45296
C25: =C24+1 -> 6 | D25: 0 | E25: =TEXT(AA25,"m") -> 1 | F25: =F24+1 -> 45297 | G25: =TEXT(AS25,"ddd") -> Sat | L25: =IF(D25=0,0,$K$6) -> 0 | M25: =IF(D25=0,0,J25-L25) -> 0 | N25: =IFERROR(J25/L25,"0%") -> 0% | P25: =IF(D25=0,0,SUM($L$20:L25)) -> 0 | Q25: =IF(D25=0,0,SUM($J$20:J25)) -> 0 | R25: =IF(D25=0,0,Q25-P25) -> 0 | S25: =IFERROR(Q25/P25,"0%") -> 0% | U25: =IF(D25=0,0,SUM($L$20:L25)) -> 0 | V25: =IF(D25=0,0,SUM($J$20:J25)) -> 0 | W25: =IF(D25=0,0,V25-U25) -> 0 | X25: =IFERROR(V25/U25,"0%") -> 0% | Z25: =Z24+1 -> 45297 | AA25: =AA24+1 -> 45297 | AB25: 45297 | AC25: 1 | AD25: 土 | AE25: =IFERROR(AVERAGEIFS(J20:J50,D20:D50,1,G20:G50,"sat"),0) -> 917.76932 | AF25: =COUNTIFS(D20:D50,1,G20:G50,"sat") -> 3 | AH25: =AE25*AF25 -> 2753.308 | AI25: =AH25/$M$6 -> 0.060974949 | AS25: =AS24+1 -> 45297
C26: =C25+1 -> 7 | D26: 0 | E26: =TEXT(AA26,"m") -> 1 | F26: =F25+1 -> 45298 | G26: =TEXT(AS26,"ddd") -> Sun | H26: 日曜日 | L26: =IF(D26=0,0,$K$6) -> 0 | M26: =IF(D26=0,0,J26-L26) -> 0 | N26: =IFERROR(J26/L26,"0%") -> 0% | P26: =IF(D26=0,0,SUM($L$20:L26)) -> 0 | Q26: =IF(D26=0,0,SUM($J$20:J26)) -> 0 | R26: =IF(D26=0,0,Q26-P26) -> 0 | S26: =IFERROR(Q26/P26,"0%") -> 0% | U26: =IF(D26=0,0,SUM($L$20:L26)) -> 0 | V26: =IF(D26=0,0,SUM($J$20:J26)) -> 0 | W26: =IF(D26=0,0,V26-U26) -> 0 | X26: =IFERROR(V26/U26,"0%") -> 0% | Z26: =Z25+1 -> 45298 | AA26: =AA25+1 -> 45298 | AB26: 45298 | AC26: 1 | AD26: 日 | AE26: =IFERROR(AVERAGEIFS(J20:J50,D20:D50,1,G20:G50,"sun"),0) -> 0 | AF26: =IFERROR(COUNTIFS(D20:D50,1,G20:G50,"sun"),0) -> 0 | AH26: =AE26*AF26 -> 0 | AI26: =AH26/$M$6 -> 0 | AS26: =AS25+1 -> 45298
C27: =C26+1 -> 8 | D27: 1 | E27: =TEXT(AA27,"m") -> 1 | F27: =F26+1 -> 45299 | G27: =TEXT(AS27,"ddd") -> Mon | J27: =250000/$B$13 -> 2265.7241 | L27: =IF(D27=0,0,$K$6) -> 2010.1046 | M27: =IF(D27=0,0,J27-L27) -> 255.6195 | N27: =IFERROR(J27/L27,"0%") -> 1.1271673 | P27: =IF(D27=0,0,SUM($L$20:L27)) -> 4020.2092 | Q27: =IF(D27=0,0,SUM($J$20:J27)) -> 5582.2911 | R27: =IF(D27=0,0,Q27-P27) -> 1562.0819 | S27: =IFERROR(Q27/P27,"0%") -> 1.3885573 | U27: =IF(D27=0,0,SUM($L$20:L27)) -> 4020.2092 | V27: =IF(D27=0,0,SUM($J$20:J27)) -> 5582.2911 | W27: =IF(D27=0,0,V27-U27) -> 1562.0819 | X27: =IFERROR(V27/U27,"0%") -> 1.3885573 | Z27: =Z26+1 -> 45299 | AA27: =AA26+1 -> 45299 | AB27: 45299 | AC27: 2 | AD27: 月 | AE27: =AVERAGEIFS(J51:J79,D51:D79,1,G51:G79,"mon") -> 2095.7948 | AF27: =COUNTIFS(D51:D79,1,G51:G79,"Mon") -> 3 | AH27: =AE27*AF27 -> 6287.3844 | AI27: =AH27/$M$7 -> 0.13869924 | AJ27: =SUM(AI27:AI33) -> 1 | AK27: 51〜79 | AS27: =AS26+1 -> 45299
C28: =C27+1 -> 9 | D28: 1 | E28: =TEXT(AA28,"m") -> 1 | F28: =F27+1 -> 45300 | G28: =TEXT(AS28,"ddd") -> Tue | J28: =143850/$B$13 -> 1303.6977 | L28: =IF(D28=0,0,$K$6) -> 2010.1046 | M28: =IF(D28=0,0,J28-L28) -> -706.40696 | N28: =IFERROR(J28/L28,"0%") -> 0.64857204 | P28: =IF(D28=0,0,SUM($L$20:L28)) -> 6030.3139 | Q28: =IF(D28=0,0,SUM($J$20:J28)) -> 6885.9888 | R28: =IF(D28=0,0,Q28-P28) -> 855.67489 | S28: =IFERROR(Q28/P28,"0%") -> 1.1418956 | U28: =IF(D28=0,0,SUM($L$20:L28)) -> 6030.3139 | V28: =IF(D28=0,0,SUM($J$20:J28)) -> 6885.9888 | W28: =IF(D28=0,0,V28-U28) -> 855.67489 | X28: =IFERROR(V28/U28,"0%") -> 1.1418956 | Z28: =Z27+1 -> 45300 | AA28: =AA27+1 -> 45300 | AB28: 45300 | AC28: 2 | AD28: 火 | AE28: =AVERAGEIFS(J51:J79,D51:D79,1,G51:G79,"tue") -> 1941.6803 | AF28: =COUNTIFS(D51:D79,1,G51:G79,"tue") -> 4 | AH28: =AE28*AF28 -> 7766.721 | AI28: =AH28/$M$7 -> 0.17133329 | AS28: =AS27+1 -> 45300
C29: =C28+1 -> 10 | D29: 1 | E29: =TEXT(AA29,"m") -> 1 | F29: =F28+1 -> 45301 | G29: =TEXT(AS29,"ddd") -> Wed | J29: =331400/$B$13 -> 3003.4439 | L29: =IF(D29=0,0,$K$6) -> 2010.1046 | M29: =IF(D29=0,0,J29-L29) -> 993.33928 | N29: =IFERROR(J29/L29,"0%") -> 1.4941729 | P29: =IF(D29=0,0,SUM($L$20:L29)) -> 8040.4185 | Q29: =IF(D29=0,0,SUM($J$20:J29)) -> 9889.4327 | R29: =IF(D29=0,0,Q29-P29) -> 1849.0142 | S29: =IFERROR(Q29/P29,"0%") -> 1.2299649 | U29: =IF(D29=0,0,SUM($L$20:L29)) -> 8040.4185 | V29: =IF(D29=0,0,SUM($J$20:J29)) -> 9889.4327 | W29: =IF(D29=0,0,V29-U29) -> 1849.0142 | X29: =IFERROR(V29/U29,"0%") -> 1.2299649 | Z29: =Z28+1 -> 45301 | AA29: =AA28+1 -> 45301 | AB29: 45301 | AC29: 2 | AD29: 水 | AE29: =AVERAGEIFS(J51:J79,D51:D79,1,G51:G79,"wed") -> 2009.4028 | AF29: =COUNTIFS(D51:D79,1,G51:G79,"wed") -> 4 | AH29: =AE29*AF29 -> 8037.611 | AI29: =AH29/$M$7 -> 0.1773091 | AS29: =AS28+1 -> 45301
C30: =C29+1 -> 11 | D30: 1 | E30: =TEXT(AA30,"m") -> 1 | F30: =F29+1 -> 45302 | G30: =TEXT(AS30,"ddd") -> Thu | J30: =263220/$B$13 -> 2385.5356 | L30: =IF(D30=0,0,$K$6) -> 2010.1046 | M30: =IF(D30=0,0,J30-L30) -> 375.43099 | N30: =IFERROR(J30/L30,"0%") -> 1.1867719 | P30: =IF(D30=0,0,SUM($L$20:L30)) -> 10050.523 | Q30: =IF(D30=0,0,SUM($J$20:J30)) -> 12274.968 | R30: =IF(D30=0,0,Q30-P30) -> 2224.4452 | S30: =IFERROR(Q30/P30,"0%") -> 1.2213263 | U30: =IF(D30=0,0,SUM($L$20:L30)) -> 10050.523 | V30: =IF(D30=0,0,SUM($J$20:J30)) -> 12274.968 | W30: =IF(D30=0,0,V30-U30) -> 2224.4452 | X30: =IFERROR(V30/U30,"0%") -> 1.2213263 | Z30: =Z29+1 -> 45302 | AA30: =AA29+1 -> 45302 | AB30: 45302 | AC30: 2 | AD30: 木 | AE30: =AVERAGEIFS(J51:J79,D51:D79,1,G51:G79,"thu") -> 2115.2438 | AF30: =COUNTIFS(D51:D79,1,G51:G79,"thu") -> 5 | AH30: =AE30*AF30 -> 10576.219 | AI30: =AH30/$M$7 -> 0.23331061 | AS30: =AS29+1 -> 45302
C31: =C30+1 -> 12 | D31: 1 | E31: =TEXT(AA31,"m") -> 1 | F31: =F30+1 -> 45303 | G31: =TEXT(AS31,"ddd") -> Fri | J31: =230860/$B$13 -> 2092.2603 | L31: =IF(D31=0,0,$K$6) -> 2010.1046 | M31: =IF(D31=0,0,J31-L31) -> 82.155662 | N31: =IFERROR(J31/L31,"0%") -> 1.0408713 | P31: =IF(D31=0,0,SUM($L$20:L31)) -> 12060.628 | Q31: =IF(D31=0,0,SUM($J$20:J31)) -> 14367.229 | R31: =IF(D31=0,0,Q31-P31) -> 2306.6008 | S31: =IFERROR(Q31/P31,"0%") -> 1.1912505 | U31: =IF(D31=0,0,SUM($L$20:L31)) -> 12060.628 | V31: =IF(D31=0,0,SUM($J$20:J31)) -> 14367.229 | W31: =IF(D31=0,0,V31-U31) -> 2306.6008 | X31: =IFERROR(V31/U31,"0%") -> 1.1912505 | Z31: =Z30+1 -> 45303 | AA31: =AA30+1 -> 45303 | AB31: 45303 | AC31: 2 | AD31: 金 | AE31: =AVERAGEIFS(J51:J79,D51:D79,1,G51:G79,"fri") -> 2572.8959 | AF31: =COUNTIFS(D51:D79,1,G51:G79,"fri") -> 3 | AH31: =AE31*AF31 -> 7718.6877 | AI31: =AH31/$M$7 -> 0.17027368 | AS31: =AS30+1 -> 45303
C32: =C31+1 -> 13 | D32: 1 | E32: =TEXT(AA32,"m") -> 1 | F32: =F31+1 -> 45304 | G32: =TEXT(AS32,"ddd") -> Sat | J32: =50050/$B$13 -> 453.59797 | L32: =IF(D32=0,0,$K$6) -> 2010.1046 | M32: =IF(D32=0,0,J32-L32) -> -1556.5067 | N32: =IFERROR(J32/L32,"0%") -> 0.22565889 | P32: =IF(D32=0,0,SUM($L$20:L32)) -> 14070.732 | Q32: =IF(D32=0,0,SUM($J$20:J32)) -> 14820.827 | R32: =IF(D32=0,0,Q32-P32) -> 750.09416 | S32: =IFERROR(Q32/P32,"0%") -> 1.0533088 | U32: =IF(D32=0,0,SUM($L$20:L32)) -> 14070.732 | V32: =IF(D32=0,0,SUM($J$20:J32)) -> 14820.827 | W32: =IF(D32=0,0,V32-U32) -> 750.09416 | X32: =IFERROR(V32/U32,"0%") -> 1.0533088 | Z32: =Z31+1 -> 45304 | AA32: =AA31+1 -> 45304 | AB32: 45304 | AC32: 2 | AD32: 土 | AE32: =AVERAGEIFS(J51:J79,D51:D79,1,G51:G79,"sat") -> 1236.1111 | AF32: =COUNTIFS(D51:D79,1,G51:G79,"sat") -> 4 | AH32: =AE32*AF32 -> 4944.4444 | AI32: =AH32/$M$7 -> 0.10907408 | AS32: =AS31+1 -> 45304
C33: =C32+1 -> 14 | D33: 0 | E33: =TEXT(AA33,"m") -> 1 | F33: =F32+1 -> 45305 | G33: =TEXT(AS33,"ddd") -> Sun | L33: =IF(D33=0,0,$K$6) -> 0 | M33: =IF(D33=0,0,J33-L33) -> 0 | N33: =IFERROR(J33/L33,"0%") -> 0% | P33: =IF(D33=0,0,SUM($L$20:L33)) -> 0 | Q33: =IF(D33=0,0,SUM($J$20:J33)) -> 0 | R33: =IF(D33=0,0,Q33-P33) -> 0 | S33: =IFERROR(Q33/P33,"0%") -> 0% | U33: =IF(D33=0,0,SUM($L$20:L33)) -> 0 | V33: =IF(D33=0,0,SUM($J$20:J33)) -> 0 | W33: =IF(D33=0,0,V33-U33) -> 0 | X33: =IFERROR(V33/U33,"0%") -> 0% | Z33: =Z32+1 -> 45305 | AA33: =AA32+1 -> 45305 | AB33: 45305 | AC33: 2 | AD33: 日 | AE33: =IFERROR(AVERAGEIFS(J51:J79,D51:D79,1,G51:G79,"sun"),0) -> 0 | AF33: =IFERROR(COUNTIFS(D51:D79,1,G51:G79,"sun"),0) -> 0 | AH33: =AE33*AF33 -> 0 | AI33: =AH33/$M$7 -> 0 | AS33: =AS32+1 -> 45305
C34: =C33+1 -> 15 | D34: 1 | E34: =TEXT(AA34,"m") -> 1 | F34: =F33+1 -> 45306 | G34: =TEXT(AS34,"ddd") -> Mon | J34: =189100/$B$13 -> 1713.7937 | L34: =IF(D34=0,0,$K$6) -> 2010.1046 | M34: =IF(D34=0,0,J34-L34) -> -296.3109 | N34: =IFERROR(J34/L34,"0%") -> 0.85258932 | P34: =IF(D34=0,0,SUM($L$20:L34)) -> 16080.837 | Q34: =IF(D34=0,0,SUM($J$20:J34)) -> 16534.62 | R34: =IF(D34=0,0,Q34-P34) -> 453.78327 | S34: =IFERROR(Q34/P34,"0%") -> 1.0282189 | U34: =IF(D34=0,0,SUM($L$20:L34)) -> 16080.837 | V34: =IF(D34=0,0,SUM($J$20:J34)) -> 16534.62 | W34: =IF(D34=0,0,V34-U34) -> 453.78327 | X34: =IFERROR(V34/U34,"0%") -> 1.0282189 | Z34: =Z33+1 -> 45306 | AA34: =AA33+1 -> 45306 | AB34: 45306 | AC34: 3 | AD34: 月 | AE34: =AVERAGEIFS(J80:J110,D80:D110,1,G80:G110,"mon") -> 2075.0634 | AF34: =COUNTIFS( D80:D110,1,G80:G110,"Mon") -> 4 | AH34: =AE34*AF34 -> 8300.2538 | AI34: =AH34/$M$8 -> 0.1417591 | AJ34: =SUM(AI34:AI40) -> 1 | AK34: 80〜110 | AS34: =AS33+1 -> 45306
C35: =C34+1 -> 16 | D35: 1 | E35: =TEXT(AA35,"m") -> 1 | F35: =F34+1 -> 45307 | G35: =TEXT(AS35,"ddd") -> Tue | J35: =212700/$B$13 -> 1927.6781 | L35: =IF(D35=0,0,$K$6) -> 2010.1046 | M35: =IF(D35=0,0,J35-L35) -> -82.426539 | N35: =IFERROR(J35/L35,"0%") -> 0.95899391 | P35: =IF(D35=0,0,SUM($L$20:L35)) -> 18090.942 | Q35: =IF(D35=0,0,SUM($J$20:J35)) -> 18462.298 | R35: =IF(D35=0,0,Q35-P35) -> 371.35673 | S35: =IFERROR(Q35/P35,"0%") -> 1.0205272 | U35: =IF(D35=0,0,SUM($L$20:L35)) -> 18090.942 | V35: =IF(D35=0,0,SUM($J$20:J35)) -> 18462.298 | W35: =IF(D35=0,0,V35-U35) -> 371.35673 | X35: =IFERROR(V35/U35,"0%") -> 1.0205272 | Z35: =Z34+1 -> 45307 | AA35: =AA34+1 -> 45307 | AB35: 45307 | AC35: 3 | AD35: 火 | AE35: =AVERAGEIFS(J80:J110,D80:D110,1,G80:G110,"tue") -> 2392.3101 | AF35: =COUNTIFS( D80:D110,1,G80:G110,"tue") -> 4 | AH35: =AE35*AF35 -> 9569.2405 | AI35: =AH35/$M$8 -> 0.16343199 | AS35: =AS34+1 -> 45307
C36: =C35+1 -> 17 | D36: 1 | E36: =TEXT(AA36,"m") -> 1 | F36: =F35+1 -> 45308 | G36: =TEXT(AS36,"ddd") -> Wed | J36: =172600/$B$13 -> 1564.2559 | L36: =IF(D36=0,0,$K$6) -> 2010.1046 | M36: =IF(D36=0,0,J36-L36) -> -445.84869 | N36: =IFERROR(J36/L36,"0%") -> 0.77819628 | P36: =IF(D36=0,0,SUM($L$20:L36)) -> 20101.046 | Q36: =IF(D36=0,0,SUM($J$20:J36)) -> 20026.554 | R36: =IF(D36=0,0,Q36-P36) -> -74.49196 | S36: =IFERROR(Q36/P36,"0%") -> 0.99629413 | U36: =IF(D36=0,0,SUM($L$20:L36)) -> 20101.046 | V36: =IF(D36=0,0,SUM($J$20:J36)) -> 20026.554 | W36: =IF(D36=0,0,V36-U36) -> -74.49196 | X36: =IFERROR(V36/U36,"0%") -> 0.99629413 | Z36: =Z35+1 -> 45308 | AA36: =AA35+1 -> 45308 | AB36: 45308 | AC36: 3 | AD36: 水 | AE36: =AVERAGEIFS(J80:J110,D80:D110,1,G80:G110,"wed") -> 2664.0384 | AF36: =COUNTIFS( D80:D110,1,G80:G110,"wed") -> 3 | AH36: =AE36*AF36 -> 7992.1153 | AI36: =AH36/$M$8 -> 0.13649644 | AS36: =AS35+1 -> 45308
C37: =C36+1 -> 18 | D37: 1 | E37: =TEXT(AA37,"m") -> 1 | F37: =F36+1 -> 45309 | G37: =TEXT(AS37,"ddd") -> Thu | J37: =155450/$B$13 -> 1408.8273 | L37: =IF(D37=0,0,$K$6) -> 2010.1046 | M37: =IF(D37=0,0,J37-L37) -> -601.27736 | N37: =IFERROR(J37/L37,"0%") -> 0.7008726 | P37: =IF(D37=0,0,SUM($L$20:L37)) -> 22111.151 | Q37: =IF(D37=0,0,SUM($J$20:J37)) -> 21435.382 | R37: =IF(D37=0,0,Q37-P37) -> -675.76932 | S37: =IFERROR(Q37/P37,"0%") -> 0.96943762 | U37: =IF(D37=0,0,SUM($L$20:L37)) -> 22111.151 | V37: =IF(D37=0,0,SUM($J$20:J37)) -> 21435.382 | W37: =IF(D37=0,0,V37-U37) -> -675.76932 | X37: =IFERROR(V37/U37,"0%") -> 0.96943762 | Z37: =Z36+1 -> 45309 | AA37: =AA36+1 -> 45309 | AB37: 45309 | AC37: 3 | AD37: 木 | AE37: =AVERAGEIFS(J80:J110,D80:D110,1,G80:G110,"thu") -> 2796.8778 | AF37: =COUNTIFS( D80:D110,1,G80:G110,"thu") -> 4 | AH37: =AE37*AF37 -> 11187.511 | AI37: =AH37/$M$8 -> 0.19107025 | AS37: =AS36+1 -> 45309
C38: =C37+1 -> 19 | D38: 1 | E38: =TEXT(AA38,"m") -> 1 | F38: =F37+1 -> 45310 | G38: =TEXT(AS38,"ddd") -> Fri | J38: =286750/$B$13 -> 2598.7856 | L38: =IF(D38=0,0,$K$6) -> 2010.1046 | M38: =IF(D38=0,0,J38-L38) -> 588.68095 | N38: =IFERROR(J38/L38,"0%") -> 1.2928608 | P38: =IF(D38=0,0,SUM($L$20:L38)) -> 24121.255 | Q38: =IF(D38=0,0,SUM($J$20:J38)) -> 24034.167 | R38: =IF(D38=0,0,Q38-P38) -> -87.088377 | S38: =IFERROR(Q38/P38,"0%") -> 0.99638956 | U38: =IF(D38=0,0,SUM($L$20:L38)) -> 24121.255 | V38: =IF(D38=0,0,SUM($J$20:J38)) -> 24034.167 | W38: =IF(D38=0,0,V38-U38) -> -87.088377 | X38: =IFERROR(V38/U38,"0%") -> 0.99638956 | Z38: =Z37+1 -> 45310 | AA38: =AA37+1 -> 45310 | AB38: 45310 | AC38: 3 | AD38: 金 | AE38: =AVERAGEIFS(J80:J110,D80:D110,1,G80:G110,"fri") -> 2923.926 | AF38: =COUNTIFS( D80:D110,1,G80:G110,"fri") -> 5 | AH38: =AE38*AF38 -> 14619.63 | AI38: =AH38/$M$8 -> 0.24968703 | AS38: =AS37+1 -> 45310
C39: =C38+1 -> 20 | D39: 1 | E39: =TEXT(AA39,"m") -> 1 | F39: =F38+1 -> 45311 | G39: =TEXT(AS39,"ddd") -> Sat | J39: =139100/$B$13 -> 1260.6489 | L39: =IF(D39=0,0,$K$6) -> 2010.1046 | M39: =IF(D39=0,0,J39-L39) -> -749.45572 | N39: =IFERROR(J39/L39,"0%") -> 0.62715586 | P39: =IF(D39=0,0,SUM($L$20:L39)) -> 26131.36 | Q39: =IF(D39=0,0,SUM($J$20:J39)) -> 25294.816 | R39: =IF(D39=0,0,Q39-P39) -> -836.5441 | S39: =IFERROR(Q39/P39,"0%") -> 0.96798697 | U39: =IF(D39=0,0,SUM($L$20:L39)) -> 26131.36 | V39: =IF(D39=0,0,SUM($J$20:J39)) -> 25294.816 | W39: =IF(D39=0,0,V39-U39) -> -836.5441 | X39: =IFERROR(V39/U39,"0%") -> 0.96798697 | Z39: =Z38+1 -> 45311 | AA39: =AA38+1 -> 45311 | AB39: 45311 | AC39: 3 | AD39: 土 | AE39: =AVERAGEIFS(J80:J110,D80:D110,1,G80:G110,"sat") -> 1376.6141 | AF39: =COUNTIFS( D80:D110,1,G80:G110,"sat") -> 5 | AH39: =AE39*AF39 -> 6883.0705 | AI39: =AH39/$M$8 -> 0.11755519 | AS39: =AS38+1 -> 45311
C40: =C39+1 -> 21 | D40: 0 | E40: =TEXT(AA40,"m") -> 1 | F40: =F39+1 -> 45312 | G40: =TEXT(AS40,"ddd") -> Sun | H40: 日曜日 | L40: =IF(D40=0,0,$K$6) -> 0 | M40: =IF(D40=0,0,J40-L40) -> 0 | N40: =IFERROR(J40/L40,"0%") -> 0% | P40: =IF(D40=0,0,SUM($L$20:L40)) -> 0 | Q40: =IF(D40=0,0,SUM($J$20:J40)) -> 0 | R40: =IF(D40=0,0,Q40-P40) -> 0 | S40: =IFERROR(Q40/P40,"0%") -> 0% | U40: =IF(D40=0,0,SUM($L$20:L40)) -> 0 | V40: =IF(D40=0,0,SUM($J$20:J40)) -> 0 | W40: =IF(D40=0,0,V40-U40) -> 0 | X40: =IFERROR(V40/U40,"0%") -> 0% | Z40: =Z39+1 -> 45312 | AA40: =AA39+1 -> 45312 | AB40: 45312 | AC40: 3 | AD40: 日 | AE40: =IFERROR(AVERAGEIFS(J80:J110,D80:D110,3,G80:G110,"sun"),0) -> 0 | AF40: =IFERROR(COUNTIFS( D80:D110,1,G80:G110,"sun"),0) -> 0 | AH40: =AE40*AF40 -> 0 | AI40: =AH40/$M$8 -> 0 | AS40: =AS39+1 -> 45312
C41: =C40+1 -> 22 | D41: 1 | E41: =TEXT(AA41,"m") -> 1 | F41: =F40+1 -> 45313 | G41: =TEXT(AS41,"ddd") -> Mon | J41: =250550/$B$13 -> 2270.7087 | L41: =IF(D41=0,0,$K$6) -> 2010.1046 | M41: =IF(D41=0,0,J41-L41) -> 260.60409 | N41: =IFERROR(J41/L41,"0%") -> 1.129647 | P41: =IF(D41=0,0,SUM($L$20:L41)) -> 28141.465 | Q41: =IF(D41=0,0,SUM($J$20:J41)) -> 27565.525 | R41: =IF(D41=0,0,Q41-P41) -> -575.94 | S41: =IFERROR(Q41/P41,"0%") -> 0.97953411 | U41: =IF(D41=0,0,SUM($L$20:L41)) -> 28141.465 | V41: =IF(D41=0,0,SUM($J$20:J41)) -> 27565.525 | W41: =IF(D41=0,0,V41-U41) -> -575.94 | X41: =IFERROR(V41/U41,"0%") -> 0.97953411 | Z41: =Z40+1 -> 45313 | AA41: =AA40+1 -> 45313 | AB41: 45313 | AC41: 4 | AD41: 月 | AE41: =AVERAGEIFS(J111:J140,D111:D140,1,G111:G140,"mon") -> 2069.6484 | AF41: =COUNTIFS(D111:D140,1,G111:G140,"Mon") -> 4 | AH41: =AE41*AF41 -> 8278.5934 | AI41: =AH41/$M$9 -> 0.13681398 | AJ41: =SUM(AI41:AI47) -> 1 | AK41: 111〜140 | AS41: =AS40+1 -> 45313
C42: =C41+1 -> 23 | D42: 1 | E42: =TEXT(AA42,"m") -> 1 | F42: =F41+1 -> 45314 | G42: =TEXT(AS42,"ddd") -> Tue | J42: =312544/$B$13 -> 2832.5539 | L42: =IF(D42=0,0,$K$6) -> 2010.1046 | M42: =IF(D42=0,0,J42-L42) -> 822.4493 | N42: =IFERROR(J42/L42,"0%") -> 1.4091575 | P42: =IF(D42=0,0,SUM($L$20:L42)) -> 30151.569 | Q42: =IF(D42=0,0,SUM($J$20:J42)) -> 30398.079 | R42: =IF(D42=0,0,Q42-P42) -> 246.5093 | S42: =IFERROR(Q42/P42,"0%") -> 1.0081757 | U42: =IF(D42=0,0,SUM($L$20:L42)) -> 30151.569 | V42: =IF(D42=0,0,SUM($J$20:J42)) -> 30398.079 | W42: =IF(D42=0,0,V42-U42) -> 246.5093 | X42: =IFERROR(V42/U42,"0%") -> 1.0081757 | Z42: =Z41+1 -> 45314 | AA42: =AA41+1 -> 45314 | AB42: 45314 | AC42: 4 | AD42: 火 | AE42: =AVERAGEIFS(J111:J140,D111:D140,1,G111:G140,"tue") -> 2445.2365 | AF42: =COUNTIFS(D111:D140,1,G111:G140,"tue") -> 5 | AH42: =AE42*AF42 -> 12226.183 | AI42: =AH42/$M$9 -> 0.20205276 | AS42: =AS41+1 -> 45314
C43: =C42+1 -> 24 | D43: 1 | E43: =TEXT(AA43,"m") -> 1 | F43: =F42+1 -> 45315 | G43: =TEXT(AS43,"ddd") -> Wed | J43: =255500/$B$13 -> 2315.5701 | L43: =IF(D43=0,0,$K$6) -> 2010.1046 | M43: =IF(D43=0,0,J43-L43) -> 305.46543 | N43: =IFERROR(J43/L43,"0%") -> 1.1519649 | P43: =IF(D43=0,0,SUM($L$20:L43)) -> 32161.674 | Q43: =IF(D43=0,0,SUM($J$20:J43)) -> 32713.649 | R43: =IF(D43=0,0,Q43-P43) -> 551.97473 | S43: =IFERROR(Q43/P43,"0%") -> 1.0171625 | U43: =IF(D43=0,0,SUM($L$20:L43)) -> 32161.674 | V43: =IF(D43=0,0,SUM($J$20:J43)) -> 32713.649 | W43: =IF(D43=0,0,V43-U43) -> 551.97473 | X43: =IFERROR(V43/U43,"0%") -> 1.0171625 | Z43: =Z42+1 -> 45315 | AA43: =AA42+1 -> 45315 | AB43: 45315 | AC43: 4 | AD43: 水 | AE43: =AVERAGEIFS(J111:J140,D111:D140,1,G111:G140,"wed") -> 2652.8004 | AF43: =COUNTIFS(D111:D140,1,G111:G140,"wed") -> 4 | AH43: =AE43*AF43 -> 10611.202 | AI43: =AH43/$M$9 -> 0.17536321 | AS43: =AS42+1 -> 45315
...

Sheet 2025(¥)
B2: 45658 | E2: ①年間営業日 | G2: ②年間目標売上 | H2: 年間総売上％ | K2: 年間売上合計 | M2: 実質売上 | P2: 1月 | Q2: 2月 | R2: 3月 | S2: 4月 | T2: ←目標の月へジャンプ
E3: =SUM(F7:F18) -> 286 | G3: 72000000 | H3: =SUM(AK7:AK18)*100 -> 0.999996 | I3: =G3*H3 -> 71999712 | K3: =SUM(J21:J385) -> 76266459 | M3: =K3-G3 -> 4266459 | N3: =K3/I3 -> 1.0592606 | P3: 5月 | Q3: 6月 | R3: 7月 | S3: 8月
P4: 9月 | Q4: 10月 | R4: 11月 | S4: 12月
B6: 平均日次売上目標額 | E6: 月 | F6: 月次営業日数 | G6: 平均月間売上目標額 | H6: 月次繁閑期%設定 | I6: 月次目標売上 | K6: 日次目標売上 | M6: 月次売上実績 | N6: 月間KGI | P6: 月次平均%(繁閑期) | Q6: 月次実質%
B7: ② ÷ ① | E7: 1月 | F7: =COUNTIF(D21:D51,1) -> 22 | G7: =$B$8*F7 -> 5538461.5 | H7: 0.85 | I7: =G7*H7 -> 4707692.3 | K7: =I7/F7 -> 213986.01 | M7: =SUM(J21:J51) -> 5613250 | N7: =M7-I7 -> 905557.69 | P7: =M7/G7 -> 1.0135035 | Q7: =M7/I7 -> 1.192357 | R7: 1 | AK7: =(H7/100)*AL7 -> 0.0007083305 | AL7: 0.083333
B8: =G3/E3 -> 251748.25 | E8: 2月 | F8: =COUNTIF(D52:D79,1) -> 22 | G8: =$B$8*F8 -> 5538461.5 | H8: 0.85 | I8: =G8*H8 -> 4707692.3 | K8: =I8/F8 -> 213986.01 | M8: =SUM(J52:J79) -> 5503840 | N8: =M8-I8 -> 796147.69 | P8: =M8/G8 -> 0.99374889 | Q8: =M8/I8 -> 1.1691163 | R8: 2 | AK8: =(H8/100)*AL8 -> 0.0007083305 | AL8: 0.083333
E9: 3月 | F9: =COUNTIF(D80:D110,1) -> 25 | G9: =$B$8*F9 -> 6293706.3 | H9: 1 | I9: =G9*H9 -> 6293706.3 | K9: =I9/F9 -> 251748.25 | M9: =SUM(J80:J110) -> 6144090 | N9: =M9-I9 -> -149616.29 | P9: =M9/G9 -> 0.97622763 | Q9: =M9/I9 -> 0.97622763 | R9: 3 | AK9: =(H9/100)*AL9 -> 0.00083333 | AL9: 0.083333
E10: 4月 | F10: =COUNTIF(D111:D140,1) -> 25 | G10: =$B$8*F10 -> 6293706.3 | H10: 1.1 | I10: =G10*H10 -> 6923076.9 | K10: =I10/F10 -> 276923.08 | M10: =SUM(J111:J140) -> 6763280 | N10: =M10-I10 -> -159796.92 | P10: =M10/G10 -> 1.07461 | Q10: =M10/I10 -> 0.97691822 | R10: 4 | AK10: =(H10/100)*AL10 -> 0.000916663 | AL10: 0.083333
E11: 5月 | F11: =COUNTIF(D141:D171,1) -> 24 | G11: =$B$8*F11 -> 6041958 | H11: 1 | I11: =G11*H11 -> 6041958 | K11: =I11/F11 -> 251748.25 | M11: =SUM(J141:J171) -> 6041958 | N11: =M11-I11 -> 0 | P11: =M11/G11 -> 1 | Q11: =M11/I11 -> 1 | R11: 5 | AK11: =(H11/100)*AL11 -> 0.00083333 | AL11: 0.083333
E12: 6月 | F12: =COUNTIF(D172:D201,1) -> 25 | G12: =$B$8*F12 -> 6293706.3 | H12: 0.85 | I12: =G12*H12 -> 5349650.3 | K12: =I12/F12 -> 213986.01 | M12: =SUM(J172:J201) -> 6103080 | N12: =M12-I12 -> 753429.65 | P12: =M12/G12 -> 0.9697116 | Q12: =M12/I12 -> 1.1408372 | R12: 6 | AK12: =(H12/100)*AL12 -> 0.0007083305 | AL12: 0.083333
E13: 7月 | F13: =COUNTIF(D202:D232,1) -> 26 | G13: =$B$8*F13 -> 6545454.5 | H13: 1 | I13: =G13*H13 -> 6545454.5 | K13: =I13/F13 -> 251748.25 | M13: =SUM(J202:J232) -> 6581320 | N13: =M13-I13 -> 35865.455 | P13: =M13/G13 -> 1.0054794 | Q13: =M13/I13 -> 1.0054794 | R13: 7 | AK13: =(H13/100)*AL13 -> 0.00083333 | AL13: 0.083333
E14: 8月 | F14: =COUNTIF(D233:D263,1) -> 20 | G14: =$B$8*F14 -> 5034965 | H14: 1 | I14: =G14*H14 -> 5034965 | K14: =I14/F14 -> 251748.25 | M14: =SUM(J233:J263) -> 4857250 | N14: =M14-I14 -> -177715.03 | P14: =M14/G14 -> 0.96470382 | Q14: =M14/I14 -> 0.96470382 | R14: 8 | AK14: =(H14/100)*AL14 -> 0.00083333 | AL14: 0.083333
E15: 9 月 | F15: =COUNTIF(D264:D293,1) -> 24 | G15: =$B$8*F15 -> 6041958 | H15: 1 | I15: =G15*H15 -> 6041958 | K15: =I15/F15 -> 251748.25 | M15: =SUM(J264:J293) -> 6227066 | N15: =M15-I15 -> 185107.96 | P15: =M15/G15 -> 1.0306371 | Q15: =M15/I15 -> 1.0306371 | R15: 9 | AK15: =(H15/100)*AL15 -> 0.00083333 | AL15: 0.083333
E16: 10月 | F16: =COUNTIF(D294:D324,1) -> 26 | G16: =$B$8*F16 -> 6545454.5 | H16: 1.1 | I16: =G16*H16 -> 7200000 | K16: =I16/F16 -> 276923.08 | M16: =SUM(J294:J324) -> 7804180 | N16: =M16-I16 -> 604180 | P16: =M16/G16 -> 1.1923053 | Q16: =M16/I16 -> 1.0839139 | R16: 10 | AK16: =(H16/100)*AL16 -> 0.000916663 | AL16: 0.083333
