Workbook

Sheet ★プラナバルカ戦略表
A2: プラナバルカ | B2: 45962 | C2: =MONTH(B2) -> 11
B3: =B15 -> 45974 | D3: =TEXT(B3, "aaa") -> 木
B4: 目標売上 | C4: =_xlfn.XLOOKUP(D3, B7:B12, C7:C12, "該当なし") -> 該当なし
B6: 9月 曜日毎の目標売上 | D6: 傾向 | G6: 対策考察
B7: mon | C7: =SUMIFS(目標_2025R7!$AE$22:$AE$104, 目標_2025R7!$AA$22:$AA$104, MONTH($B$2), 目標_2025R7!$AB$22:$AB$104, B7) -> 219995.68 | D7: ランチ・ディナーともに客数は安定傾向。売上は全体平均よりやや下回るが、曜日内ではバランスの取れた動きが見られる。ランチ構成比が高め。 | G7: 週のスタートとして安心感を訴求する投稿が有効。ディナーの客単価は高めな一方、客数は少ないため、リピート促進や「月曜限定メニュー」などで来店動機づけを強化。
B8: tue | C8: =SUMIFS(目標_2025R7!$AE$22:$AE$104, 目標_2025R7!$AA$22:$AA$104, MONTH($B$2), 目標_2025R7!$AB$22:$AB$104, B8) -> 192620.47 | D8: 全体平均を下回る売上水準。ディナーの客単価・客数が共に控えめで、回転率の低さが目立つ。 | G8: 来店促進のため、SNSでのクーポンやペア割の訴求が効果的。ランチの来客数は一定のため、固定ファン向けの新メニューや限定セットで強化を図る。
B9: wed | C9: =SUMIFS(目標_2025R7!$AE$22:$AE$104, 目標_2025R7!$AA$22:$AA$104, MONTH($B$2), 目標_2025R7!$AB$22:$AB$104, B9) -> 222098.1 | D9: 全曜日中、最も売上が高く、ランチ・ディナー共に客単価・客数ともに好調。特にディナーの売上が突出。 | G9: 定着需要があると推測されるため、人気メニューの再告知や満席対策が重要。週前半のピークに備えてスタッフ体制を厚めに配置。
B10: thu | C10: =SUMIFS(目標_2025R7!$AE$22:$AE$104, 目標_2025R7!$AA$22:$AA$104, MONTH($B$2), 目標_2025R7!$AB$22:$AB$104, B10) -> 216358.54 | D10: 平均をやや上回る水準で安定。ランチ・ディナーともに偏りなく客数が確保されている。 | G10: 中間日としての安定運用が可能。レビュー促進やLINE登録キャンペーンなど、継続来店につながる施策を試みたい。
B11: fri | C11: =SUMIFS(目標_2025R7!$AE$22:$AE$104, 目標_2025R7!$AA$22:$AA$104, MONTH($B$2), 目標_2025R7!$AB$22:$AB$104, B11) -> 346355.42 | D11: 水曜に次ぐ高売上曜日。特にディナーの客数が最多であり、終末への流れによる需要の高まりが顕著。 | G11: ピーク帯の事前予約推奨、オペレーション効率化が必須。混雑時の待ち時間緩和策（簡易ドリンク提供等）も検討価値あり。
B12: sat | C12: =SUMIFS(目標_2025R7!$AE$22:$AE$104, 目標_2025R7!$AA$22:$AA$104, MONTH($B$2), 目標_2025R7!$AB$22:$AB$104, B12) -> 146897.8 | D12: 売上は全体平均を下回るが、ランチ客単価は最も高い。客数が少ないため、単価依存の構成となっている。 | G12: 昼飲みや記念日需要への訴求を強化。Instagramなどビジュアル訴求による週末の集客導線設計がカギ。予約なし来店の傾向も加味しつつ対応を。
E14: 下方修正案 | H14: 現状案
A15: プラナバルカ | B15: 45974 | C15: =TEXT(B15, "ddd") -> Thu | E15: 年間目標金額 | F15: =F29 -> 63000000 | H15: 年間目標金額 | I15: 75000000
A16: 日次 | B16: 売上 | C16: =_xlfn.XLOOKUP(B15, 目標_2025R7!F21:F385,目標_2025R7!J21:J385,"該当なし") -> 79100 | E16: 月次目標売上 | F16: =INDEX(目標_2025R7!I7:I18, MATCH(MONTH(B2), 目標_2025R7!AC7:AC18, 0)) -> 5084210.5 | H16: 月次目標売上 | I16: =INDEX(目標_2025R7!I7:I18, MATCH(MONTH(B2), 目標_2025R7!AC7:AC18, 0)) -> 5084210.5 | N16: 月 | O16: 傾向分析
B17: 平均目標売上 | C17: =INDEX(目標_2025R7!K7:K18, MATCH(C2, 目標_2025R7!AC7:AC18, 0)) -> 221052.63 | E17: 月次累計実績売上 | F17: =C22 -> 1636190 | H17: 月次累計実績売上 | I17: =C22 -> 1636190
B18: 目標売上 | C18: =_xlfn.XLOOKUP(C15, B7:B12, C7:C12, "該当なし") -> 216358.54 | E18: 差額 | F18: =F16-F17 -> 3448020.5 | H18: 差額 | I18: =I16-I17 -> 3448020.5 | N18: 1月 | O18: A: 月初・末が強い（中旬落ち）
B19: 差額 | C19: =C16-C18 -> -137258.54 | E19: 当月残営業日 | F19: {=(SUMPRODUCT((目標_2025R7!F21:F385>=B15)*(目標_2025R7!E21:E385=C2)*(目標_2025R7!D21:D385=1)))-1} -> 13 | H19: 当月残営業日 | I19: =F19 -> 13 | N19: 2月 | O19: B: 月末にかけて上がる
B20: 達成率 | C20: =IFERROR(C16/C18,0) -> 0.36559684 | E20: 今月1日あたりの目標売上 | F20: =IFERROR(F18/F19,0) -> 265232.35 | H20: 今月1日あたりの目標売上 | I20: =I18/I19 -> 265232.35 | N20: 3月 | O20: B: 同様に右肩上がり傾向
N21: 4月 | O21: A: 月初も末も強く安定感あり
A22: 月次 | B22: 累積売上 | C22: =_xlfn.XLOOKUP(B15, 目標_2025R7!F21:F385,目標_2025R7!Q21:Q385,"該当なし") -> 1636190 | N22: 5月 | O22: B: 徐々に上がる
B23: 累積目標売上 | C23: =_xlfn.XLOOKUP(B15, 目標_2025R7!F21:F385,目標_2025R7!P21:P385,"該当なし") -> 2122300.9 | E23: 年間営業日数 | F23: =目標_2025R7!E3 -> 285 | N23: 分類 | O23: 説明
B24: 差額 | C24: =C22-C23 -> -486110.94 | E24: =B34 -> 今年の残営業日数 | F24: =C34 -> 37 | N24: A: 初・末が強い | O24: 月初・月末の売上が高く、中旬が落ちるパターン
B25: 達成率 | C25: =IFERROR(C22/C23,0) -> 0.77095098 | E25: 直近までの営業日数 | F25: =F23-F24 -> 248 | N25: B: 徐々に上がる | O25: 月初が弱く、末に向かって売上が上がる
N26: C: 平均的 or 中旬強い | O26: 大きな偏りがない or 中旬が強いパターン
A27: 年次 | B27: 累積売上 | C27: =_xlfn.XLOOKUP(B15, 目標_2025R7!F21:F385,目標_2025R7!V21:V385,"該当なし") -> 54634150 | E27: 今年の今までの営業日平均売上 | F27: =C27/F25 -> 220298.99
B28: 累積目標売上 | C28: =_xlfn.XLOOKUP(B15, 目標_2025R7!F21:F385,目標_2025R7!U21:U385,"該当なし") -> 54710722 | E28: 今年の残営業日数での売上 | F28: =F27*F24 -> 8151062.7
B29: 差額 | C29: =C27-C28 -> -76571.992 | E29: 合計 | F29: 63000000
B30: 達成率 | C30: =IFERROR(C27/C28,0) -> 0.99860042
B32: 年次目標売上 | C32: =目標_2025R7!G3 -> 63000000
B33: 目標達成までの残額 | C33: =C32-C27 -> 8365850
B34: 今年の残営業日数 | C34: {=(SUMPRODUCT((目標_2025R7!F21:F385>=B15)*(目標_2025R7!D21:D385=1)))-1} -> 37
B35: 1日あたりの売上額 | C35: =IFERROR(C33/C34,0) -> 226104.05
B36: 年間達成率 | C36: =1-(C33/C32) -> 0.86720873
B38: 2025年7月の情報
B39: 曜日 | C39: 出現回数 | D39: 加重比率 | E39: 曜日別割当額 | F39: 1日あたり目標
B40: 月 | C40: 4 | D40: 0.1193 | E40: 894636 | F40: 223659
B41: 火 | C41: 5 | D41: 0.1404 | E41: 1053371 | F41: 210674
B42: 水 | C42: 5 | D42: 0.2035 | E42: 1526394 | F42: 305279
B43: 木 | C43: 5 | D43: 0.2281 | E43: 1710568 | F43: 342114
B44: 金 | C44: 4 | D44: 0.2189 | E44: 1641933 | F44: 410483
B45: 土 | C45: 4 | D45: 0.0897 | E45: 673097 | F45: 168274
...

Sheet 下方修正案
C2: 実績売上額 | D2: 目標売上額 | E2: 達成率 | F2: 営業日数 | G2: 平均売上額
B3: 1月 | C3: 6112150 | D3: 5538461.5 | E3: =C3/D3 -> 1.1035826 | F3: 22 | G3: =C3/F3 -> 277825 | I3: =IF(H3=1,G3,"")
B4: 2月 | C4: 5368670 | D4: 4923076.9 | E4: =C4/D4 -> 1.0905111 | F4: 22 | G4: =C4/F4 -> 244030.45 | I4: =IF(H4=1,G4,"")
B5: 3月 | C5: 7189290 | D5: 7692307.7 | E5: =C5/D5 -> 0.9346077 | F5: 25 | G5: =C5/F5 -> 287571.6 | I5: =IF(H5=1,G5,"")
B6: 4月 | C6: 7232940 | D6: 7692307.7 | E6: =C6/D6 -> 0.9402822 | F6: 25 | G6: =C6/F6 -> 289317.6 | I6: =IF(H6=1,G6,"")
B7: 5月 | C7: 5931330 | D7: 5370629.4 | E7: =C7/D7 -> 1.1044013 | F7: 24 | G7: =C7/F7 -> 247138.75 | I7: =IF(H7=1,G7,"")
B8: 6月 | C8: 5714340 | D8: 5944055.9 | E8: =C8/D8 -> 0.96135367 | F8: 25 | G8: =C8/F8 -> 228573.6 | H8: 1 | I8: =IF(H8=1,G8,"") -> 228573.6
B9: 7月 | C9: 5338530 | D9: 6545454.5 | E9: =C9/D9 -> 0.81560875 | F9: 26 | G9: =C9/F9 -> 205328.08 | H9: 1 | I9: =IF(H9=1,G9,"") -> 205328.08
B10: 8月 | C10: 2414310 | D10: 5594405.6 | E10: =C10/D10 -> 0.43155791 | F10: 20 | G10: =C10/F10 -> 120715.5 | H10: 1 | I10: =IF(H10=1,G10,"") -> 120715.5
C11: =SUM(C3:C10) -> 45301560 | F11: =SUM(F3:F10) -> 189 | H11: 平均 | I11: =AVERAGE(I3:I10) -> 184872.39
B13: 9 月 | C13: =$I$11*F13 -> 4436937.4 | D13: 5663505.2 | E13: =C13/D13 -> 0.78342603 | F13: 24 | G13: =C13/F13 -> 184872.39
B14: 10月 | C14: =$I$11*F14 -> 4806682.2 | D14: 6749010.4 | E14: =C14/D14 -> 0.71220548 | F14: 26 | G14: =C14/F14 -> 184872.39
B15: 11月 | C15: =$I$11*F15 -> 4252065 | D15: 6513031 | E15: =C15/D15 -> 0.65285502 | F15: 23 | G15: =C15/F15 -> 184872.39
B16: 12月 | C16: =$I$11*F16 -> 4436937.4 | D16: 7079381.5 | E16: =C16/D16 -> 0.62674082 | F16: 24 | G16: =C16/F16 -> 184872.39
C17: =SUM(C13:C16) -> 17932622 | F17: =SUM(F13:F16) -> 97
F18: =F11+F17 -> 286
B19: 年間合計 | C19: =SUM(C3:C10,SUM(C13:C16)) -> 63234182
C20: =[2]★プラナバルカ戦略表!F29 -> 63000000 | D20: 75000000 | E20: 80000000
C21: =C19-C20 -> 234182.05 | D21: =C19-D20 -> -11765818 | E21: =C19-E20 -> -16765818

Sheet 目標_2025R7
B2: 45658 | E2: ①年間営業日 | G2: ②年間目標売上 | H2: 年間総売上％ | K2: 年間売上合計 | M2: 実質売上 | P2: 1月 | Q2: 2月 | R2: 3月 | S2: 4月 | T2: ←目標の月へジャンプ
E3: =SUM(F7:F18) -> 285 | G3: =★プラナバルカ戦略表!F29 -> 63000000 | H3: =SUM(AD7:AD18)*100 -> 0.999996 | I3: =G3*H3 -> 62999748 | K3: =SUM(J21:J385) -> 56787100 | M3: =K3-G3 -> -6212900 | P3: 5月 | Q3: 6月 | R3: 7月 | S3: 8月
M4: =AVERAGE(M7:M13) -> 6111675.7 | P4: 9月 | Q4: 10月 | R4: 11月 | S4: 12月
B6: 平均日次売上目標額 | E6: 月 | F6: 月次営業日数 | G6: 平均月間売上目標額 | H6: 月次繁閑期%設定 | I6: 月次目標売上 | K6: 日次目標売上 | M6: 月次売上実績 | N6: 月間KGI | P6: 月次平均%(繁閑期) | Q6: 月次実質%
B7: ② ÷ ① | E7: 1月 | F7: =COUNTIF(D21:D51,1) -> 22 | G7: =$B$8*F7 -> 4863157.9 | H7: 1.2 | I7: =G7*H7 -> 5835789.5 | K7: =I7/F7 -> 265263.16 | M7: =SUM(J21:J51) -> 6006630 | N7: =M7-I7 -> 170840.53 | P7: =M7/G7 -> 1.2351295 | Q7: =M7/I7 -> 1.0292746 | R7: 0.9 | AA7: =TEXT(K7,"¥0") -> ¥265263 | AC7: 1 | AD7: =(H7/100)*AE7 -> 0.000999996 | AE7: 0.083333
B8: =G3/E3 -> 221052.63 | E8: 2月 | F8: =COUNTIF(D52:D79,1) -> 22 | G8: =$B$8*F8 -> 4863157.9 | H8: 1 | I8: =G8*H8 -> 4863157.9 | K8: =I8/F8 -> 221052.63 | M8: =SUM(J52:J79) -> 5368670 | N8: =M8-I8 -> 505512.11 | P8: =M8/G8 -> 1.1039473 | Q8: =M8/I8 -> 1.1039473 | R8: 0.8 | AA8: =TEXT(K8,"¥0") -> ¥221053 | AC8: 2 | AD8: =(H8/100)*AE8 -> 0.00083333 | AE8: 0.083333
E9: 3月 | F9: =COUNTIF(D80:D110,1) -> 25 | G9: =$B$8*F9 -> 5526315.8 | H9: 1.3 | I9: =G9*H9 -> 7184210.5 | K9: =I9/F9 -> 287368.42 | M9: =SUM(J80:J110) -> 7189290 | N9: =M9-I9 -> 5079.4737 | P9: =M9/G9 -> 1.3009191 | Q9: =M9/I9 -> 1.000707 | R9: 1.1 | AA9: =TEXT(K9,"¥0") -> ¥287368 | AC9: 3 | AD9: =(H9/100)*AE9 -> 0.001083329 | AE9: 0.083333
E10: 4月 | F10: =COUNTIF(D111:D140,1) -> 25 | G10: =$B$8*F10 -> 5526315.8 | H10: 1.3 | I10: =G10*H10 -> 7184210.5 | K10: =I10/F10 -> 287368.42 | M10: =SUM(J111:J140) -> 7232940 | N10: =M10-I10 -> 48729.474 | P10: =M10/G10 -> 1.3088177 | Q10: =M10/I10 -> 1.0067829 | R10: 1.1 | AA10: =TEXT(K10,"¥0") -> ¥287368 | AC10: 4 | AD10: =(H10/100)*AE10 -> 0.001083329 | AE10: 0.083333
E11: 5月 | F11: =COUNTIF(D141:D171,1) -> 24 | G11: =$B$8*F11 -> 5305263.2 | H11: 1.1 | I11: =G11*H11 -> 5835789.5 | K11: =I11/F11 -> 243157.89 | M11: =SUM(J141:J171) -> 5931330 | N11: =M11-I11 -> 95540.526 | P11: =M11/G11 -> 1.1180086 | Q11: =M11/I11 -> 1.0163715 | R11: 0.8 | AA11: =TEXT(K11,"¥0") -> ¥243158 | AC11: 5 | AD11: =(H11/100)*AE11 -> 0.000916663 | AE11: 0.083333
E12: 6月 | F12: =COUNTIF(D172:D201,1) -> 25 | G12: =$B$8*F12 -> 5526315.8 | H12: 1.1 | I12: =G12*H12 -> 6078947.4 | K12: =I12/F12 -> 243157.89 | M12: =SUM(J172:J201) -> 5714340 | N12: =M12-I12 -> -364607.37 | P12: =M12/G12 -> 1.0340234 | Q12: =M12/I12 -> 0.9400213 | R12: 0.85 | AA12: =TEXT(K12,"¥0") -> ¥243158 | AC12: 6 | AD12: =(H12/100)*AE12 -> 0.000916663 | AE12: 0.083333
E13: 7月 | F13: =COUNTIF(D202:D232,1) -> 26 | G13: =$B$8*F13 -> 5747368.4 | H13: 0.9 | I13: =G13*H13 -> 5172631.6 | K13: =I13/F13 -> 198947.37 | M13: =SUM(J202:J232) -> 5338530 | N13: =M13-I13 -> 165898.42 | P13: =M13/G13 -> 0.92886511 | Q13: =M13/I13 -> 1.0320723 | R13: 0.9 | AA13: =TEXT(K13,"¥0") -> ¥198947 | AC13: 7 | AD13: =(H13/100)*AE13 -> 0.000749997 | AE13: 0.083333
E14: 8月 | F14: =COUNTIF(D233:D263,1) -> 20 | G14: =$B$8*F14 -> 4421052.6 | H14: 0.5 | I14: =G14*H14 -> 2210526.3 | K14: =I14/F14 -> 110526.32 | M14: =SUM(J233:J263) -> 2414310 | N14: =M14-I14 -> 203783.68 | P14: =M14/G14 -> 0.54609393 | Q14: =M14/I14 -> 1.0921879 | R14: 1 | AA14: =TEXT(K14,"¥0") -> ¥110526 | AC14: 8 | AD14: =(H14/100)*AE14 -> 0.000416665 | AE14: 0.083333
E15: 9 月 | F15: =COUNTIF(D264:D293,1) -> 23 | G15: =$B$8*F15 -> 5084210.5 | H15: 0.6 | I15: =G15*H15 -> 3050526.3 | K15: =I15/F15 -> 132631.58 | M15: =SUM(J264:J293) -> 3957920 | N15: =M15-I15 -> 907393.68 | P15: =M15/G15 -> 0.77847288 | Q15: =M15/I15 -> 1.2974548 | R15: 1 | AA15: =TEXT(K15,"¥0") -> ¥132632 | AC15: 9 | AD15: =(H15/100)*AE15 -> 0.000499998 | AE15: 0.083333
E16: 10月 | F16: =COUNTIF(D294:D324,1) -> 26 | G16: =$B$8*F16 -> 5747368.4 | H16: 0.9 | I16: =G16*H16 -> 5172631.6 | K16: =I16/F16 -> 198947.37 | M16: =SUM(J294:J324) -> 3844000 | N16: =M16-I16 -> -1328631.6 | P16: =M16/G16 -> 0.66882784 | Q16: =M16/I16 -> 0.74314204 | R16: 1.1 | AA16: =TEXT(K16,"¥0") -> ¥198947 | AC16: 10 | AD16: =(H16/100)*AE16 -> 0.000749997 | AE16: 0.083333
E17: 11月 | F17: =COUNTIF(D325:D354,1) -> 23 | G17: =$B$8*F17 -> 5084210.5 | H17: 1 | I17: =G17*H17 -> 5084210.5 | K17: =I17/F17 -> 221052.63 | M17: =SUM(J325:J354) -> 3789140 | N17: =M17-I17 -> -1295070.5 | P17: =M17/G17 -> 0.74527598 | Q17: =M17/I17 -> 0.74527598 | R17: 1.2 | AA17: =TEXT(K17,"¥0") -> ¥221053 | AC17: 11 | AD17: =(H17/100)*AE17 -> 0.00083333 | AE17: 0.083333
E18: 12月 | F18: =COUNTIF(D355:D385,1) -> 24 | G18: =$B$8*F18 -> 5305263.2 | H18: 1.1 | I18: =G18*H18 -> 5835789.5 | K18: =I18/F18 -> 243157.89 | M18: =SUM(J355:J385) -> 0 | N18: =M18-I18 -> -5835789.5 | P18: =M18/G18 -> 0 | Q18: =M18/I18 -> 0 | R18: 1.25 | AA18: =TEXT(K18,"¥0") -> ¥243158 | AC18: 12 | AD18: =(H18/100)*AE18 -> 0.000916663 | AE18: 0.083333
E20: 月 | F20: 日程 | G20: 曜日 | H20: 日祝日 | J20: Daily売上入力 | L20: 目標売上 | M20: 実質売上 | N20: 実質% | P20: 月次目標売上 | Q20: 月次実質売上 | R20: 月次差額 | S20: 月次達成率 | U20: 年次目標売上 | V20: 年次実質売上 | W20: 年次差額 | X20: 年次達成率 | AA20: 月 | AB20: 曜日 | AC20: 実質曜日平均売上 | AD20: 曜日回数 | AE20: 曜日毎目標売上額 | AF20: 曜日毎トータル額
C21: 1 | D21: 0 | E21: =MONTH(Y21) -> 1 | F21: =B2 -> 45658 | G21: =TEXT(Z21,"ddd") -> Wed | H21: 元旦 | L21: =IF(D21=0,0,IFERROR(SUMIFS($AE$21:$AE$104,$AA$21:$AA$104,$E21,$AB$21:$AB$104,$G21),0)) -> 0 | M21: =IF(D21=0,0,J21-L21) -> 0 | N21: =IFERROR(J21/L21,"¥0") -> ¥0 | P21: =IF(D21=0,0,$K$7) -> 0 | Q21: =IF(D21=0,0,$J$21) -> 0 | R21: =IF(D21=0,0,Q21-P21) -> 0 | S21: =IF(D21=0,0,Q21/P21) -> 0 | U21: =IF(D21=0,0,$L$21) -> 0 | V21: =IF(D21=0,0,$J$21) -> 0 | W21: =IF(D21=0,0,V21-U21) -> 0 | X21: =IF(D21=0,0,V21/U21) -> 0 | Y21: =B2 -> 45658 | Z21: =B2 -> 45658 | AA21: 1 | AB21: mon | AC21: =IFERROR(AVERAGEIFS(J21:J51,D21:D51,1,G21:G51,"mon"),0) -> 299840 | AD21: =COUNTIFS(D21:D51,1,G21:G51,"Mon") -> 3 | AE21: =($I$7*実績_2024R6!AI20)/AD21 -> 395153.16 | AF21: =AD21*AE21 -> 1185459.5 | AG21: 21〜51
C22: 2 | D22: 0 | E22: =MONTH(Y22) -> 1 | F22: =F21+1 -> 45659 | G22: =TEXT(Z22,"ddd") -> Thu | H22: 休み | L22: =IF(D22=0,0,IFERROR(SUMIFS($AE$21:$AE$104,$AA$21:$AA$104,$E22,$AB$21:$AB$104,$G22),0)) -> 0 | M22: =IF(D22=0,0,J22-L22) -> 0 | N22: =IFERROR(J22/L22,"¥0") -> ¥0 | P22: =IF(D22=0,0,SUM($L$21:L22)) -> 0 | Q22: =IF(D22=0,0,SUM($J$21:J22)) -> 0 | R22: =IF(D22=0,0,Q22-P22) -> 0 | S22: =IF(D22=0,0,Q22/P22) -> 0 | U22: =IF(D22=0,0,SUM($L$21:L22)) -> 0 | V22: =IF(D22=0,0,SUM($J$21:J22)) -> 0 | W22: =IF(D22=0,0,V22-U22) -> 0 | X22: =IF(D22=0,0,V22/U22) -> 0 | Y22: =Y21+1 -> 45659 | Z22: =Z21+1 -> 45659 | AA22: 1 | AB22: tue | AC22: =IFERROR(AVERAGEIFS(J21:J51,D21:D51,1,G21:G51,"tue"),0) -> 241427.5 | AD22: =COUNTIFS(D21:D51,1,G21:G51,"tue") -> 4 | AE22: =($I$7*実績_2024R6!AI21)/AD22 -> 251136.8 | AF22: =AD22*AE22 -> 1004547.2
C23: 3 | D23: 0 | E23: =MONTH(Y23) -> 1 | F23: =F22+1 -> 45660 | G23: =TEXT(Z23,"ddd") -> Fri | H23: 休み | L23: =IF(D23=0,0,IFERROR(SUMIFS($AE$21:$AE$104,$AA$21:$AA$104,$E23,$AB$21:$AB$104,$G23),0)) -> 0 | M23: =IF(D23=0,0,J23-L23) -> 0 | N23: =IFERROR(J23/L23,"¥0") -> ¥0 | P23: =IF(D23=0,0,SUM($L$21:L23)) -> 0 | Q23: =IF(D23=0,0,SUM($J$21:J23)) -> 0 | R23: =IF(D23=0,0,Q23-P23) -> 0 | S23: =IF(D23=0,0,Q23/P23) -> 0 | U23: =IF(D23=0,0,SUM($L$21:L23)) -> 0 | V23: =IF(D23=0,0,SUM($J$21:J23)) -> 0 | W23: =IF(D23=0,0,V23-U23) -> 0 | X23: =IF(D23=0,0,V23/U23) -> 0 | Y23: =Y22+1 -> 45660 | Z23: =Z22+1 -> 45660 | AA23: 1 | AB23: wed | AC23: =IFERROR(AVERAGEIFS(J21:J51,D21:D51,1,G21:G51,"wed"),0) -> 230592.5 | AD23: =COUNTIFS(D21:D51,1,G21:G51,"wed") -> 4 | AE23: =IFERROR(($I$7*実績_2024R6!AI22)/AD23,0) -> 282865.79 | AF23: =AD23*AE23 -> 1131463.2
C24: 4 | D24: 0 | E24: =MONTH(Y24) -> 1 | F24: =F23+1 -> 45661 | G24: =TEXT(Z24,"ddd") -> Sat | H24: 休み | L24: =IF(D24=0,0,IFERROR(SUMIFS($AE$21:$AE$104,$AA$21:$AA$104,$E24,$AB$21:$AB$104,$G24),0)) -> 0 | M24: =IF(D24=0,0,J24-L24) -> 0 | N24: =IFERROR(J24/L24,"¥0") -> ¥0 | P24: =IF(D24=0,0,SUM($L$21:L24)) -> 0 | Q24: =IF(D24=0,0,SUM($J$21:J24)) -> 0 | R24: =IF(D24=0,0,Q24-P24) -> 0 | S24: =IF(D24=0,0,Q24/P24) -> 0 | U24: =IF(D24=0,0,SUM($L$21:L24)) -> 0 | V24: =IF(D24=0,0,SUM($J$21:J24)) -> 0 | W24: =IF(D24=0,0,V24-U24) -> 0 | X24: =IF(D24=0,0,V24/U24) -> 0 | Y24: =Y23+1 -> 45661 | Z24: =Z23+1 -> 45661 | AA24: 1 | AB24: thu | AC24: =IFERROR(AVERAGEIFS(J21:J51,D21:D51,1,G21:G51,"thu"),0) -> 392675 | AD24: =COUNTIFS(D21:D51,1,G21:G51,"thu") -> 4 | AE24: =($I$7*実績_2024R6!AI23)/AD24 -> 196518.52 | AF24: =AD24*AE24 -> 786074.07
C25: 5 | D25: 0 | E25: =MONTH(Y25) -> 1 | F25: =F24+1 -> 45662 | G25: =TEXT(Z25,"ddd") -> Sun | H25: 日曜日 | L25: =IF(D25=0,0,IFERROR(SUMIFS($AE$21:$AE$104,$AA$21:$AA$104,$E25,$AB$21:$AB$104,$G25),0)) -> 0 | M25: =IF(D25=0,0,J25-L25) -> 0 | N25: =IFERROR(J25/L25,"¥0") -> ¥0 | P25: =IF(D25=0,0,SUM($L$21:L25)) -> 0 | Q25: =IF(D25=0,0,SUM($J$21:J25)) -> 0 | R25: =IF(D25=0,0,Q25-P25) -> 0 | S25: =IF(D25=0,0,Q25/P25) -> 0 | U25: =IF(D25=0,0,SUM($L$21:L25)) -> 0 | V25: =IF(D25=0,0,SUM($J$21:J25)) -> 0 | W25: =IF(D25=0,0,V25-U25) -> 0 | X25: =IF(D25=0,0,V25/U25) -> 0 | Y25: =Y24+1 -> 45662 | Z25: =Z24+1 -> 45662 | AA25: 1 | AB25: fri | AC25: =IFERROR(AVERAGEIFS(J21:J51,D21:D51,1,G21:G51,"fri"),0) -> 330490 | AD25: =COUNTIFS(D21:D51,1,G21:G51,"fri") -> 4 | AE25: =($I$7*実績_2024R6!AI24)/AD25 -> 343102.15 | AF25: =AD25*AE25 -> 1372408.6
C26: 6 | D26: 1 | E26: =MONTH(Y26) -> 1 | F26: =F25+1 -> 45663 | G26: =TEXT(Z26,"ddd") -> Mon | J26: 349800 | L26: =IF(D26=0,0,IFERROR(SUMIFS($AE$21:$AE$104,$AA$21:$AA$104,$E26,$AB$21:$AB$104,$G26),0)) -> 395153.16 | M26: =IF(D26=0,0,J26-L26) -> -45353.162 | N26: =IFERROR(J26/L26,"¥0") -> 0.88522637 | P26: =IF(D26=0,0,SUM($L$21:L26)) -> 395153.16 | Q26: =IF(D26=0,0,SUM($J$21:J26)) -> 349800 | R26: =IF(D26=0,0,Q26-P26) -> -45353.162 | S26: =IF(D26=0,0,Q26/P26) -> 0.88522637 | U26: =IF(D26=0,0,SUM($L$21:L26)) -> 395153.16 | V26: =IF(D26=0,0,SUM($J$21:J26)) -> 349800 | W26: =IF(D26=0,0,V26-U26) -> -45353.162 | X26: =IF(D26=0,0,V26/U26) -> 0.88522637 | Y26: =Y25+1 -> 45663 | Z26: =Z25+1 -> 45663 | AA26: 1 | AB26: sat | AC26: =IFERROR(AVERAGEIFS(J21:J51,D21:D51,1,G21:G51,"sat"),0) -> 108790 | AD26: =COUNTIFS(D21:D51,1,G21:G51,"sat") -> 3 | AE26: =($I$7*実績_2024R6!AI25)/AD26 -> 118612.32 | AF26: =AD26*AE26 -> 355836.96 | AG26: 1月目標売り上げ
C27: 7 | D27: 1 | E27: =MONTH(Y27) -> 1 | F27: =F26+1 -> 45664 | G27: =TEXT(Z27,"ddd") -> Tue | J27: 88530 | L27: =IF(D27=0,0,IFERROR(SUMIFS($AE$21:$AE$104,$AA$21:$AA$104,$E27,$AB$21:$AB$104,$G27),0)) -> 251136.8 | M27: =IF(D27=0,0,J27-L27) -> -162606.8 | N27: =IFERROR(J27/L27,"¥0") -> 0.35251704 | P27: =IF(D27=0,0,SUM($L$21:L27)) -> 646289.96 | Q27: =IF(D27=0,0,SUM($J$21:J27)) -> 438330 | R27: =IF(D27=0,0,Q27-P27) -> -207959.96 | S27: =IF(D27=0,0,Q27/P27) -> 0.67822499 | U27: =IF(D27=0,0,SUM($L$21:L27)) -> 646289.96 | V27: =IF(D27=0,0,SUM($J$21:J27)) -> 438330 | W27: =IF(D27=0,0,V27-U27) -> -207959.96 | X27: =IF(D27=0,0,V27/U27) -> 0.67822499 | Y27: =Y26+1 -> 45664 | Z27: =Z26+1 -> 45664 | AA27: 1 | AB27: sun | AC27: =IFERROR(AVERAGEIFS(J21:J51,D21:D51,1,G21:G51,"sun"),0) -> 0 | AD27: =IFERROR(COUNTIFS(D21:D51,1,G21:G51,"sun"),0) -> 0 | AE27: =IFERROR(($I$7*実績_2024R6!AI26)/AD27,0) -> 0 | AF27: =SUM(AF21:AF26) -> 5835789.5 | AG27: =I7 -> 5835789.5
C28: 8 | D28: 1 | E28: =MONTH(Y28) -> 1 | F28: =F27+1 -> 45665 | G28: =TEXT(Z28,"ddd") -> Wed | J28: 177630 | L28: =IF(D28=0,0,IFERROR(SUMIFS($AE$21:$AE$104,$AA$21:$AA$104,$E28,$AB$21:$AB$104,$G28),0)) -> 282865.79 | M28: =IF(D28=0,0,J28-L28) -> -105235.79 | N28: =IFERROR(J28/L28,"¥0") -> 0.62796565 | P28: =IF(D28=0,0,SUM($L$21:L28)) -> 929155.75 | Q28: =IF(D28=0,0,SUM($J$21:J28)) -> 615960 | R28: =IF(D28=0,0,Q28-P28) -> -313195.75 | S28: =IF(D28=0,0,Q28/P28) -> 0.66292438 | U28: =IF(D28=0,0,SUM($L$21:L28)) -> 929155.75 | V28: =IF(D28=0,0,SUM($J$21:J28)) -> 615960 | W28: =IF(D28=0,0,V28-U28) -> -313195.75 | X28: =IF(D28=0,0,V28/U28) -> 0.66292438 | Y28: =Y27+1 -> 45665 | Z28: =Z27+1 -> 45665 | AA28: 2 | AB28: Mon | AC28: =IFERROR(AVERAGEIFS(J52:J79,D52:D79,1,G52:G79,"mon"),0) -> 136670 | AD28: =COUNTIFS(D52:D79,1,G52:G79,"Mon") -> 3 | AE28: =($I$8*実績_2024R6!AI27)/AD28 -> 224838.76 | AF28: =AD28*AE28 -> 674516.28 | AG28: 52〜79
C29: 9 | D29: 1 | E29: =MONTH(Y29) -> 1 | F29: =F28+1 -> 45666 | G29: =TEXT(Z29,"ddd") -> Thu | J29: 376670 | L29: =IF(D29=0,0,IFERROR(SUMIFS($AE$21:$AE$104,$AA$21:$AA$104,$E29,$AB$21:$AB$104,$G29),0)) -> 196518.52 | M29: =IF(D29=0,0,J29-L29) -> 180151.48 | N29: =IFERROR(J29/L29,"¥0") -> 1.916715 | P29: =IF(D29=0,0,SUM($L$21:L29)) -> 1125674.3 | Q29: =IF(D29=0,0,SUM($J$21:J29)) -> 992630 | R29: =IF(D29=0,0,Q29-P29) -> -133044.27 | S29: =IF(D29=0,0,Q29/P29) -> 0.88180926 | U29: =IF(D29=0,0,SUM($L$21:L29)) -> 1125674.3 | V29: =IF(D29=0,0,SUM($J$21:J29)) -> 992630 | W29: =IF(D29=0,0,V29-U29) -> -133044.27 | X29: =IF(D29=0,0,V29/U29) -> 0.88180926 | Y29: =Y28+1 -> 45666 | Z29: =Z28+1 -> 45666 | AA29: 2 | AB29: Tue | AC29: =IFERROR(AVERAGEIFS(J53:J80,D53:D80,1,G53:G80,"tue"),0) -> 198143.33 | AD29: =COUNTIFS(D52:D79,1,G52:G79,"tue") -> 3 | AE29: =($I$8*実績_2024R6!AI28)/AD29 -> 277740.28 | AF29: =AD29*AE29 -> 833220.85
C30: 10 | D30: 1 | E30: =MONTH(Y30) -> 1 | F30: =F29+1 -> 45667 | G30: =TEXT(Z30,"ddd") -> Fri | J30: 377100 | L30: =IF(D30=0,0,IFERROR(SUMIFS($AE$21:$AE$104,$AA$21:$AA$104,$E30,$AB$21:$AB$104,$G30),0)) -> 343102.15 | M30: =IF(D30=0,0,J30-L30) -> 33997.852 | N30: =IFERROR(J30/L30,"¥0") -> 1.0990896 | P30: =IF(D30=0,0,SUM($L$21:L30)) -> 1468776.4 | Q30: =IF(D30=0,0,SUM($J$21:J30)) -> 1369730 | R30: =IF(D30=0,0,Q30-P30) -> -99046.418 | S30: =IF(D30=0,0,Q30/P30) -> 0.93256535 | U30: =IF(D30=0,0,SUM($L$21:L30)) -> 1468776.4 | V30: =IF(D30=0,0,SUM($J$21:J30)) -> 1369730 | W30: =IF(D30=0,0,V30-U30) -> -99046.418 | X30: =IF(D30=0,0,V30/U30) -> 0.93256535 | Y30: =Y29+1 -> 45667 | Z30: =Z29+1 -> 45667 | AA30: 2 | AB30: Wed | AC30: =IFERROR(AVERAGEIFS(J52:J79,D52:D79,1,G52:G79,"wed"),0) -> 268685 | AD30: =COUNTIFS(D52:D79,1,G52:G79,"wed") -> 4 | AE30: =($I$8*実績_2024R6!AI29)/AD30 -> 215570.54 | AF30: =AD30*AE30 -> 862282.17
C31: 11 | D31: 1 | E31: =MONTH(Y31) -> 1 | F31: =F30+1 -> 45668 | G31: =TEXT(Z31,"ddd") -> Sat | J31: 66550 | L31: =IF(D31=0,0,IFERROR(SUMIFS($AE$21:$AE$104,$AA$21:$AA$104,$E31,$AB$21:$AB$104,$G31),0)) -> 118612.32 | M31: =IF(D31=0,0,J31-L31) -> -52062.322 | N31: =IFERROR(J31/L31,"¥0") -> 0.56107156 | P31: =IF(D31=0,0,SUM($L$21:L31)) -> 1587388.7 | Q31: =IF(D31=0,0,SUM($J$21:J31)) -> 1436280 | R31: =IF(D31=0,0,Q31-P31) -> -151108.74 | S31: =IF(D31=0,0,Q31/P31) -> 0.90480672 | U31: =IF(D31=0,0,SUM($L$21:L31)) -> 1587388.7 | V31: =IF(D31=0,0,SUM($J$21:J31)) -> 1436280 | W31: =IF(D31=0,0,V31-U31) -> -151108.74 | X31: =IF(D31=0,0,V31/U31) -> 0.90480672 | Y31: =Y30+1 -> 45668 | Z31: =Z30+1 -> 45668 | AA31: 2 | AB31: Thu | AC31: =IFERROR(AVERAGEIFS(J52:J79,D52:D79,1,G52:G79,"thu"),0) -> 369147.5 | AD31: =COUNTIFS(D52:D79,1,G52:G79,"thu") -> 4 | AE31: =($I$8*実績_2024R6!AI30)/AD31 -> 283656.58 | AF31: =AD31*AE31 -> 1134626.3
C32: 12 | D32: 0 | E32: =MONTH(Y32) -> 1 | F32: =F31+1 -> 45669 | G32: =TEXT(Z32,"ddd") -> Sun | H32: 日曜日 | L32: =IF(D32=0,0,IFERROR(SUMIFS($AE$21:$AE$104,$AA$21:$AA$104,$E32,$AB$21:$AB$104,$G32),0)) -> 0 | M32: =IF(D32=0,0,J32-L32) -> 0 | N32: =IFERROR(J32/L32,"¥0") -> ¥0 | P32: =IF(D32=0,0,SUM($L$21:L32)) -> 0 | Q32: =IF(D32=0,0,SUM($J$21:J32)) -> 0 | R32: =IF(D32=0,0,Q32-P32) -> 0 | S32: =IF(D32=0,0,Q32/P32) -> 0 | U32: =IF(D32=0,0,SUM($L$21:L32)) -> 0 | V32: =IF(D32=0,0,SUM($J$21:J32)) -> 0 | W32: =IF(D32=0,0,V32-U32) -> 0 | X32: =IF(D32=0,0,V32/U32) -> 0 | Y32: =Y31+1 -> 45669 | Z32: =Z31+1 -> 45669 | AA32: 2 | AB32: Fri | AC32: =IFERROR(AVERAGEIFS(J52:J79,D52:D79,1,G52:G79,"fri"),0) -> 310005 | AD32: =COUNTIFS(D52:D79,1,G52:G79,"fri") -> 4 | AE32: =($I$8*実績_2024R6!AI31)/AD32 -> 207016.95 | AF32: =AD32*AE32 -> 828067.79
C33: 13 | D33: 0 | E33: =MONTH(Y33) -> 1 | F33: =F32+1 -> 45670 | G33: =TEXT(Z33,"ddd") -> Mon | H33: 成人の日 | L33: =IF(D33=0,0,IFERROR(SUMIFS($AE$21:$AE$104,$AA$21:$AA$104,$E33,$AB$21:$AB$104,$G33),0)) -> 0 | M33: =IF(D33=0,0,J33-L33) -> 0 | N33: =IFERROR(J33/L33,"¥0") -> ¥0 | P33: =IF(D33=0,0,SUM($L$21:L33)) -> 0 | Q33: =IF(D33=0,0,SUM($J$21:J33)) -> 0 | R33: =IF(D33=0,0,Q33-P33) -> 0 | S33: =IF(D33=0,0,Q33/P33) -> 0 | U33: =IF(D33=0,0,SUM($L$21:L33)) -> 0 | V33: =IF(D33=0,0,SUM($J$21:J33)) -> 0 | W33: =IF(D33=0,0,V33-U33) -> 0 | X33: =IF(D33=0,0,V33/U33) -> 0 | Y33: =Y32+1 -> 45670 | Z33: =Z32+1 -> 45670 | AA33: 2 | AB33: Sat | AC33: =IFERROR(AVERAGEIFS(J52:J79,D52:D79,1,G52:G79,"sat"),0) -> 143220 | AD33: =COUNTIFS(D52:D79,1,G52:G79,"sat") -> 4 | AE33: =($I$8*実績_2024R6!AI32)/AD33 -> 132611.12 | AF33: =AD33*AE33 -> 530444.47 | AG33: 2月目標売り上げ
C34: 14 | D34: 1 | E34: =MONTH(Y34) -> 1 | F34: =F33+1 -> 45671 | G34: =TEXT(Z34,"ddd") -> Tue | J34: 372310 | L34: =IF(D34=0,0,IFERROR(SUMIFS($AE$21:$AE$104,$AA$21:$AA$104,$E34,$AB$21:$AB$104,$G34),0)) -> 251136.8 | M34: =IF(D34=0,0,J34-L34) -> 121173.2 | N34: =IFERROR(J34/L34,"¥0") -> 1.4824988 | P34: =IF(D34=0,0,SUM($L$21:L34)) -> 1838525.5 | Q34: =IF(D34=0,0,SUM($J$21:J34)) -> 1808590 | R34: =IF(D34=0,0,Q34-P34) -> -29935.538 | S34: =IF(D34=0,0,Q34/P34) -> 0.98371764 | U34: =IF(D34=0,0,SUM($L$21:L34)) -> 1838525.5 | V34: =IF(D34=0,0,SUM($J$21:J34)) -> 1808590 | W34: =IF(D34=0,0,V34-U34) -> -29935.538 | X34: =IF(D34=0,0,V34/U34) -> 0.98371764 | Y34: =Y33+1 -> 45671 | Z34: =Z33+1 -> 45671 | AA34: 2 | AB34: Sun | AC34: =IFERROR(AVERAGEIFS(J52:J79,D52:D79,1,G52:G79,"sun"),0) -> 0 | AD34: =IFERROR(COUNTIFS(D52:D79,1,G52:G79,"sun"),0) -> 0 | AE34: =IFERROR(($I$8*実績_2024R6!AI33)/AD34,0) -> 0 | AF34: =SUM(AF28:AF33) -> 4863157.9 | AG34: =I8 -> 4863157.9
C35: 15 | D35: 1 | E35: =MONTH(Y35) -> 1 | F35: =F34+1 -> 45672 | G35: =TEXT(Z35,"ddd") -> Wed | J35: 246200 | L35: =IF(D35=0,0,IFERROR(SUMIFS($AE$21:$AE$104,$AA$21:$AA$104,$E35,$AB$21:$AB$104,$G35),0)) -> 282865.79 | M35: =IF(D35=0,0,J35-L35) -> -36665.79 | N35: =IFERROR(J35/L35,"¥0") -> 0.87037743 | P35: =IF(D35=0,0,SUM($L$21:L35)) -> 2121391.3 | Q35: =IF(D35=0,0,SUM($J$21:J35)) -> 2054790 | R35: =IF(D35=0,0,Q35-P35) -> -66601.328 | S35: =IF(D35=0,0,Q35/P35) -> 0.96860488 | U35: =IF(D35=0,0,SUM($L$21:L35)) -> 2121391.3 | V35: =IF(D35=0,0,SUM($J$21:J35)) -> 2054790 | W35: =IF(D35=0,0,V35-U35) -> -66601.328 | X35: =IF(D35=0,0,V35/U35) -> 0.96860488 | Y35: =Y34+1 -> 45672 | Z35: =Z34+1 -> 45672 | AA35: 3 | AB35: Mon | AC35: =IFERROR(AVERAGEIFS(J80:J110,D80:D110,1,G80:G110,"mon"),0) -> 199934 | AD35: =COUNTIFS(D80:D110,1,G80:G110,"Mon") -> 5 | AE35: =($I$9*実績_2024R6!AI34)/AD35 -> 203685.45 | AF35: =AD35*AE35 -> 1018427.2 | AG35: 80〜110
C36: 16 | D36: 1 | E36: =MONTH(Y36) -> 1 | F36: =F35+1 -> 45673 | G36: =TEXT(Z36,"ddd") -> Thu | J36: 400950 | L36: =IF(D36=0,0,IFERROR(SUMIFS($AE$21:$AE$104,$AA$21:$AA$104,$E36,$AB$21:$AB$104,$G36),0)) -> 196518.52 | M36: =IF(D36=0,0,J36-L36) -> 204431.48 | N36: =IFERROR(J36/L36,"¥0") -> 2.0402657 | P36: =IF(D36=0,0,SUM($L$21:L36)) -> 2317909.8 | Q36: =IF(D36=0,0,SUM($J$21:J36)) -> 2455740 | R36: =IF(D36=0,0,Q36-P36) -> 137830.15 | S36: =IF(D36=0,0,Q36/P36) -> 1.0594631 | U36: =IF(D36=0,0,SUM($L$21:L36)) -> 2317909.8 | V36: =IF(D36=0,0,SUM($J$21:J36)) -> 2455740 | W36: =IF(D36=0,0,V36-U36) -> 137830.15 | X36: =IF(D36=0,0,V36/U36) -> 1.0594631 | Y36: =Y35+1 -> 45673 | Z36: =Z35+1 -> 45673 | AA36: 3 | AB36: Tue | AC36: =IFERROR(AVERAGEIFS(J80:J110,D80:D110,1,G80:G110,"tue"),0) -> 314582.5 | AD36: =COUNTIFS(D80:D110,1,G80:G110,"tue") -> 4 | AE36: =($I$9*実績_2024R6!AI35)/AD36 -> 293532.45 | AF36: =AD36*AE36 -> 1174129.8
C37: 17 | D37: 1 | E37: =MONTH(Y37) -> 1 | F37: =F36+1 -> 45674 | G37: =TEXT(Z37,"ddd") -> Fri | J37: 262380 | L37: =IF(D37=0,0,IFERROR(SUMIFS($AE$21:$AE$104,$AA$21:$AA$104,$E37,$AB$21:$AB$104,$G37),0)) -> 343102.15 | M37: =IF(D37=0,0,J37-L37) -> -80722.148 | N37: =IFERROR(J37/L37,"¥0") -> 0.76472853 | P37: =IF(D37=0,0,SUM($L$21:L37)) -> 2661012 | Q37: =IF(D37=0,0,SUM($J$21:J37)) -> 2718120 | R37: =IF(D37=0,0,Q37-P37) -> 57108.005 | S37: =IF(D37=0,0,Q37/P37) -> 1.021461 | U37: =IF(D37=0,0,SUM($L$21:L37)) -> 2661012 | V37: =IF(D37=0,0,SUM($J$21:J37)) -> 2718120 | W37: =IF(D37=0,0,V37-U37) -> 57108.005 | X37: =IF(D37=0,0,V37/U37) -> 1.021461 | Y37: =Y36+1 -> 45674 | Z37: =Z36+1 -> 45674 | AA37: 3 | AB37: Wed | AC37: =IFERROR(AVERAGEIFS(J80:J110,D80:D110,1,G80:G110,"wed"),0) -> 355035 | AD37: =COUNTIFS(D80:D110,1,G80:G110,"wed") -> 4 | AE37: =($I$9*実績_2024R6!AI36)/AD37 -> 245154.79 | AF37: =AD37*AE37 -> 980619.17
C38: 18 | D38: 1 | E38: =MONTH(Y38) -> 1 | F38: =F37+1 -> 45675 | G38: =TEXT(Z38,"ddd") -> Sat | J38: 137800 | L38: =IF(D38=0,0,IFERROR(SUMIFS($AE$21:$AE$104,$AA$21:$AA$104,$E38,$AB$21:$AB$104,$G38),0)) -> 118612.32 | M38: =IF(D38=0,0,J38-L38) -> 19187.678 | N38: =IFERROR(J38/L38,"¥0") -> 1.161768 | P38: =IF(D38=0,0,SUM($L$21:L38)) -> 2779624.3 | Q38: =IF(D38=0,0,SUM($J$21:J38)) -> 2855920 | R38: =IF(D38=0,0,Q38-P38) -> 76295.684 | S38: =IF(D38=0,0,Q38/P38) -> 1.0274482 | U38: =IF(D38=0,0,SUM($L$21:L38)) -> 2779624.3 | V38: =IF(D38=0,0,SUM($J$21:J38)) -> 2855920 | W38: =IF(D38=0,0,V38-U38) -> 76295.684 | X38: =IF(D38=0,0,V38/U38) -> 1.0274482 | Y38: =Y37+1 -> 45675 | Z38: =Z37+1 -> 45675 | AA38: 3 | AB38: Thu | AC38: =IFERROR(AVERAGEIFS(J80:J110,D80:D110,1,G80:G110,"thu"),0) -> 355676.67 | AD38: =COUNTIFS(D80:D110,1,G80:G110,"thu") -> 3 | AE38: =($I$9*実績_2024R6!AI37)/AD38 -> 457562.97 | AF38: =AD38*AE38 -> 1372688.9
C39: 19 | D39: 0 | E39: =MONTH(Y39) -> 1 | F39: =F38+1 -> 45676 | G39: =TEXT(Z39,"ddd") -> Sun | L39: =IF(D39=0,0,IFERROR(SUMIFS($AE$21:$AE$104,$AA$21:$AA$104,$E39,$AB$21:$AB$104,$G39),0)) -> 0 | M39: =IF(D39=0,0,J39-L39) -> 0 | N39: =IFERROR(J39/L39,"¥0") -> ¥0 | P39: =IF(D39=0,0,SUM($L$21:L39)) -> 0 | Q39: =IF(D39=0,0,SUM($J$21:J39)) -> 0 | R39: =IF(D39=0,0,Q39-P39) -> 0 | S39: =IF(D39=0,0,Q39/P39) -> 0 | U39: =IF(D39=0,0,SUM($L$21:L39)) -> 0 | V39: =IF(D39=0,0,SUM($J$21:J39)) -> 0 | W39: =IF(D39=0,0,V39-U39) -> 0 | X39: =IF(D39=0,0,V39/U39) -> 0 | Y39: =Y38+1 -> 45676 | Z39: =Z38+1 -> 45676 | AA39: 3 | AB39: Fri | AC39: =IFERROR(AVERAGEIFS(J80:J110,D80:D110,1,G80:G110,"fri"),0) -> 406890 | AD39: =COUNTIFS(D80:D110,1,G80:G110,"fri") -> 4 | AE39: =($I$9*実績_2024R6!AI38)/AD39 -> 448451.04 | AF39: =AD39*AE39 -> 1793804.2
C40: 20 | D40: 1 | E40: =MONTH(Y40) -> 1 | F40: =F39+1 -> 45677 | G40: =TEXT(Z40,"ddd") -> Mon | J40: 265910 | L40: =IF(D40=0,0,IFERROR(SUMIFS($AE$21:$AE$104,$AA$21:$AA$104,$E40,$AB$21:$AB$104,$G40),0)) -> 395153.16 | M40: =IF(D40=0,0,J40-L40) -> -129243.16 | N40: =IFERROR(J40/L40,"¥0") -> 0.67292894 | P40: =IF(D40=0,0,SUM($L$21:L40)) -> 3174777.5 | Q40: =IF(D40=0,0,SUM($J$21:J40)) -> 3121830 | R40: =IF(D40=0,0,Q40-P40) -> -52947.479 | S40: =IF(D40=0,0,Q40/P40) -> 0.98332246 | U40: =IF(D40=0,0,SUM($L$21:L40)) -> 3174777.5 | V40: =IF(D40=0,0,SUM($J$21:J40)) -> 3121830 | W40: =IF(D40=0,0,V40-U40) -> -52947.479 | X40: =IF(D40=0,0,V40/U40) -> 0.98332246 | Y40: =Y39+1 -> 45677 | Z40: =Z39+1 -> 45677 | AA40: 3 | AB40: Sat | AC40: =IFERROR(AVERAGEIFS(J80:J110,D80:D110,1,G80:G110,"sat"),0) -> 163312 | AD40: =COUNTIFS(D80:D110,1,G80:G110,"sat") -> 5 | AE40: =($I$9*実績_2024R6!AI39)/AD40 -> 168908.25 | AF40: =AD40*AE40 -> 844541.23 | AG40: 3月目標売り上げ
C41: 21 | D41: 1 | E41: =MONTH(Y41) -> 1 | F41: =F40+1 -> 45678 | G41: =TEXT(Z41,"ddd") -> Tue | J41: 175950 | L41: =IF(D41=0,0,IFERROR(SUMIFS($AE$21:$AE$104,$AA$21:$AA$104,$E41,$AB$21:$AB$104,$G41),0)) -> 251136.8 | M41: =IF(D41=0,0,J41-L41) -> -75186.799 | N41: =IFERROR(J41/L41,"¥0") -> 0.70061417 | P41: =IF(D41=0,0,SUM($L$21:L41)) -> 3425914.3 | Q41: =IF(D41=0,0,SUM($J$21:J41)) -> 3297780 | R41: =IF(D41=0,0,Q41-P41) -> -128134.28 | S41: =IF(D41=0,0,Q41/P41) -> 0.96259852 | U41: =IF(D41=0,0,SUM($L$21:L41)) -> 3425914.3 | V41: =IF(D41=0,0,SUM($J$21:J41)) -> 3297780 | W41: =IF(D41=0,0,V41-U41) -> -128134.28 | X41: =IF(D41=0,0,V41/U41) -> 0.96259852 | Y41: =Y40+1 -> 45678 | Z41: =Z40+1 -> 45678 | AA41: 3 | AB41: Sun | AC41: =IFERROR(AVERAGEIFS(J80:J110,D80:D110,1,G80:G110,"sun"),0) -> 0 | AD41: =IFERROR(COUNTIFS(D80:D110,1,G80:G110,"sun"),0) -> 0 | AE41: =IFERROR(($I$9*実績_2024R6!AI40)/AD41,0) -> 0 | AF41: =SUM(AF35:AF40) -> 7184210.5 | AG41: =I9 -> 7184210.5
C42: 22 | D42: 1 | E42: =MONTH(Y42) -> 1 | F42: =F41+1 -> 45679 | G42: =TEXT(Z42,"ddd") -> Wed | J42: 262170 | L42: =IF(D42=0,0,IFERROR(SUMIFS($AE$21:$AE$104,$AA$21:$AA$104,$E42,$AB$21:$AB$104,$G42),0)) -> 282865.79 | M42: =IF(D42=0,0,J42-L42) -> -20695.79 | N42: =IFERROR(J42/L42,"¥0") -> 0.9268353 | P42: =IF(D42=0,0,SUM($L$21:L42)) -> 3708780.1 | Q42: =IF(D42=0,0,SUM($J$21:J42)) -> 3559950 | R42: =IF(D42=0,0,Q42-P42) -> -148830.07 | S42: =IF(D42=0,0,Q42/P42) -> 0.95987088 | U42: =IF(D42=0,0,SUM($L$21:L42)) -> 3708780.1 | V42: =IF(D42=0,0,SUM($J$21:J42)) -> 3559950 | W42: =IF(D42=0,0,V42-U42) -> -148830.07 | X42: =IF(D42=0,0,V42/U42) -> 0.95987088 | Y42: =Y41+1 -> 45679 | Z42: =Z41+1 -> 45679 | AA42: 4 | AB42: Mon | AC42: =IFERROR(AVERAGEIFS(J111:J140,D111:D140,1,G111:G140,"mon"),0) -> 244835 | AD42: =COUNTIFS(D111:D140,1,G111:G140,"Mon") -> 4 | AE42: =($I$10*実績_2024R6!AI41)/AD42 -> 245725.1 | AF42: =AD42*AE42 -> 982900.42 | AG42: 111〜140
C43: 23 | D43: 1 | E43: =MONTH(Y43) -> 1 | F43: =F42+1 -> 45680 | G43: =TEXT(Z43,"ddd") -> Thu | J43: 342980 | L43: =IF(D43=0,0,IFERROR(SUMIFS($AE$21:$AE$104,$AA$21:$AA$104,$E43,$AB$21:$AB$104,$G43),0)) -> 196518.52 | M43: =IF(D43=0,0,J43-L43) -> 146461.48 | N43: =IFERROR(J43/L43,"¥0") -> 1.7452808 | P43: =IF(D43=0,0,SUM($L$21:L43)) -> 3905298.6 | Q43: =IF(D43=0,0,SUM($J$21:J43)) -> 3902930 | R43: =IF(D43=0,0,Q43-P43) -> -2368.5864 | S43: =IF(D43=0,0,Q43/P43) -> 0.99939349 | U43: =IF(D43=0,0,SUM($L$21:L43)) -> 3905298.6 | V43: =IF(D43=0,0,SUM($J$21:J43)) -> 3902930 | W43: =IF(D43=0,0,V43-U43) -> -2368.5864 | X43: =IF(D43=0,0,V43/U43) -> 0.99939349 | Y43: =Y42+1 -> 45680 | Z43: =Z42+1 -> 45680 | AA43: 4 | AB43: Tue | AC43: =IFERROR(AVERAGEIFS(J111:J140,D111:D140,1,G111:G140,"tue"),0) -> 270190 | AD43: =COUNTIFS(D111:D140,1,G111:G140,"tue") -> 4 | AE43: =($I$10*実績_2024R6!AI42)/AD43 -> 362897.4 | AF43: =AD43*AE43 -> 1451589.6
...

Sheet 目標_2025R7 (2)
B2: 45658 | E2: ①年間営業日 | G2: ②年間目標売上 | H2: 年間総売上％ | K2: 年間売上合計 | M2: 実質売上 | P2: 1月 | Q2: 2月 | R2: 3月 | S2: 4月 | T2: ←目標の月へジャンプ
E3: =SUM(F7:F18) -> 286 | G3: 80000000 | H3: =SUM(AD7:AD18)*100 -> 0.999996 | I3: =G3*H3 -> 79999680 | K3: =SUM(J21:J385) -> 31748860 | M3: =K3-G3 -> -48251140 | P3: 5月 | Q3: 6月 | R3: 7月 | S3: 8月
P4: 9月 | Q4: 10月 | R4: 11月 | S4: 12月
B6: 平均日次売上目標額 | E6: 月 | F6: 月次営業日数 | G6: 平均月間売上目標額 | H6: 月次繁閑期%設定 | I6: 月次目標売上 | K6: 日次目標売上 | M6: 月次売上実績 | N6: 月間KGI | P6: 月次平均%(繁閑期) | Q6: 月次実質%
B7: ② ÷ ① | E7: 1月 | F7: =COUNTIF(D21:D51,1) -> 22 | G7: =$B$8*F7 -> 6153846.2 | H7: 0.95 | I7: =G7*H7 -> 5846153.8 | K7: =I7/F7 -> 265734.27 | M7: =SUM(J21:J51) -> 6005630 | N7: =M7-I7 -> 159476.15 | P7: =M7/G7 -> 0.97591487 | Q7: =M7/I7 -> 1.0272788 | AA7: =TEXT(K7,"¥0") -> ¥265734 | AD7: =(H7/100)*AE7 -> 0.0007916635 | AE7: 0.083333
B8: =G3/E3 -> 279720.28 | E8: 2月 | F8: =COUNTIF(D52:D79,1) -> 22 | G8: =$B$8*F8 -> 6153846.2 | H8: 0.85 | I8: =G8*H8 -> 5230769.2 | K8: =I8/F8 -> 237762.24 | M8: =SUM(J52:J79) -> 5377670 | N8: =M8-I8 -> 146900.77 | P8: =M8/G8 -> 0.87387138 | Q8: =M8/I8 -> 1.028084 | AA8: =TEXT(K8,"¥0") -> ¥237762 | AD8: =(H8/100)*AE8 -> 0.0007083305 | AE8: 0.083333
E9: 3月 | F9: =COUNTIF(D80:D110,1) -> 25 | G9: =$B$8*F9 -> 6993007 | H9: 1.1 | I9: =G9*H9 -> 7692307.7 | K9: =I9/F9 -> 307692.31 | M9: =SUM(J80:J110) -> 7195290 | N9: =M9-I9 -> -497017.69 | P9: =M9/G9 -> 1.0289265 | Q9: =M9/I9 -> 0.9353877 | AA9: =TEXT(K9,"¥0") -> ¥307692 | AD9: =(H9/100)*AE9 -> 0.000916663 | AE9: 0.083333
E10: 4月 | F10: =COUNTIF(D111:D140,1) -> 25 | G10: =$B$8*F10 -> 6993007 | H10: 1.1 | I10: =G10*H10 -> 7692307.7 | K10: =I10/F10 -> 307692.31 | M10: =SUM(J111:J140) -> 7238940 | N10: =M10-I10 -> -453367.69 | P10: =M10/G10 -> 1.0351684 | Q10: =M10/I10 -> 0.9410622 | AA10: =TEXT(K10,"¥0") -> ¥307692 | AD10: =(H10/100)*AE10 -> 0.000916663 | AE10: 0.083333
E11: 5月 | F11: =COUNTIF(D141:D171,1) -> 24 | G11: =$B$8*F11 -> 6713286.7 | H11: 0.85 | I11: =G11*H11 -> 5706293.7 | K11: =I11/F11 -> 237762.24 | M11: =SUM(J141:J171) -> 5931330 | N11: =M11-I11 -> 225036.29 | P11: =M11/G11 -> 0.88352103 | Q11: =M11/I11 -> 1.0394365 | AA11: =TEXT(K11,"¥0") -> ¥237762 | AD11: =(H11/100)*AE11 -> 0.0007083305 | AE11: 0.083333
E12: 6月 | F12: =COUNTIF(D172:D201,1) -> 25 | G12: =$B$8*F12 -> 6993007 | H12: 0.8 | I12: =G12*H12 -> 5594405.6 | K12: =I12/F12 -> 223776.22 | M12: =SUM(J172:J201) -> 0 | N12: =M12-I12 -> -5594405.6 | P12: =M12/G12 -> 0 | Q12: =M12/I12 -> 0 | AA12: =TEXT(K12,"¥0") -> ¥223776 | AD12: =(H12/100)*AE12 -> 0.000666664 | AE12: 0.083333
E13: 7月 | F13: =COUNTIF(D202:D232,1) -> 26 | G13: =$B$8*F13 -> 7272727.3 | H13: 0.9 | I13: =G13*H13 -> 6545454.5 | K13: =I13/F13 -> 251748.25 | M13: =SUM(J202:J232) -> 0 | N13: =M13-I13 -> -6545454.5 | P13: =M13/G13 -> 0 | Q13: =M13/I13 -> 0 | AA13: =TEXT(K13,"¥0") -> ¥251748 | AD13: =(H13/100)*AE13 -> 0.000749997 | AE13: 0.083333
E14: 8月 | F14: =COUNTIF(D233:D263,1) -> 20 | G14: =$B$8*F14 -> 5594405.6 | H14: 1 | I14: =G14*H14 -> 5594405.6 | K14: =I14/F14 -> 279720.28 | M14: =SUM(J233:J263) -> 0 | N14: =M14-I14 -> -5594405.6 | P14: =M14/G14 -> 0 | Q14: =M14/I14 -> 0 | AA14: =TEXT(K14,"¥0") -> ¥279720 | AD14: =(H14/100)*AE14 -> 0.00083333 | AE14: 0.083333
E15: 9 月 | F15: =COUNTIF(D264:D293,1) -> 24 | G15: =$B$8*F15 -> 6713286.7 | H15: 1 | I15: =G15*H15 -> 6713286.7 | K15: =I15/F15 -> 279720.28 | M15: =SUM(J264:J293) -> 0 | N15: =M15-I15 -> -6713286.7 | P15: =M15/G15 -> 0 | Q15: =M15/I15 -> 0 | AA15: =TEXT(K15,"¥0") -> ¥279720 | AD15: =(H15/100)*AE15 -> 0.00083333 | AE15: 0.083333
E16: 10月 | F16: =COUNTIF(D294:D324,1) -> 26 | G16: =$B$8*F16 -> 7272727.3 | H16: 1.05 | I16: =G16*H16 -> 7636363.6 | K16: =I16/F16 -> 293706.29 | M16: =SUM(J294:J324) -> 0 | N16: =M16-I16 -> -7636363.6 | P16: =M16/G16 -> 0 | Q16: =M16/I16 -> 0 | AA16: =TEXT(K16,"¥0") -> ¥293706 | AD16: =(H16/100)*AE16 -> 0.0008749965 | AE16: 0.083333
E17: 11月 | F17: =COUNTIF(D325:D354,1) -> 23 | G17: =$B$8*F17 -> 6433566.4 | H17: 1.2 | I17: =G17*H17 -> 7720279.7 | K17: =I17/F17 -> 335664.34 | M17: =SUM(J325:J354) -> 0 | N17: =M17-I17 -> -7720279.7 | P17: =M17/G17 -> 0 | Q17: =M17/I17 -> 0 | AA17: =TEXT(K17,"¥0") -> ¥335664 | AD17: =(H17/100)*AE17 -> 0.000999996 | AE17: 0.083333
E18: 12月 | F18: =COUNTIF(D355:D385,1) -> 24 | G18: =$B$8*F18 -> 6713286.7 | H18: 1.2 | I18: =G18*H18 -> 8055944.1 | K18: =I18/F18 -> 335664.34 | M18: =SUM(J355:J385) -> 0 | N18: =M18-I18 -> -8055944.1 | P18: =M18/G18 -> 0 | Q18: =M18/I18 -> 0 | AA18: =TEXT(K18,"¥0") -> ¥335664 | AD18: =(H18/100)*AE18 -> 0.000999996 | AE18: 0.083333
E20: 月 | F20: 日程 | G20: 曜日 | H20: 日祝日 | J20: Daily売上入力 | L20: 目標売上 | M20: 実質売上 | N20: 実質% | P20: 月次目標売上 | Q20: 月次実質売上 | R20: 月次差額 | S20: 月次達成率 | U20: 年次目標売上 | V20: 年次実質売上 | W20: 年次差額 | X20: 年次達成率
C21: 1 | D21: 0 | E21: =MONTH(Y21) -> 1 | F21: =B2 -> 45658 | G21: =TEXT(Z21,"ddd") -> Wed | H21: 元旦 | L21: =IF(D21=0,0,$K$7) -> 0 | M21: =IF(D21=0,0,J21-L21) -> 0 | N21: =IFERROR(J21/L21,"¥0") -> ¥0 | P21: =IF(D21=0,0,$K$7) -> 0 | Q21: =IF(D21=0,0,$J$21) -> 0 | R21: =IF(D21=0,0,Q21-P21) -> 0 | S21: =IF(D21=0,0,Q21/P21) -> 0 | U21: =IF(D21=0,0,$L$21) -> 0 | V21: =IF(D21=0,0,$J$21) -> 0 | W21: =IF(D21=0,0,V21-U21) -> 0 | X21: =IF(D21=0,0,V21/U21) -> 0 | Y21: =B2 -> 45658 | Z21: =B2 -> 45658
C22: 2 | D22: 0 | E22: =MONTH(Y22) -> 1 | F22: =F21+1 -> 45659 | G22: =TEXT(Z22,"ddd") -> Thu | H22: 休み | L22: =IF(D22=0,0,$K$7) -> 0 | M22: =IF(D22=0,0,J22-L22) -> 0 | N22: =IFERROR(J22/L22,"¥0") -> ¥0 | P22: =IF(D22=0,0,SUM($L$21:L22)) -> 0 | Q22: =IF(D22=0,0,SUM($J$21:J22)) -> 0 | R22: =IF(D22=0,0,Q22-P22) -> 0 | S22: =IF(D22=0,0,Q22/P22) -> 0 | U22: =IF(D22=0,0,SUM($L$21:L22)) -> 0 | V22: =IF(D22=0,0,SUM($J$21:J22)) -> 0 | W22: =IF(D22=0,0,V22-U22) -> 0 | X22: =IF(D22=0,0,V22/U22) -> 0 | Y22: =Y21+1 -> 45659 | Z22: =Z21+1 -> 45659
C23: 3 | D23: 0 | E23: =MONTH(Y23) -> 1 | F23: =F22+1 -> 45660 | G23: =TEXT(Z23,"ddd") -> Fri | H23: 休み | L23: =IF(D23=0,0,$K$7) -> 0 | M23: =IF(D23=0,0,J23-L23) -> 0 | N23: =IFERROR(J23/L23,"¥0") -> ¥0 | P23: =IF(D23=0,0,SUM($L$21:L23)) -> 0 | Q23: =IF(D23=0,0,SUM($J$21:J23)) -> 0 | R23: =IF(D23=0,0,Q23-P23) -> 0 | S23: =IF(D23=0,0,Q23/P23) -> 0 | U23: =IF(D23=0,0,SUM($L$21:L23)) -> 0 | V23: =IF(D23=0,0,SUM($J$21:J23)) -> 0 | W23: =IF(D23=0,0,V23-U23) -> 0 | X23: =IF(D23=0,0,V23/U23) -> 0 | Y23: =Y22+1 -> 45660 | Z23: =Z22+1 -> 45660
C24: 4 | D24: 0 | E24: =MONTH(Y24) -> 1 | F24: =F23+1 -> 45661 | G24: =TEXT(Z24,"ddd") -> Sat | H24: 休み | L24: =IF(D24=0,0,$K$7) -> 0 | M24: =IF(D24=0,0,J24-L24) -> 0 | N24: =IFERROR(J24/L24,"¥0") -> ¥0 | P24: =IF(D24=0,0,SUM($L$21:L24)) -> 0 | Q24: =IF(D24=0,0,SUM($J$21:J24)) -> 0 | R24: =IF(D24=0,0,Q24-P24) -> 0 | S24: =IF(D24=0,0,Q24/P24) -> 0 | U24: =IF(D24=0,0,SUM($L$21:L24)) -> 0 | V24: =IF(D24=0,0,SUM($J$21:J24)) -> 0 | W24: =IF(D24=0,0,V24-U24) -> 0 | X24: =IF(D24=0,0,V24/U24) -> 0 | Y24: =Y23+1 -> 45661 | Z24: =Z23+1 -> 45661
C25: 5 | D25: 0 | E25: =MONTH(Y25) -> 1 | F25: =F24+1 -> 45662 | G25: =TEXT(Z25,"ddd") -> Sun | H25: 日曜日 | L25: =IF(D25=0,0,$K$7) -> 0 | M25: =IF(D25=0,0,J25-L25) -> 0 | N25: =IFERROR(J25/L25,"¥0") -> ¥0 | P25: =IF(D25=0,0,SUM($L$21:L25)) -> 0 | Q25: =IF(D25=0,0,SUM($J$21:J25)) -> 0 | R25: =IF(D25=0,0,Q25-P25) -> 0 | S25: =IF(D25=0,0,Q25/P25) -> 0 | U25: =IF(D25=0,0,SUM($L$21:L25)) -> 0 | V25: =IF(D25=0,0,SUM($J$21:J25)) -> 0 | W25: =IF(D25=0,0,V25-U25) -> 0 | X25: =IF(D25=0,0,V25/U25) -> 0 | Y25: =Y24+1 -> 45662 | Z25: =Z24+1 -> 45662
C26: 6 | D26: 1 | E26: =MONTH(Y26) -> 1 | F26: =F25+1 -> 45663 | G26: =TEXT(Z26,"ddd") -> Mon | J26: 349800 | L26: =IF(D26=0,0,$K$7) -> 265734.27 | M26: =IF(D26=0,0,J26-L26) -> 84065.734 | N26: =IFERROR(J26/L26,"¥0") -> 1.3163526 | P26: =IF(D26=0,0,SUM($L$21:L26)) -> 265734.27 | Q26: =IF(D26=0,0,SUM($J$21:J26)) -> 349800 | R26: =IF(D26=0,0,Q26-P26) -> 84065.734 | S26: =IF(D26=0,0,Q26/P26) -> 1.3163526 | U26: =IF(D26=0,0,SUM($L$21:L26)) -> 265734.27 | V26: =IF(D26=0,0,SUM($J$21:J26)) -> 349800 | W26: =IF(D26=0,0,V26-U26) -> 84065.734 | X26: =IF(D26=0,0,V26/U26) -> 1.3163526 | Y26: =Y25+1 -> 45663 | Z26: =Z25+1 -> 45663
C27: 7 | D27: 1 | E27: =MONTH(Y27) -> 1 | F27: =F26+1 -> 45664 | G27: =TEXT(Z27,"ddd") -> Tue | J27: 88530 | L27: =IF(D27=0,0,$K$7) -> 265734.27 | M27: =IF(D27=0,0,J27-L27) -> -177204.27 | N27: =IFERROR(J27/L27,"¥0") -> 0.33315237 | P27: =IF(D27=0,0,SUM($L$21:L27)) -> 531468.53 | Q27: =IF(D27=0,0,SUM($J$21:J27)) -> 438330 | R27: =IF(D27=0,0,Q27-P27) -> -93138.531 | S27: =IF(D27=0,0,Q27/P27) -> 0.8247525 | U27: =IF(D27=0,0,SUM($L$21:L27)) -> 531468.53 | V27: =IF(D27=0,0,SUM($J$21:J27)) -> 438330 | W27: =IF(D27=0,0,V27-U27) -> -93138.531 | X27: =IF(D27=0,0,V27/U27) -> 0.8247525 | Y27: =Y26+1 -> 45664 | Z27: =Z26+1 -> 45664
C28: 8 | D28: 1 | E28: =MONTH(Y28) -> 1 | F28: =F27+1 -> 45665 | G28: =TEXT(Z28,"ddd") -> Wed | J28: 177630 | L28: =IF(D28=0,0,$K$7) -> 265734.27 | M28: =IF(D28=0,0,J28-L28) -> -88104.266 | N28: =IFERROR(J28/L28,"¥0") -> 0.66844974 | P28: =IF(D28=0,0,SUM($L$21:L28)) -> 797202.8 | Q28: =IF(D28=0,0,SUM($J$21:J28)) -> 615960 | R28: =IF(D28=0,0,Q28-P28) -> -181242.8 | S28: =IF(D28=0,0,Q28/P28) -> 0.77265158 | U28: =IF(D28=0,0,SUM($L$21:L28)) -> 797202.8 | V28: =IF(D28=0,0,SUM($J$21:J28)) -> 615960 | W28: =IF(D28=0,0,V28-U28) -> -181242.8 | X28: =IF(D28=0,0,V28/U28) -> 0.77265158 | Y28: =Y27+1 -> 45665 | Z28: =Z27+1 -> 45665
C29: 9 | D29: 1 | E29: =MONTH(Y29) -> 1 | F29: =F28+1 -> 45666 | G29: =TEXT(Z29,"ddd") -> Thu | J29: 376670 | L29: =IF(D29=0,0,$K$7) -> 265734.27 | M29: =IF(D29=0,0,J29-L29) -> 110935.73 | N29: =IFERROR(J29/L29,"¥0") -> 1.4174687 | P29: =IF(D29=0,0,SUM($L$21:L29)) -> 1062937.1 | Q29: =IF(D29=0,0,SUM($J$21:J29)) -> 992630 | R29: =IF(D29=0,0,Q29-P29) -> -70307.063 | S29: =IF(D29=0,0,Q29/P29) -> 0.93385586 | U29: =IF(D29=0,0,SUM($L$21:L29)) -> 1062937.1 | V29: =IF(D29=0,0,SUM($J$21:J29)) -> 992630 | W29: =IF(D29=0,0,V29-U29) -> -70307.063 | X29: =IF(D29=0,0,V29/U29) -> 0.93385586 | Y29: =Y28+1 -> 45666 | Z29: =Z28+1 -> 45666
C30: 10 | D30: 1 | E30: =MONTH(Y30) -> 1 | F30: =F29+1 -> 45667 | G30: =TEXT(Z30,"ddd") -> Fri | J30: 377100 | L30: =IF(D30=0,0,$K$7) -> 265734.27 | M30: =IF(D30=0,0,J30-L30) -> 111365.73 | N30: =IFERROR(J30/L30,"¥0") -> 1.4190868 | P30: =IF(D30=0,0,SUM($L$21:L30)) -> 1328671.3 | Q30: =IF(D30=0,0,SUM($J$21:J30)) -> 1369730 | R30: =IF(D30=0,0,Q30-P30) -> 41058.671 | S30: =IF(D30=0,0,Q30/P30) -> 1.0309021 | U30: =IF(D30=0,0,SUM($L$21:L30)) -> 1328671.3 | V30: =IF(D30=0,0,SUM($J$21:J30)) -> 1369730 | W30: =IF(D30=0,0,V30-U30) -> 41058.671 | X30: =IF(D30=0,0,V30/U30) -> 1.0309021 | Y30: =Y29+1 -> 45667 | Z30: =Z29+1 -> 45667
C31: 11 | D31: 1 | E31: =MONTH(Y31) -> 1 | F31: =F30+1 -> 45668 | G31: =TEXT(Z31,"ddd") -> Sat | J31: 66550 | L31: =IF(D31=0,0,$K$7) -> 265734.27 | M31: =IF(D31=0,0,J31-L31) -> -199184.27 | N31: =IFERROR(J31/L31,"¥0") -> 0.25043816 | P31: =IF(D31=0,0,SUM($L$21:L31)) -> 1594405.6 | Q31: =IF(D31=0,0,SUM($J$21:J31)) -> 1436280 | R31: =IF(D31=0,0,Q31-P31) -> -158125.59 | S31: =IF(D31=0,0,Q31/P31) -> 0.90082474 | U31: =IF(D31=0,0,SUM($L$21:L31)) -> 1594405.6 | V31: =IF(D31=0,0,SUM($J$21:J31)) -> 1436280 | W31: =IF(D31=0,0,V31-U31) -> -158125.59 | X31: =IF(D31=0,0,V31/U31) -> 0.90082474 | Y31: =Y30+1 -> 45668 | Z31: =Z30+1 -> 45668
C32: 12 | D32: 0 | E32: =MONTH(Y32) -> 1 | F32: =F31+1 -> 45669 | G32: =TEXT(Z32,"ddd") -> Sun | H32: 日曜日 | L32: =IF(D32=0,0,$K$7) -> 0 | M32: =IF(D32=0,0,J32-L32) -> 0 | N32: =IFERROR(J32/L32,"¥0") -> ¥0 | P32: =IF(D32=0,0,SUM($L$21:L32)) -> 0 | Q32: =IF(D32=0,0,SUM($J$21:J32)) -> 0 | R32: =IF(D32=0,0,Q32-P32) -> 0 | S32: =IF(D32=0,0,Q32/P32) -> 0 | U32: =IF(D32=0,0,SUM($L$21:L32)) -> 0 | V32: =IF(D32=0,0,SUM($J$21:J32)) -> 0 | W32: =IF(D32=0,0,V32-U32) -> 0 | X32: =IF(D32=0,0,V32/U32) -> 0 | Y32: =Y31+1 -> 45669 | Z32: =Z31+1 -> 45669
C33: 13 | D33: 0 | E33: =MONTH(Y33) -> 1 | F33: =F32+1 -> 45670 | G33: =TEXT(Z33,"ddd") -> Mon | H33: 成人の日 | L33: =IF(D33=0,0,$K$7) -> 0 | M33: =IF(D33=0,0,J33-L33) -> 0 | N33: =IFERROR(J33/L33,"¥0") -> ¥0 | P33: =IF(D33=0,0,SUM($L$21:L33)) -> 0 | Q33: =IF(D33=0,0,SUM($J$21:J33)) -> 0 | R33: =IF(D33=0,0,Q33-P33) -> 0 | S33: =IF(D33=0,0,Q33/P33) -> 0 | U33: =IF(D33=0,0,SUM($L$21:L33)) -> 0 | V33: =IF(D33=0,0,SUM($J$21:J33)) -> 0 | W33: =IF(D33=0,0,V33-U33) -> 0 | X33: =IF(D33=0,0,V33/U33) -> 0 | Y33: =Y32+1 -> 45670 | Z33: =Z32+1 -> 45670
C34: 14 | D34: 1 | E34: =MONTH(Y34) -> 1 | F34: =F33+1 -> 45671 | G34: =TEXT(Z34,"ddd") -> Tue | J34: 372310 | L34: =IF(D34=0,0,$K$7) -> 265734.27 | M34: =IF(D34=0,0,J34-L34) -> 106575.73 | N34: =IFERROR(J34/L34,"¥0") -> 1.4010613 | P34: =IF(D34=0,0,SUM($L$21:L34)) -> 1860139.9 | Q34: =IF(D34=0,0,SUM($J$21:J34)) -> 1808590 | R34: =IF(D34=0,0,Q34-P34) -> -51549.86 | S34: =IF(D34=0,0,Q34/P34) -> 0.97228711 | U34: =IF(D34=0,0,SUM($L$21:L34)) -> 1860139.9 | V34: =IF(D34=0,0,SUM($J$21:J34)) -> 1808590 | W34: =IF(D34=0,0,V34-U34) -> -51549.86 | X34: =IF(D34=0,0,V34/U34) -> 0.97228711 | Y34: =Y33+1 -> 45671 | Z34: =Z33+1 -> 45671
C35: 15 | D35: 1 | E35: =MONTH(Y35) -> 1 | F35: =F34+1 -> 45672 | G35: =TEXT(Z35,"ddd") -> Wed | J35: 246200 | L35: =IF(D35=0,0,$K$7) -> 265734.27 | M35: =IF(D35=0,0,J35-L35) -> -19534.266 | N35: =IFERROR(J35/L35,"¥0") -> 0.92648947 | P35: =IF(D35=0,0,SUM($L$21:L35)) -> 2125874.1 | Q35: =IF(D35=0,0,SUM($J$21:J35)) -> 2054790 | R35: =IF(D35=0,0,Q35-P35) -> -71084.126 | S35: =IF(D35=0,0,Q35/P35) -> 0.9665624 | U35: =IF(D35=0,0,SUM($L$21:L35)) -> 2125874.1 | V35: =IF(D35=0,0,SUM($J$21:J35)) -> 2054790 | W35: =IF(D35=0,0,V35-U35) -> -71084.126 | X35: =IF(D35=0,0,V35/U35) -> 0.9665624 | Y35: =Y34+1 -> 45672 | Z35: =Z34+1 -> 45672
C36: 16 | D36: 1 | E36: =MONTH(Y36) -> 1 | F36: =F35+1 -> 45673 | G36: =TEXT(Z36,"ddd") -> Thu | J36: 400950 | L36: =IF(D36=0,0,$K$7) -> 265734.27 | M36: =IF(D36=0,0,J36-L36) -> 135215.73 | N36: =IFERROR(J36/L36,"¥0") -> 1.5088382 | P36: =IF(D36=0,0,SUM($L$21:L36)) -> 2391608.4 | Q36: =IF(D36=0,0,SUM($J$21:J36)) -> 2455740 | R36: =IF(D36=0,0,Q36-P36) -> 64131.608 | S36: =IF(D36=0,0,Q36/P36) -> 1.0268153 | U36: =IF(D36=0,0,SUM($L$21:L36)) -> 2391608.4 | V36: =IF(D36=0,0,SUM($J$21:J36)) -> 2455740 | W36: =IF(D36=0,0,V36-U36) -> 64131.608 | X36: =IF(D36=0,0,V36/U36) -> 1.0268153 | Y36: =Y35+1 -> 45673 | Z36: =Z35+1 -> 45673
C37: 17 | D37: 1 | E37: =MONTH(Y37) -> 1 | F37: =F36+1 -> 45674 | G37: =TEXT(Z37,"ddd") -> Fri | J37: 262380 | L37: =IF(D37=0,0,$K$7) -> 265734.27 | M37: =IF(D37=0,0,J37-L37) -> -3354.2657 | N37: =IFERROR(J37/L37,"¥0") -> 0.98737737 | P37: =IF(D37=0,0,SUM($L$21:L37)) -> 2657342.7 | Q37: =IF(D37=0,0,SUM($J$21:J37)) -> 2718120 | R37: =IF(D37=0,0,Q37-P37) -> 60777.343 | S37: =IF(D37=0,0,Q37/P37) -> 1.0228715 | U37: =IF(D37=0,0,SUM($L$21:L37)) -> 2657342.7 | V37: =IF(D37=0,0,SUM($J$21:J37)) -> 2718120 | W37: =IF(D37=0,0,V37-U37) -> 60777.343 | X37: =IF(D37=0,0,V37/U37) -> 1.0228715 | Y37: =Y36+1 -> 45674 | Z37: =Z36+1 -> 45674
C38: 18 | D38: 1 | E38: =MONTH(Y38) -> 1 | F38: =F37+1 -> 45675 | G38: =TEXT(Z38,"ddd") -> Sat | J38: 137800 | L38: =IF(D38=0,0,$K$7) -> 265734.27 | M38: =IF(D38=0,0,J38-L38) -> -127934.27 | N38: =IFERROR(J38/L38,"¥0") -> 0.51856316 | P38: =IF(D38=0,0,SUM($L$21:L38)) -> 2923076.9 | Q38: =IF(D38=0,0,SUM($J$21:J38)) -> 2855920 | R38: =IF(D38=0,0,Q38-P38) -> -67156.923 | S38: =IF(D38=0,0,Q38/P38) -> 0.97702526 | U38: =IF(D38=0,0,SUM($L$21:L38)) -> 2923076.9 | V38: =IF(D38=0,0,SUM($J$21:J38)) -> 2855920 | W38: =IF(D38=0,0,V38-U38) -> -67156.923 | X38: =IF(D38=0,0,V38/U38) -> 0.97702526 | Y38: =Y37+1 -> 45675 | Z38: =Z37+1 -> 45675
C39: 19 | D39: 0 | E39: =MONTH(Y39) -> 1 | F39: =F38+1 -> 45676 | G39: =TEXT(Z39,"ddd") -> Sun | L39: =IF(D39=0,0,$K$7) -> 0 | M39: =IF(D39=0,0,J39-L39) -> 0 | N39: =IFERROR(J39/L39,"¥0") -> ¥0 | P39: =IF(D39=0,0,SUM($L$21:L39)) -> 0 | Q39: =IF(D39=0,0,SUM($J$21:J39)) -> 0 | R39: =IF(D39=0,0,Q39-P39) -> 0 | S39: =IF(D39=0,0,Q39/P39) -> 0 | U39: =IF(D39=0,0,SUM($L$21:L39)) -> 0 | V39: =IF(D39=0,0,SUM($J$21:J39)) -> 0 | W39: =IF(D39=0,0,V39-U39) -> 0 | X39: =IF(D39=0,0,V39/U39) -> 0 | Y39: =Y38+1 -> 45676 | Z39: =Z38+1 -> 45676
C40: 20 | D40: 1 | E40: =MONTH(Y40) -> 1 | F40: =F39+1 -> 45677 | G40: =TEXT(Z40,"ddd") -> Mon | J40: 265910 | L40: =IF(D40=0,0,$K$7) -> 265734.27 | M40: =IF(D40=0,0,J40-L40) -> 175.73427 | N40: =IFERROR(J40/L40,"¥0") -> 1.0006613 | P40: =IF(D40=0,0,SUM($L$21:L40)) -> 3188811.2 | Q40: =IF(D40=0,0,SUM($J$21:J40)) -> 3121830 | R40: =IF(D40=0,0,Q40-P40) -> -66981.189 | S40: =IF(D40=0,0,Q40/P40) -> 0.97899493 | U40: =IF(D40=0,0,SUM($L$21:L40)) -> 3188811.2 | V40: =IF(D40=0,0,SUM($J$21:J40)) -> 3121830 | W40: =IF(D40=0,0,V40-U40) -> -66981.189 | X40: =IF(D40=0,0,V40/U40) -> 0.97899493 | Y40: =Y39+1 -> 45677 | Z40: =Z39+1 -> 45677
C41: 21 | D41: 1 | E41: =MONTH(Y41) -> 1 | F41: =F40+1 -> 45678 | G41: =TEXT(Z41,"ddd") -> Tue | J41: 175950 | L41: =IF(D41=0,0,$K$7) -> 265734.27 | M41: =IF(D41=0,0,J41-L41) -> -89784.266 | N41: =IFERROR(J41/L41,"¥0") -> 0.66212763 | P41: =IF(D41=0,0,SUM($L$21:L41)) -> 3454545.5 | Q41: =IF(D41=0,0,SUM($J$21:J41)) -> 3297780 | R41: =IF(D41=0,0,Q41-P41) -> -156765.45 | S41: =IF(D41=0,0,Q41/P41) -> 0.95462053 | U41: =IF(D41=0,0,SUM($L$21:L41)) -> 3454545.5 | V41: =IF(D41=0,0,SUM($J$21:J41)) -> 3297780 | W41: =IF(D41=0,0,V41-U41) -> -156765.45 | X41: =IF(D41=0,0,V41/U41) -> 0.95462053 | Y41: =Y40+1 -> 45678 | Z41: =Z40+1 -> 45678
C42: 22 | D42: 1 | E42: =MONTH(Y42) -> 1 | F42: =F41+1 -> 45679 | G42: =TEXT(Z42,"ddd") -> Wed | J42: 262170 | L42: =IF(D42=0,0,$K$7) -> 265734.27 | M42: =IF(D42=0,0,J42-L42) -> -3564.2657 | N42: =IFERROR(J42/L42,"¥0") -> 0.98658711 | P42: =IF(D42=0,0,SUM($L$21:L42)) -> 3720279.7 | Q42: =IF(D42=0,0,SUM($J$21:J42)) -> 3559950 | R42: =IF(D42=0,0,Q42-P42) -> -160329.72 | S42: =IF(D42=0,0,Q42/P42) -> 0.95690385 | U42: =IF(D42=0,0,SUM($L$21:L42)) -> 3720279.7 | V42: =IF(D42=0,0,SUM($J$21:J42)) -> 3559950 | W42: =IF(D42=0,0,V42-U42) -> -160329.72 | X42: =IF(D42=0,0,V42/U42) -> 0.95690385 | Y42: =Y41+1 -> 45679 | Z42: =Z41+1 -> 45679
C43: 23 | D43: 1 | E43: =MONTH(Y43) -> 1 | F43: =F42+1 -> 45680 | G43: =TEXT(Z43,"ddd") -> Thu | J43: 342980 | L43: =IF(D43=0,0,$K$7) -> 265734.27 | M43: =IF(D43=0,0,J43-L43) -> 77245.734 | N43: =IFERROR(J43/L43,"¥0") -> 1.2906879 | P43: =IF(D43=0,0,SUM($L$21:L43)) -> 3986014 | Q43: =IF(D43=0,0,SUM($J$21:J43)) -> 3902930 | R43: =IF(D43=0,0,Q43-P43) -> -83083.986 | S43: =IF(D43=0,0,Q43/P43) -> 0.97915612 | U43: =IF(D43=0,0,SUM($L$21:L43)) -> 3986014 | V43: =IF(D43=0,0,SUM($J$21:J43)) -> 3902930 | W43: =IF(D43=0,0,V43-U43) -> -83083.986 | X43: =IF(D43=0,0,V43/U43) -> 0.97915612 | Y43: =Y42+1 -> 45680 | Z43: =Z42+1 -> 45680
...

Sheet 適正原価率表(仕入れお小遣い制度)
B1: 2025年次売上目標額 | L1: 2024年売上実績
B2: 80000000 | C2: =SUM(B4:B27) -> 63508421 | L2: 71110161
B3: 目標売上額 | C3: 営業日数 | D3: カテゴリ | E3: 売上率(2024年) | F3: 想定売上額 | H3: 目標原価率 | I3: 月次目標原価額 | J3: 1日あたりの仕入額 | L3: 2024年仕入れ額 | M3: 差額=削減目標額 | O3: 食材原価率
A4: 45658 | B4: =目標_2025R7!I7 -> 5835789.5 | C4: =目標_2025R7!F7 -> 22 | D4: フード | E4: =バルカ18期!E12 -> 0.73432464 | F4: =B4*E4 -> 4285364 | H4: 0.3 | I4: =F4*H4 -> 1285609.2 | J4: =I4/C4 -> 58436.782 | L4: =バルカ18期!D13 -> 1264422 | M4: =I4-L4 -> 21187.203 | O4: =(I4+I5)/B4 -> 0.27343246
D5: ドリンク | E5: =バルカ18期!E14 -> 0.26567536 | F5: =B4*E5 -> 1550425.5 | H5: 0.2 | I5: =F5*H5 -> 310085.09 | J5: =I5/C4 -> 14094.777 | L5: =バルカ18期!D15 -> 486956 | M5: =I5-L5 -> -176870.91
A6: 45689 | B6: =目標_2025R7!I8 -> 4863157.9 | C6: =目標_2025R7!F8 -> 22 | D6: フード | E6: =バルカ18期!G12 -> 0.7316942 | F6: =B6*E6 -> 3558344.4 | H6: 0.3 | I6: =F6*H6 -> 1067503.3 | J6: =I6/C6 -> 48522.879 | L6: =バルカ18期!F13 -> 1416358 | M6: =I6-L6 -> -348854.67 | O6: =(I6+I7)/B6 -> 0.27316942
D7: ドリンク | E7: =バルカ18期!G14 -> 0.2683058 | F7: =B6*E7 -> 1304813.5 | H7: 0.2 | I7: =F7*H7 -> 260962.69 | J7: =I7/C6 -> 11861.941 | L7: =バルカ18期!F15 -> 361305 | M7: =I7-L7 -> -100342.31
A8: 45717 | B8: =目標_2025R7!I9 -> 7184210.5 | C8: =目標_2025R7!F9 -> 25 | D8: フード | E8: =バルカ18期!I12 -> 0.75556981 | F8: =B8*E8 -> 5428172.6 | H8: 0.3 | I8: =F8*H8 -> 1628451.8 | J8: =I8/C8 -> 65138.071 | L8: =バルカ18期!H13 -> 1742628 | M8: =I8-L8 -> -114176.23 | O8: =(I8+I9)/B8 -> 0.27555698
D9: ドリンク | E9: =バルカ18期!I14 -> 0.24443019 | F9: =B8*E9 -> 1756037.9 | H9: 0.2 | I9: =F9*H9 -> 351207.59 | J9: =I9/C8 -> 14048.304 | L9: =バルカ18期!H15 -> 394307 | M9: =I9-L9 -> -43099.41
A10: 45748 | B10: =目標_2025R7!I10 -> 7184210.5 | C10: =目標_2025R7!F10 -> 25 | D10: フード | E10: =バルカ18期!K12 -> 0.74456124 | F10: =B10*E10 -> 5349084.7 | H10: 0.3 | I10: =F10*H10 -> 1604725.4 | J10: =I10/C10 -> 64189.016 | L10: =バルカ18期!J13 -> 1870295 | M10: =I10-L10 -> -265569.6 | O10: =(I10+I11)/B10 -> 0.27445612
D11: ドリンク | E11: =バルカ18期!K14 -> 0.25543876 | F11: =B10*E11 -> 1835125.8 | H11: 0.2 | I11: =F11*H11 -> 367025.17 | J11: =I11/C10 -> 14681.007 | L11: =バルカ18期!J15 -> 369635 | M11: =I11-L11 -> -2609.8311
A12: 45778 | B12: =目標_2025R7!I11 -> 5835789.5 | C12: =目標_2025R7!F11 -> 24 | D12: フード | E12: =バルカ18期!M12 -> 0.75478872 | F12: =B12*E12 -> 4404788.1 | H12: 0.3 | I12: =F12*H12 -> 1321436.4 | J12: =I12/C12 -> 55059.851 | L12: =バルカ18期!L13 -> 1771753 | M12: =I12-L12 -> -450316.58 | O12: =(I12+I13)/B12 -> 0.27547887
D13: ドリンク | E13: =バルカ18期!M14 -> 0.24521128 | F13: =B12*E13 -> 1431001.4 | H13: 0.2 | I13: =F13*H13 -> 286200.28 | J13: =I13/C12 -> 11925.012 | L13: =バルカ18期!L15 -> 336516 | M13: =I13-L13 -> -50315.717
A14: 45809 | B14: =目標_2025R7!I12 -> 6078947.4 | C14: =目標_2025R7!F12 -> 25 | D14: フード | E14: =バルカ18期!O12 -> 0.75608291 | F14: =B14*E14 -> 4596188.2 | H14: 0.3 | I14: =F14*H14 -> 1378856.5 | J14: =I14/C14 -> 55154.258 | L14: =バルカ18期!N13 -> 2345230 | M14: =I14-L14 -> -966373.54 | O14: =(I14+I15)/B14 -> 0.27560829
D15: ドリンク | E15: =バルカ18期!O14 -> 0.24391709 | F15: =B14*E15 -> 1482759.2 | H15: 0.2 | I15: =F15*H15 -> 296551.84 | J15: =I15/C14 -> 11862.073 | L15: =バルカ18期!N15 -> 328916 | M15: =I15-L15 -> -32364.164
A16: 45839 | B16: =目標_2025R7!I13 -> 5172631.6 | C16: =目標_2025R7!F13 -> 26 | D16: フード | E16: =バルカ18期!Q12 -> 0.77721653 | F16: =B16*E16 -> 4020254.8 | H16: 0.3 | I16: =F16*H16 -> 1206076.4 | J16: =I16/C16 -> 46387.555 | L16: =バルカ18期!P13 -> 1682168 | M16: =I16-L16 -> -476091.57 | O16: =(I16+I17)/B16 -> 0.27772165
D17: ドリンク | E17: =バルカ18期!Q14 -> 0.22278347 | F17: =B16*E17 -> 1152376.8 | H17: 0.2 | I17: =F17*H17 -> 230475.36 | J17: =I17/C16 -> 8864.437 | L17: =バルカ18期!P15 -> 441503 | M17: =I17-L17 -> -211027.64
A18: 45870 | B18: =目標_2025R7!I14 -> 2210526.3 | C18: =目標_2025R7!F14 -> 20 | D18: フード | E18: =バルカ18期!S12 -> 0.76479 | F18: =B18*E18 -> 1690588.4 | H18: 0.3 | I18: =F18*H18 -> 507176.52 | J18: =I18/C18 -> 25358.826 | L18: =バルカ18期!R13 -> 1300325 | M18: =I18-L18 -> -793148.48 | O18: =(I18+I19)/B18 -> 0.276479
D19: ドリンク | E19: =バルカ18期!S14 -> 0.23521 | F19: =B18*E19 -> 519937.9 | H19: 0.2 | I19: =F19*H19 -> 103987.58 | J19: =I19/C18 -> 5199.379 | L19: =バルカ18期!R15 -> 225741 | M19: =I19-L19 -> -121753.42
A20: 45901 | B20: =目標_2025R7!I15 -> 3050526.3 | C20: =目標_2025R7!F15 -> 23 | D20: フード | E20: =バルカ18期!U12 -> 0.76676359 | F20: =B20*E20 -> 2339032.5 | H20: 0.3 | I20: =F20*H20 -> 701709.76 | J20: =I20/C20 -> 30509.12 | L20: =バルカ18期!T13 -> 1712780 | M20: =I20-L20 -> -1011070.2 | O20: =(I20+I21)/B20 -> 0.27667636
D21: ドリンク | E21: =バルカ18期!U14 -> 0.23323641 | F21: =B20*E21 -> 711493.8 | H21: 0.2 | I21: =F21*H21 -> 142298.76 | J21: =I21/C20 -> 6186.9026 | L21: =バルカ18期!T15 -> 358096 | M21: =I21-L21 -> -215797.24
A22: 45931 | B22: =目標_2025R7!I16 -> 5172631.6 | C22: =目標_2025R7!F16 -> 26 | D22: フード | E22: =バルカ18期!W12 -> 0.76291191 | F22: =B22*E22 -> 3946262.2 | H22: 0.3 | I22: =F22*H22 -> 1183878.7 | J22: =I22/C22 -> 45533.795 | L22: =バルカ18期!V13 -> 1877653 | M22: =I22-L22 -> -693774.33 | O22: =(I22+I23)/B22 -> 0.27629119
D23: ドリンク | E23: =バルカ18期!W14 -> 0.23708809 | F23: =B22*E23 -> 1226369.3 | H23: 0.2 | I23: =F23*H23 -> 245273.87 | J23: =I23/C22 -> 9433.6103 | L23: =バルカ18期!V15 -> 424058 | M23: =I23-L23 -> -178784.13
A24: 45962 | B24: =目標_2025R7!I17 -> 5084210.5 | C24: =目標_2025R7!F17 -> 23 | D24: フード | E24: =バルカ18期!Y12 -> 0.75359571 | F24: =B24*E24 -> 3831439.2 | H24: 0.3 | I24: =F24*H24 -> 1149431.8 | J24: =I24/C24 -> 49975.294 | L24: =バルカ18期!X13 -> 1365920 | M24: =I24-L24 -> -216488.23 | O24: =(I24+I25)/B24 -> 0.27535957
D25: ドリンク | E25: =バルカ18期!Y14 -> 0.24640429 | F25: =B24*E25 -> 1252771.3 | H25: 0.2 | I25: =F25*H25 -> 250554.26 | J25: =I25/C24 -> 10893.663 | L25: =バルカ18期!X15 -> 379401 | M25: =I25-L25 -> -128846.74
A26: 45992 | B26: =目標_2025R7!I18 -> 5835789.5 | C26: =目標_2025R7!F18 -> 24 | D26: フード | E26: =バルカ18期!AA12 -> 0.75430599 | F26: =B26*E26 -> 4401971 | H26: 0.3 | I26: =F26*H26 -> 1320591.3 | J26: =I26/C26 -> 55024.637 | L26: =バルカ18期!Z13 -> 2079765 | M26: =I26-L26 -> -759173.71 | O26: =(I26+I27)/B26 -> 0.2754306
D27: ドリンク | E27: =バルカ18期!AA14 -> 0.24569401 | F27: =B26*E27 -> 1433818.5 | H27: 0.2 | I27: =F27*H27 -> 286763.7 | J27: =I27/C26 -> 11948.488 | L27: =バルカ18期!Z15 -> 568462 | M27: =I27-L27 -> -281698.3
I28: =SUM(I4:I27) -> 17486833 | J28: =I28/B2 -> 0.21858542 | L28: =SUM(L4:L27) -> 25104193 | M28: =L28/L2 -> 0.35303243

Sheet 戦略シート
B2: 日程 | D2: ①日次目標売上 | E2: 月次目標売上 | F2: 同月営業残日数 | I2: ランチ平均客単価 | J2: ディナー平均客単価
B3: 45822 | D3: =INDEX(目標_2025R7!L20:L384, MATCH(B3, 目標_2025R7!F20:F384, 0)) -> 174297.9 | E3: {=INDEX(目標_2025R7!I7:I18, MONTH(B3))} -> 6078947.4 | F3: =SUMIFS(目標_2025R7!D20:D384, 目標_2025R7!F20:F384, ">=" & B3, 目標_2025R7!E20:E384, MONTH(B3)) -> 14 | I3: 1275 | J3: 6274
D5: ②前年同曜日実質売上額 | E5: {=IF( INDEX(実績_2024R6!D20:D385, MATCH(1, (実績_2024R6!G20:G385=TEXT(B3,"ddd"))* (実績_2024R6!F20:F385>=B3-370)* (実績_2024R6!F20:F385<=B3-358), 0) )=0, "店休日", INDEX(実績_2024R6!J20:J385, MATCH(1, (実績_2024R6!G20:G385=TEXT(B3,"ddd"))* (実績_2024R6!F20:F385>=B3-370)* (実績_2024R6!F20:F385<=B3-358), 0) ) )} -> 161770 | F5: {=TEXT( INDEX(実績_2024R6!F20:F385, MATCH(1, (実績_2024R6!G20:G385=TEXT(B3,"ddd"))* (実績_2024R6!F20:F385>=B3-370)* (実績_2024R6!F20:F385<=B3-358), 0) ), "yyyy/m/d (ddd)" )} -> 2024/6/15 (Sat) | G5: 前年同曜日の実績売上
D6: ②ー①差額 | E6: =E5-D3 -> -12527.902
D7: 達成率 | E7: =E5/D3 -> 0.92812362
D9: 月次売上額 | E9: =INDEX(目標_2025R7!Q20:Q384, MATCH(B3, 目標_2025R7!F20:F384, 0)) -> 2650720
D10: 月次目標売上額 | E10: =INDEX(目標_2025R7!P20:P384, MATCH(B3, 目標_2025R7!F20:F384, 0)) -> 2960345.9
D11: ③月次差額 | E11: =E9-E10 -> -309625.86
D12: 月次達成率 | E12: =E10/E9 -> 1.1168082
D13: 1日辺りに取返す額 | E13: =E11/F3 -> -22116.133 | F13: ＊営業残日数で③を割った値
D15: 年次売上額 | E15: =INDEX(目標_2025R7!V20:V384, MATCH(B3, 目標_2025R7!F20:F384, 0)) -> 34379580
D16: 年次目標売上額 | E16: =INDEX(目標_2025R7!U20:U384, MATCH(B3, 目標_2025R7!F20:F384, 0)) -> 33863504
D17: 年次差額 | E17: =E16-E15 -> -516076.24
D18: 年次達成率 | E18: =E15/E16 -> 1.0152399
D20: 1日の売上目標値 参考例
D21: 目標売上 | F21: =D3 -> 174297.9
D22: 実質予想売上額 | F22: =E5 -> 161770
D23: 差額 | F23: =F22-F21 -> -12527.902
D24: 仮1日売上総合計 | F24: =F25-F23 -> 217805.9
D25: シュミレーター | F25: =SUM(G27:G32) -> 205278
D26: 項目 | E26: 仮客単価 | F26: 集客数 | G26: 仮1日の売上小計
D27: ランチ | E27: ='2024年間データ'!G30 -> 1275.1667 | F27: 67 | G27: =E27*F27 -> 85436.167
D28: ディナー | E28: ='2024年間データ'!H30 -> 6274.4167 | F28: 14 | G28: =E28*F28 -> 87841.833
D29: Party 5500 | E29: 5500 | F29: 0 | G29: =E29*F29 -> 0
D30: Party 6800 | E30: 6800 | F30: 0 | G30: =E30*F30 -> 0
D31: Party 8000 | E31: 8000 | F31: 4 | G31: =E31*F31 -> 32000
F32: 0 | G32: =E32*F32 -> 0

Sheet 実績_2024R6
