Workbook

Sheet ★リトローボ戦略表
A2: リトローボ | B2: 45962 | C2: =MONTH(B2) -> 11 | D2: =TEXT(B2, "ddd") -> Sat
B3: =B16 -> 45970 | D3: =TEXT(B3, "aaa") -> 日
B4: 目標売上 | C4: {=_xludf.XLOOKUP(D3, B7:B13, C7:C13, "該当なし")} -> #NAME?
B6: 9月 曜日毎の目標売上 | D6: 傾向 | G6: 対策考察
B7: mon | C7: =SUMIFS(目標_2025R7!$AE$22:$AE$104, 目標_2025R7!$AA$22:$AA$104, MONTH($B$2), 目標_2025R7!$AB$22:$AB$104, B7) -> 0
B8: tue | C8: =SUMIFS(目標_2025R7!$AE$22:$AE$104, 目標_2025R7!$AA$22:$AA$104, MONTH($B$2), 目標_2025R7!$AB$22:$AB$104, B8) -> 0
B9: wed | C9: =SUMIFS(目標_2025R7!$AE$22:$AE$104, 目標_2025R7!$AA$22:$AA$104, MONTH($B$2), 目標_2025R7!$AB$22:$AB$104, B9) -> 0
B10: thu | C10: =SUMIFS(目標_2025R7!$AE$22:$AE$104, 目標_2025R7!$AA$22:$AA$104, MONTH($B$2), 目標_2025R7!$AB$22:$AB$104, B10) -> 0
B11: fri | C11: =SUMIFS(目標_2025R7!$AE$22:$AE$104, 目標_2025R7!$AA$22:$AA$104, MONTH($B$2), 目標_2025R7!$AB$22:$AB$104, B11) -> 0
B12: sat | C12: =SUMIFS(目標_2025R7!$AE$22:$AE$104, 目標_2025R7!$AA$22:$AA$104, MONTH($B$2), 目標_2025R7!$AB$22:$AB$104, B12) -> 0
B13: sun | C13: =SUMIFS(目標_2025R7!$AE$22:$AE$104, 目標_2025R7!$AA$22:$AA$104, MONTH($B$2), 目標_2025R7!$AB$22:$AB$104, B13) -> 0
A16: リトローボ | B16: 45970 | C16: =TEXT(B16, "ddd") -> Sun
A17: 日次 | B17: 売上 | C17: =_xlfn.XLOOKUP(B16, 目標_2025R7!F21:F385,目標_2025R7!J21:J385,"該当なし") -> 33600 | E17: 月次目標売上 | F17: {=INDEX(目標_2025R7!I7:I18, MATCH(MONTH(B2), 目標_2025R7!R7:R18, 0))} -> 2268041.2 | N17: 月 | O17: 傾向分析
B18: 平均目標売上 | C18: {=INDEX(目標_2025R7!K7:K18, MATCH(C2, 目標_2025R7!R7:R18, 0))} -> 103092.78 | E18: 月次累計実績売上 | F18: =C23 -> 606850
B19: 目標売上 | C19: =_xlfn.XLOOKUP(C16, B7:B13, C7:C13, "該当なし") -> 0 | E19: 差額 | F19: =F17-F18 -> 1661191.2 | N19: 1月 | O19: A: 月初・末が強い（中旬落ち）
B20: 差額 | C20: =IFERROR(C17-C19,0) -> 33600 | E20: 当月残営業日 | F20: {=(SUMPRODUCT((目標_2025R7!F21:F385>=B16)*(目標_2025R7!E21:E385=C2)*(目標_2025R7!D21:D385=1)))-1} -> 15 | N20: 2月 | O20: B: 月末にかけて上がる
B21: 達成率 | C21: =IFERROR(C17/C19,0) -> 0 | E21: 1日あたりの目標売上 | F21: =IFERROR(F19/F20,0) -> 110746.08 | N21: 3月 | O21: B: 同様に右肩上がり傾向
N22: 4月 | O22: A: 月初も末も強く安定感あり
A23: 月次 | B23: 累積売上 | C23: =_xlfn.XLOOKUP(B16, 目標_2025R7!F21:F385,目標_2025R7!Q21:Q385,"該当なし") -> 606850 | N23: 5月 | O23: B: 徐々に上がる
B24: 累積目標売上 | C24: =_xlfn.XLOOKUP(B16, 目標_2025R7!F21:F385,目標_2025R7!P21:P385,"該当なし") -> 721649.48 | N24: 分類 | O24: 説明
B25: 差額 | C25: =C23-C24 -> -114799.48 | N25: A: 初・末が強い | O25: 月初・月末の売上が高く、中旬が落ちるパターン
B26: 達成率 | C26: =IFERROR(C23/C24,0) -> 0.84092071 | N26: B: 徐々に上がる | O26: 月初が弱く、末に向かって売上が上がる
N27: C: 平均的 or 中旬強い | O27: 大きな偏りがない or 中旬が強いパターン
A28: 年次 | B28: 累積売上 | C28: =_xlfn.XLOOKUP(B16, 目標_2025R7!F21:F385,目標_2025R7!V21:V385,"該当なし") -> 21736375
B29: 累積目標売上 | C29: =_xlfn.XLOOKUP(B16, 目標_2025R7!F21:F385,目標_2025R7!U21:U385,"該当なし") -> 25680412
B30: 差額 | C30: =C28-C29 -> -3944037.4
B31: 達成率 | C31: =IFERROR(C28/C29,0) -> 0.84641846
B33: 年次目標売上 | C33: =目標_2025R7!G3 -> 30000000
B34: 目標達成までの残額 | C34: =C33-C29 -> 4319587.6
B35: 今年の残営業日数 | C35: {=(SUMPRODUCT((目標_2025R7!F21:F385>=B16)*(目標_2025R7!D21:D385=1)))-1} -> 39
B36: 1日あたりの売上額 | C36: =C34/C35 -> 110758.66
B37: 年間達成率 | C37: =1-(C34/C33) -> 0.85601375
A40: リトローボ | B40: 曜日 | C40: 売上 | D40: 平均目標売上 | E40: 曜日繁閑期目標売上 | F40: 差額 | G40: 達成率 | H40: 累積売上 | I40: 累積目標売上 | J40: 差額 | K40: 達成率
B41: =B2 -> 45962 | D41: =$C$18 -> 103092.78 | E41: =$C$8 -> 0 | F41: =C41-E41 -> 0 | G41: =IFERROR(C41/E41,0) -> 0 | H41: =IF(C41=0,0,C41) -> 0 | I41: =IF(C41=0,0,E41) -> 0 | J41: =H41-I41 -> 0 | K41: =IFERROR(H41/I41,0) -> 0
B42: =B41+1 -> 45963 | D42: =$C$18 -> 103092.78 | E42: =$C$9 -> 0 | F42: =C42-E42 -> 0 | G42: =IFERROR(C42/E42,0) -> 0 | H42: =IF(C42=0,0,(H41+C42)) -> 0 | I42: =IF(C42=0,0,(I41+E42)) -> 0 | J42: =H42-I42 -> 0 | K42: =IFERROR(H42/I42,0) -> 0
B43: =B42+1 -> 45964 | D43: =$C$18 -> 103092.78 | E43: =$C$10 -> 0 | F43: =C43-E43 -> 0 | G43: =IFERROR(C43/E43,0) -> 0 | H43: =IF(C43=0,0,(H42+C43)) -> 0 | I43: =IF(C43=0,0,(I42+E43)) -> 0 | J43: =H43-I43 -> 0 | K43: =IFERROR(H43/I43,0) -> 0
B44: =B43+1 -> 45965 | D44: =$C$18 -> 103092.78 | E44: =$C$11 -> 0 | F44: =C44-E44 -> 0 | G44: =IFERROR(C44/E44,0) -> 0 | H44: =IF(C44=0,0,(H43+C44)) -> 0 | I44: =IF(C44=0,0,(I43+E44)) -> 0 | J44: =H44-I44 -> 0 | K44: =IFERROR(H44/I44,0) -> 0
B45: =B44+1 -> 45966 | D45: =$C$18 -> 103092.78 | E45: =$C$12 -> 0 | F45: =C45-E45 -> 0 | G45: =IFERROR(C45/E45,0) -> 0 | H45: =IF(C45=0,0,(H44+C45)) -> 0 | I45: =IF(C45=0,0,(I44+E45)) -> 0 | J45: =H45-I45 -> 0 | K45: =IFERROR(H45/I45,0) -> 0
B46: =B45+1 -> 45967 | D46: 0 | E46: =$C$13 -> 0 | F46: =C46-E46 -> 0 | G46: =IFERROR(C46/E46,0) -> 0 | H46: =IF(C46=0,0,(H45+C46)) -> 0 | I46: =IF(C46=0,0,(I45+E46)) -> 0 | J46: =H46-I46 -> 0 | K46: =IFERROR(H46/I46,0) -> 0
B47: =B46+1 -> 45968 | D47: =$C$18 -> 103092.78 | E47: =$C$7 -> 0 | F47: =C47-E47 -> 0 | G47: =IFERROR(C47/E47,0) -> 0 | H47: =IF(C47=0,0,(H46+C47)) -> 0 | I47: =IF(C47=0,0,(I46+E47)) -> 0 | J47: =H47-I47 -> 0 | K47: =IFERROR(H47/I47,0) -> 0
...

Sheet 目標_2025R7
B2: 45658 | E2: ①年間営業日 | G2: ②年間目標売上 | H2: 年間総売上％ | K2: 年間売上合計 | M2: 実質売上 | P2: 1月 | Q2: 2月 | R2: 3月 | S2: 4月 | T2: ←目標の月へジャンプ
E3: =SUM(F7:F18) -> 291 | G3: 30000000 | H3: =SUM(AD7:AD18)*100 -> 0.999996 | I3: =G3*H3 -> 29999880 | K3: =SUM(J21:J385) -> 21736375 | M3: =K3-G3 -> -8263625 | P3: 5月 | Q3: 6月 | R3: 7月 | S3: 8月
P4: 9月 | Q4: 10月 | R4: 11月 | S4: 12月
B6: 平均日次売上目標額 | E6: 月 | F6: 月次営業日数 | G6: 平均月間売上目標額 | H6: 月次繁閑期%設定 | I6: 月次目標売上 | K6: 日次目標売上 | M6: 月次売上実績 | N6: 月間KGI | P6: 月次平均%(繁閑期) | Q6: 月次実質%
B7: ② ÷ ① | E7: 1月 | F7: =COUNTIF(D21:D51,1) -> 22 | G7: =$B$8*F7 -> 2268041.2 | H7: 0.85 | I7: =G7*H7 -> 1927835.1 | K7: =I7/F7 -> 87628.866 | M7: =SUM(J21:J51) -> 1783850 | N7: =M7-I7 -> -143985.05 | P7: =M7/G7 -> 0.78651568 | Q7: =M7/I7 -> 0.92531257 | R7: 1 | AA7: =TEXT(K7,"¥0") -> ¥87629 | AD7: =(H7/100)*AE7 -> 0.0007083305 | AE7: 0.083333
B8: =G3/E3 -> 103092.78 | E8: 2月 | F8: =COUNTIF(D52:D79,1) -> 23 | G8: =$B$8*F8 -> 2371134 | H8: 0.85 | I8: =G8*H8 -> 2015463.9 | K8: =I8/F8 -> 87628.866 | M8: =SUM(J52:J79) -> 1822300 | N8: =M8-I8 -> -193163.92 | P8: =M8/G8 -> 0.76853522 | Q8: =M8/I8 -> 0.90415908 | R8: 2 | AA8: =TEXT(K8,"¥0") -> ¥87629 | AD8: =(H8/100)*AE8 -> 0.0007083305 | AE8: 0.083333
E9: 3月 | F9: =COUNTIF(D80:D110,1) -> 26 | G9: =$B$8*F9 -> 2680412.4 | H9: 1 | I9: =G9*H9 -> 2680412.4 | K9: =I9/F9 -> 103092.78 | M9: =SUM(J80:J110) -> 2158500 | N9: =M9-I9 -> -521912.37 | P9: =M9/G9 -> 0.80528654 | Q9: =M9/I9 -> 0.80528654 | R9: 3 | AA9: =TEXT(K9,"¥0") -> ¥103093 | AD9: =(H9/100)*AE9 -> 0.00083333 | AE9: 0.083333
E10: 4月 | F10: =COUNTIF(D111:D140,1) -> 25 | G10: =$B$8*F10 -> 2577319.6 | H10: 1.1 | I10: =G10*H10 -> 2835051.5 | K10: =I10/F10 -> 113402.06 | M10: =SUM(J111:J140) -> 2262450 | N10: =M10-I10 -> -572601.55 | P10: =M10/G10 -> 0.8778306 | Q10: =M10/I10 -> 0.79802782 | R10: 4 | AA10: =TEXT(K10,"¥0") -> ¥113402 | AD10: =(H10/100)*AE10 -> 0.000916663 | AE10: 0.083333
E11: 5月 | F11: =COUNTIF(D141:D171,1) -> 26 | G11: =$B$8*F11 -> 2680412.4 | H11: 1 | I11: =G11*H11 -> 2680412.4 | K11: =I11/F11 -> 103092.78 | M11: =SUM(J141:J171) -> 2494050 | N11: =M11-I11 -> -186362.37 | P11: =M11/G11 -> 0.9304725 | Q11: =M11/I11 -> 0.9304725 | R11: 5 | AA11: =TEXT(K11,"¥0") -> ¥103093 | AD11: =(H11/100)*AE11 -> 0.00083333 | AE11: 0.083333
E12: 6月 | F12: =COUNTIF(D172:D201,1) -> 25 | G12: =$B$8*F12 -> 2577319.6 | H12: 0.85 | I12: =G12*H12 -> 2190721.6 | K12: =I12/F12 -> 87628.866 | M12: =SUM(J172:J201) -> 2396250 | N12: =M12-I12 -> 205528.35 | P12: =M12/G12 -> 0.929745 | Q12: =M12/I12 -> 1.0938176 | R12: 6 | AA12: =TEXT(K12,"¥0") -> ¥87629 | AD12: =(H12/100)*AE12 -> 0.0007083305 | AE12: 0.083333
E13: 7月 | F13: =COUNTIF(D202:D232,1) -> 25 | G13: =$B$8*F13 -> 2577319.6 | H13: 1.1 | I13: =G13*H13 -> 2835051.5 | K13: =I13/F13 -> 113402.06 | M13: =SUM(J202:J232) -> 2307750 | N13: =M13-I13 -> -527301.55 | P13: =M13/G13 -> 0.895407 | Q13: =M13/I13 -> 0.81400636 | R13: 7 | AA13: =TEXT(K13,"¥0") -> ¥113402 | AD13: =(H13/100)*AE13 -> 0.000916663 | AE13: 0.083333
E14: 8月 | F14: =COUNTIF(D233:D263,1) -> 24 | G14: =$B$8*F14 -> 2474226.8 | H14: 1 | I14: =G14*H14 -> 2474226.8 | K14: =I14/F14 -> 103092.78 | M14: =SUM(J233:J263) -> 1980325 | N14: =M14-I14 -> -493901.8 | P14: =M14/G14 -> 0.80038135 | Q14: =M14/I14 -> 0.80038135 | R14: 8 | AA14: =TEXT(K14,"¥0") -> ¥103093 | AD14: =(H14/100)*AE14 -> 0.00083333 | AE14: 0.083333
E15: 9 月 | F15: =COUNTIF(D264:D293,1) -> 23 | G15: =$B$8*F15 -> 2371134 | H15: 1 | I15: =G15*H15 -> 2371134 | K15: =I15/F15 -> 103092.78 | M15: =SUM(J264:J293) -> 1800300 | N15: =M15-I15 -> -570834.02 | P15: =M15/G15 -> 0.75925696 | Q15: =M15/I15 -> 0.75925696 | R15: 9 | AA15: =TEXT(K15,"¥0") -> ¥103093 | AD15: =(H15/100)*AE15 -> 0.00083333 | AE15: 0.083333
E16: 10月 | F16: =COUNTIF(D294:D324,1) -> 26 | G16: =$B$8*F16 -> 2680412.4 | H16: 1.1 | I16: =G16*H16 -> 2948453.6 | K16: =I16/F16 -> 113402.06 | M16: =SUM(J294:J324) -> 2123750 | N16: =M16-I16 -> -824703.61 | P16: =M16/G16 -> 0.79232212 | Q16: =M16/I16 -> 0.72029283 | R16: 10 | AA16: =TEXT(K16,"¥0") -> ¥113402 | AD16: =(H16/100)*AE16 -> 0.000916663 | AE16: 0.083333
E17: 11月 | F17: =COUNTIF(D325:D354,1) -> 22 | G17: =$B$8*F17 -> 2268041.2 | H17: 1 | I17: =G17*H17 -> 2268041.2 | K17: =I17/F17 -> 103092.78 | M17: =SUM(J325:J354) -> 606850 | N17: =M17-I17 -> -1661191.2 | P17: =M17/G17 -> 0.26756568 | Q17: =M17/I17 -> 0.26756568 | R17: 11 | AA17: =TEXT(K17,"¥0") -> ¥103093 | AD17: =(H17/100)*AE17 -> 0.00083333 | AE17: 0.083333
E18: 12月 | F18: =COUNTIF(D355:D385,1) -> 24 | G18: =$B$8*F18 -> 2474226.8 | H18: 1.15 | I18: =G18*H18 -> 2845360.8 | K18: =I18/F18 -> 118556.7 | M18: =SUM(J355:J385) -> 0 | N18: =M18-I18 -> -2845360.8 | P18: =M18/G18 -> 0 | Q18: =M18/I18 -> 0 | R18: 12 | AA18: =TEXT(K18,"¥0") -> ¥118557 | AD18: =(H18/100)*AE18 -> 0.0009583295 | AE18: 0.083333
E20: 月 | F20: 日程 | G20: 曜日 | H20: 日祝日 | J20: Daily売上入力 | L20: 目標売上 | M20: 実質売上 | N20: 実質% | P20: 月次目標売上 | Q20: 月次実質売上 | R20: 月次差額 | S20: 月次達成率 | U20: 年次目標売上 | V20: 年次実質売上 | W20: 年次差額 | X20: 年次達成率 | AA20: 月 | AB20: 曜日 | AC20: 実質曜日平均売上 | AD20: 曜日回数 | AE20: 曜日毎目標売上額 | AF20: 曜日毎トータル額
C21: 1 | D21: 0 | E21: =MONTH(Y21) -> 1 | F21: =B2 -> 45658 | G21: =TEXT(Z21,"ddd") -> Wed | H21: 元旦 | L21: =IF(D21=0,0,$K$7) -> 0 | M21: =IF(D21=0,0,J21-L21) -> 0 | N21: =IFERROR(J21/L21,"¥0") -> ¥0 | P21: =IF(D21=0,0,$K$7) -> 0 | Q21: =IF(D21=0,0,$J$21) -> 0 | R21: =IF(D21=0,0,Q21-P21) -> 0 | S21: =IF(D21=0,0,Q21/P21) -> 0 | U21: =IF(D21=0,0,$L$21) -> 0 | V21: =IF(D21=0,0,$J$21) -> 0 | W21: =IF(D21=0,0,V21-U21) -> 0 | X21: =IF(D21=0,0,V21/U21) -> 0 | Y21: =B2 -> 45658 | Z21: =B2 -> 45658 | AA21: 1 | AB21: mon | AC21: =IFERROR(AVERAGEIFS(J21:J51,D21:D51,1,G21:G51,"mon"),0) -> 90400 | AD21: =COUNTIFS(D21:D51,1,G21:G51,"Mon") -> 1 | AE21: =($I$7*[1]リトローボ_実績_2024R6!AI20)/AD21 -> 0 | AF21: =AD21*AE21 -> 0 | AG21: 21〜51
C22: 2 | D22: 0 | E22: =MONTH(Y22) -> 1 | F22: =F21+1 -> 45659 | G22: =TEXT(Z22,"ddd") -> Thu | H22: 休み | L22: =IF(D22=0,0,$K$7) -> 0 | M22: =IF(D22=0,0,J22-L22) -> 0 | N22: =IFERROR(J22/L22,"¥0") -> ¥0 | P22: =IF(D22=0,0,SUM($L$21:L22)) -> 0 | Q22: =IF(D22=0,0,SUM($J$21:J22)) -> 0 | R22: =IF(D22=0,0,Q22-P22) -> 0 | S22: =IF(D22=0,0,Q22/P22) -> 0 | U22: =IF(D22=0,0,SUM($L$21:L22)) -> 0 | V22: =IF(D22=0,0,SUM($J$21:J22)) -> 0 | W22: =IF(D22=0,0,V22-U22) -> 0 | X22: =IF(D22=0,0,V22/U22) -> 0 | Y22: =Y21+1 -> 45659 | Z22: =Z21+1 -> 45659 | AA22: 1 | AB22: tue | AC22: =IFERROR(AVERAGEIFS(J21:J51,D21:D51,1,G21:G51,"tue"),0) -> 67750 | AD22: =COUNTIFS(D21:D51,1,G21:G51,"tue") -> 4 | AE22: =($I$7*[1]リトローボ_実績_2024R6!AI21)/AD22 -> 0 | AF22: =AD22*AE22 -> 0
C23: 3 | D23: 0 | E23: =MONTH(Y23) -> 1 | F23: =F22+1 -> 45660 | G23: =TEXT(Z23,"ddd") -> Fri | H23: 休み | L23: =IF(D23=0,0,$K$7) -> 0 | M23: =IF(D23=0,0,J23-L23) -> 0 | N23: =IFERROR(J23/L23,"¥0") -> ¥0 | P23: =IF(D23=0,0,SUM($L$21:L23)) -> 0 | Q23: =IF(D23=0,0,SUM($J$21:J23)) -> 0 | R23: =IF(D23=0,0,Q23-P23) -> 0 | S23: =IF(D23=0,0,Q23/P23) -> 0 | U23: =IF(D23=0,0,SUM($L$21:L23)) -> 0 | V23: =IF(D23=0,0,SUM($J$21:J23)) -> 0 | W23: =IF(D23=0,0,V23-U23) -> 0 | X23: =IF(D23=0,0,V23/U23) -> 0 | Y23: =Y22+1 -> 45660 | Z23: =Z22+1 -> 45660 | AA23: 1 | AB23: wed | AC23: =IFERROR(AVERAGEIFS(J21:J51,D21:D51,1,G21:G51,"wed"),0) -> 83862.5 | AD23: =COUNTIFS(D21:D51,1,G21:G51,"wed") -> 4 | AE23: =IFERROR(($I$7*[1]リトローボ_実績_2024R6!AI22)/AD23,0) -> 0 | AF23: =AD23*AE23 -> 0
C24: 4 | D24: 0 | E24: =MONTH(Y24) -> 1 | F24: =F23+1 -> 45661 | G24: =TEXT(Z24,"ddd") -> Sat | L24: =IF(D24=0,0,$K$7) -> 0 | M24: =IF(D24=0,0,J24-L24) -> 0 | N24: =IFERROR(J24/L24,"¥0") -> ¥0 | P24: =IF(D24=0,0,SUM($L$21:L24)) -> 0 | Q24: =IF(D24=0,0,SUM($J$21:J24)) -> 0 | R24: =IF(D24=0,0,Q24-P24) -> 0 | S24: =IF(D24=0,0,Q24/P24) -> 0 | U24: =IF(D24=0,0,SUM($L$21:L24)) -> 0 | V24: =IF(D24=0,0,SUM($J$21:J24)) -> 0 | W24: =IF(D24=0,0,V24-U24) -> 0 | X24: =IF(D24=0,0,V24/U24) -> 0 | Y24: =Y23+1 -> 45661 | Z24: =Z23+1 -> 45661 | AA24: 1 | AB24: thu | AC24: =IFERROR(AVERAGEIFS(J21:J51,D21:D51,1,G21:G51,"thu"),0) -> 78475 | AD24: =COUNTIFS(D21:D51,1,G21:G51,"thu") -> 4 | AE24: =($I$7*[1]リトローボ_実績_2024R6!AI23)/AD24 -> 0 | AF24: =AD24*AE24 -> 0
C25: 5 | D25: 0 | E25: =MONTH(Y25) -> 1 | F25: =F24+1 -> 45662 | G25: =TEXT(Z25,"ddd") -> Sun | L25: =IF(D25=0,0,$K$7) -> 0 | M25: =IF(D25=0,0,J25-L25) -> 0 | N25: =IFERROR(J25/L25,"¥0") -> ¥0 | P25: =IF(D25=0,0,SUM($L$21:L25)) -> 0 | Q25: =IF(D25=0,0,SUM($J$21:J25)) -> 0 | R25: =IF(D25=0,0,Q25-P25) -> 0 | S25: =IF(D25=0,0,Q25/P25) -> 0 | U25: =IF(D25=0,0,SUM($L$21:L25)) -> 0 | V25: =IF(D25=0,0,SUM($J$21:J25)) -> 0 | W25: =IF(D25=0,0,V25-U25) -> 0 | X25: =IF(D25=0,0,V25/U25) -> 0 | Y25: =Y24+1 -> 45662 | Z25: =Z24+1 -> 45662 | AA25: 1 | AB25: fri | AC25: =IFERROR(AVERAGEIFS(J21:J51,D21:D51,1,G21:G51,"fri"),0) -> 108412.5 | AD25: =COUNTIFS(D21:D51,1,G21:G51,"fri") -> 4 | AE25: =($I$7*[1]リトローボ_実績_2024R6!AI24)/AD25 -> 0 | AF25: =AD25*AE25 -> 0
C26: 6 | D26: 0 | E26: =MONTH(Y26) -> 1 | F26: =F25+1 -> 45663 | G26: =TEXT(Z26,"ddd") -> Mon | L26: =IF(D26=0,0,$K$7) -> 0 | M26: =IF(D26=0,0,J26-L26) -> 0 | N26: =IFERROR(J26/L26,"¥0") -> ¥0 | P26: =IF(D26=0,0,SUM($L$21:L26)) -> 0 | Q26: =IF(D26=0,0,SUM($J$21:J26)) -> 0 | R26: =IF(D26=0,0,Q26-P26) -> 0 | S26: =IF(D26=0,0,Q26/P26) -> 0 | U26: =IF(D26=0,0,SUM($L$21:L26)) -> 0 | V26: =IF(D26=0,0,SUM($J$21:J26)) -> 0 | W26: =IF(D26=0,0,V26-U26) -> 0 | X26: =IF(D26=0,0,V26/U26) -> 0 | Y26: =Y25+1 -> 45663 | Z26: =Z25+1 -> 45663 | AA26: 1 | AB26: sat | AC26: =IFERROR(AVERAGEIFS(J21:J51,D21:D51,1,G21:G51,"sat"),0) -> 62316.667 | AD26: =COUNTIFS(D21:D51,1,G21:G51,"sat") -> 3 | AE26: =($I$7*[1]リトローボ_実績_2024R6!AI25)/AD26 -> 0 | AF26: =AD26*AE26 -> 0 | AG26: 1月目標売り上げ
C27: 7 | D27: 1 | E27: =MONTH(Y27) -> 1 | F27: =F26+1 -> 45664 | G27: =TEXT(Z27,"ddd") -> Tue | J27: 47550 | L27: =IF(D27=0,0,$K$7) -> 87628.866 | M27: =IF(D27=0,0,J27-L27) -> -40078.866 | N27: =IFERROR(J27/L27,"¥0") -> 0.54262941 | P27: =IF(D27=0,0,SUM($L$21:L27)) -> 87628.866 | Q27: =IF(D27=0,0,SUM($J$21:J27)) -> 47550 | R27: =IF(D27=0,0,Q27-P27) -> -40078.866 | S27: =IF(D27=0,0,Q27/P27) -> 0.54262941 | U27: =IF(D27=0,0,SUM($L$21:L27)) -> 87628.866 | V27: =IF(D27=0,0,SUM($J$21:J27)) -> 47550 | W27: =IF(D27=0,0,V27-U27) -> -40078.866 | X27: =IF(D27=0,0,V27/U27) -> 0.54262941 | Y27: =Y26+1 -> 45664 | Z27: =Z26+1 -> 45664 | AA27: 1 | AB27: sun | AC27: =IFERROR(AVERAGEIFS(J21:J51,D21:D51,1,G21:G51,"sun"),0) -> 76250 | AD27: =IFERROR(COUNTIFS(D21:D51,1,G21:G51,"sun"),0) -> 2 | AE27: =IFERROR(($I$7*[1]リトローボ_実績_2024R6!AI26)/AD27,0) -> 0 | AF27: =SUM(AF21:AF26) -> 0 | AG27: =I7 -> 1927835.1
C28: 8 | D28: 1 | E28: =MONTH(Y28) -> 1 | F28: =F27+1 -> 45665 | G28: =TEXT(Z28,"ddd") -> Wed | J28: 36950 | L28: =IF(D28=0,0,$K$7) -> 87628.866 | M28: =IF(D28=0,0,J28-L28) -> -50678.866 | N28: =IFERROR(J28/L28,"¥0") -> 0.42166471 | P28: =IF(D28=0,0,SUM($L$21:L28)) -> 175257.73 | Q28: =IF(D28=0,0,SUM($J$21:J28)) -> 84500 | R28: =IF(D28=0,0,Q28-P28) -> -90757.732 | S28: =IF(D28=0,0,Q28/P28) -> 0.48214706 | U28: =IF(D28=0,0,SUM($L$21:L28)) -> 175257.73 | V28: =IF(D28=0,0,SUM($J$21:J28)) -> 84500 | W28: =IF(D28=0,0,V28-U28) -> -90757.732 | X28: =IF(D28=0,0,V28/U28) -> 0.48214706 | Y28: =Y27+1 -> 45665 | Z28: =Z27+1 -> 45665 | AA28: 2 | AB28: Mon | AC28: =IFERROR(AVERAGEIFS(J52:J79,D52:D79,1,G52:G79,"mon"),0) -> 0 | AD28: =COUNTIFS(D52:D79,1,G52:G79,"Mon") -> 0 | AE28: =IFERROR(($I$8*[1]リトローボ_実績_2024R6!AI27)/AD28,0) -> 0 | AF28: =AD28*AE28 -> 0 | AG28: 52〜79
C29: 9 | D29: 1 | E29: =MONTH(Y29) -> 1 | F29: =F28+1 -> 45666 | G29: =TEXT(Z29,"ddd") -> Thu | J29: 71250 | L29: =IF(D29=0,0,$K$7) -> 87628.866 | M29: =IF(D29=0,0,J29-L29) -> -16378.866 | N29: =IFERROR(J29/L29,"¥0") -> 0.81308824 | P29: =IF(D29=0,0,SUM($L$21:L29)) -> 262886.6 | Q29: =IF(D29=0,0,SUM($J$21:J29)) -> 155750 | R29: =IF(D29=0,0,Q29-P29) -> -107136.6 | S29: =IF(D29=0,0,Q29/P29) -> 0.59246078 | U29: =IF(D29=0,0,SUM($L$21:L29)) -> 262886.6 | V29: =IF(D29=0,0,SUM($J$21:J29)) -> 155750 | W29: =IF(D29=0,0,V29-U29) -> -107136.6 | X29: =IF(D29=0,0,V29/U29) -> 0.59246078 | Y29: =Y28+1 -> 45666 | Z29: =Z28+1 -> 45666 | AA29: 2 | AB29: Tue | AC29: =IFERROR(AVERAGEIFS(J53:J80,D53:D80,1,G53:G80,"tue"),0) -> 56766.667 | AD29: =COUNTIFS(D52:D79,1,G52:G79,"tue") -> 3 | AE29: =($I$8*[1]リトローボ_実績_2024R6!AI28)/AD29 -> 0 | AF29: =AD29*AE29 -> 0
C30: 10 | D30: 1 | E30: =MONTH(Y30) -> 1 | F30: =F29+1 -> 45667 | G30: =TEXT(Z30,"ddd") -> Fri | J30: 127150 | L30: =IF(D30=0,0,$K$7) -> 87628.866 | M30: =IF(D30=0,0,J30-L30) -> 39521.134 | N30: =IFERROR(J30/L30,"¥0") -> 1.4510059 | P30: =IF(D30=0,0,SUM($L$21:L30)) -> 350515.46 | Q30: =IF(D30=0,0,SUM($J$21:J30)) -> 282900 | R30: =IF(D30=0,0,Q30-P30) -> -67615.464 | S30: =IF(D30=0,0,Q30/P30) -> 0.80709706 | U30: =IF(D30=0,0,SUM($L$21:L30)) -> 350515.46 | V30: =IF(D30=0,0,SUM($J$21:J30)) -> 282900 | W30: =IF(D30=0,0,V30-U30) -> -67615.464 | X30: =IF(D30=0,0,V30/U30) -> 0.80709706 | Y30: =Y29+1 -> 45667 | Z30: =Z29+1 -> 45667 | AA30: 2 | AB30: Wed | AC30: =IFERROR(AVERAGEIFS(J52:J79,D52:D79,1,G52:G79,"wed"),0) -> 68750 | AD30: =COUNTIFS(D52:D79,1,G52:G79,"wed") -> 4 | AE30: =($I$8*[1]リトローボ_実績_2024R6!AI29)/AD30 -> 0 | AF30: =AD30*AE30 -> 0
C31: 11 | D31: 1 | E31: =MONTH(Y31) -> 1 | F31: =F30+1 -> 45668 | G31: =TEXT(Z31,"ddd") -> Sat | J31: 96850 | L31: =IF(D31=0,0,$K$7) -> 87628.866 | M31: =IF(D31=0,0,J31-L31) -> 9221.134 | N31: =IFERROR(J31/L31,"¥0") -> 1.1052294 | P31: =IF(D31=0,0,SUM($L$21:L31)) -> 438144.33 | Q31: =IF(D31=0,0,SUM($J$21:J31)) -> 379750 | R31: =IF(D31=0,0,Q31-P31) -> -58394.33 | S31: =IF(D31=0,0,Q31/P31) -> 0.86672353 | U31: =IF(D31=0,0,SUM($L$21:L31)) -> 438144.33 | V31: =IF(D31=0,0,SUM($J$21:J31)) -> 379750 | W31: =IF(D31=0,0,V31-U31) -> -58394.33 | X31: =IF(D31=0,0,V31/U31) -> 0.86672353 | Y31: =Y30+1 -> 45668 | Z31: =Z30+1 -> 45668 | AA31: 2 | AB31: Thu | AC31: =IFERROR(AVERAGEIFS(J52:J79,D52:D79,1,G52:G79,"thu"),0) -> 89987.5 | AD31: =COUNTIFS(D52:D79,1,G52:G79,"thu") -> 4 | AE31: =($I$8*[1]リトローボ_実績_2024R6!AI30)/AD31 -> 0 | AF31: =AD31*AE31 -> 0
C32: 12 | D32: 0 | E32: =MONTH(Y32) -> 1 | F32: =F31+1 -> 45669 | G32: =TEXT(Z32,"ddd") -> Sun | H32: 成人の日 | L32: =IF(D32=0,0,$K$7) -> 0 | M32: =IF(D32=0,0,J32-L32) -> 0 | N32: =IFERROR(J32/L32,"¥0") -> ¥0 | P32: =IF(D32=0,0,SUM($L$21:L32)) -> 0 | Q32: =IF(D32=0,0,SUM($J$21:J32)) -> 0 | R32: =IF(D32=0,0,Q32-P32) -> 0 | S32: =IF(D32=0,0,Q32/P32) -> 0 | U32: =IF(D32=0,0,SUM($L$21:L32)) -> 0 | V32: =IF(D32=0,0,SUM($J$21:J32)) -> 0 | W32: =IF(D32=0,0,V32-U32) -> 0 | X32: =IF(D32=0,0,V32/U32) -> 0 | Y32: =Y31+1 -> 45669 | Z32: =Z31+1 -> 45669 | AA32: 2 | AB32: Fri | AC32: =IFERROR(AVERAGEIFS(J52:J79,D52:D79,1,G52:G79,"fri"),0) -> 97600 | AD32: =COUNTIFS(D52:D79,1,G52:G79,"fri") -> 4 | AE32: =($I$8*[1]リトローボ_実績_2024R6!AI31)/AD32 -> 0 | AF32: =AD32*AE32 -> 0
C33: 13 | D33: 0 | E33: =MONTH(Y33) -> 1 | F33: =F32+1 -> 45670 | G33: =TEXT(Z33,"ddd") -> Mon | L33: =IF(D33=0,0,$K$7) -> 0 | M33: =IF(D33=0,0,J33-L33) -> 0 | N33: =IFERROR(J33/L33,"¥0") -> ¥0 | P33: =IF(D33=0,0,SUM($L$21:L33)) -> 0 | Q33: =IF(D33=0,0,SUM($J$21:J33)) -> 0 | R33: =IF(D33=0,0,Q33-P33) -> 0 | S33: =IF(D33=0,0,Q33/P33) -> 0 | U33: =IF(D33=0,0,SUM($L$21:L33)) -> 0 | V33: =IF(D33=0,0,SUM($J$21:J33)) -> 0 | W33: =IF(D33=0,0,V33-U33) -> 0 | X33: =IF(D33=0,0,V33/U33) -> 0 | Y33: =Y32+1 -> 45670 | Z33: =Z32+1 -> 45670 | AA33: 2 | AB33: Sat | AC33: =IFERROR(AVERAGEIFS(J52:J79,D52:D79,1,G52:G79,"sat"),0) -> 76175 | AD33: =COUNTIFS(D52:D79,1,G52:G79,"sat") -> 4 | AE33: =($I$8*[1]リトローボ_実績_2024R6!AI32)/AD33 -> 0 | AF33: =AD33*AE33 -> 0 | AG33: 2月目標売り上げ
C34: 14 | D34: 1 | E34: =MONTH(Y34) -> 1 | F34: =F33+1 -> 45671 | G34: =TEXT(Z34,"ddd") -> Tue | J34: 48100 | L34: =IF(D34=0,0,$K$7) -> 87628.866 | M34: =IF(D34=0,0,J34-L34) -> -39528.866 | N34: =IFERROR(J34/L34,"¥0") -> 0.54890588 | P34: =IF(D34=0,0,SUM($L$21:L34)) -> 525773.2 | Q34: =IF(D34=0,0,SUM($J$21:J34)) -> 427850 | R34: =IF(D34=0,0,Q34-P34) -> -97923.196 | S34: =IF(D34=0,0,Q34/P34) -> 0.81375392 | U34: =IF(D34=0,0,SUM($L$21:L34)) -> 525773.2 | V34: =IF(D34=0,0,SUM($J$21:J34)) -> 427850 | W34: =IF(D34=0,0,V34-U34) -> -97923.196 | X34: =IF(D34=0,0,V34/U34) -> 0.81375392 | Y34: =Y33+1 -> 45671 | Z34: =Z33+1 -> 45671 | AA34: 2 | AB34: Sun | AC34: =IFERROR(AVERAGEIFS(J52:J79,D52:D79,1,G52:G79,"sun"),0) -> 80487.5 | AD34: =IFERROR(COUNTIFS(D52:D79,1,G52:G79,"sun"),0) -> 4 | AE34: =IFERROR(($I$8*[1]リトローボ_実績_2024R6!AI33)/AD34,0) -> 0 | AF34: =SUM(AF28:AF33) -> 0 | AG34: =I8 -> 2015463.9
C35: 15 | D35: 1 | E35: =MONTH(Y35) -> 1 | F35: =F34+1 -> 45672 | G35: =TEXT(Z35,"ddd") -> Wed | J35: 86400 | L35: =IF(D35=0,0,$K$7) -> 87628.866 | M35: =IF(D35=0,0,J35-L35) -> -1228.866 | N35: =IFERROR(J35/L35,"¥0") -> 0.98597647 | P35: =IF(D35=0,0,SUM($L$21:L35)) -> 613402.06 | Q35: =IF(D35=0,0,SUM($J$21:J35)) -> 514250 | R35: =IF(D35=0,0,Q35-P35) -> -99152.062 | S35: =IF(D35=0,0,Q35/P35) -> 0.83835714 | U35: =IF(D35=0,0,SUM($L$21:L35)) -> 613402.06 | V35: =IF(D35=0,0,SUM($J$21:J35)) -> 514250 | W35: =IF(D35=0,0,V35-U35) -> -99152.062 | X35: =IF(D35=0,0,V35/U35) -> 0.83835714 | Y35: =Y34+1 -> 45672 | Z35: =Z34+1 -> 45672 | AA35: 3 | AB35: Mon | AC35: =IFERROR(AVERAGEIFS(J80:J110,D80:D110,1,G80:G110,"mon"),0) -> 0 | AD35: =COUNTIFS(D80:D110,1,G80:G110,"Mon") -> 0 | AE35: =IFERROR(($I$9*[1]リトローボ_実績_2024R6!AI34)/AD35,0) -> 0 | AF35: =AD35*AE35 -> 0 | AG35: 80〜110
C36: 16 | D36: 1 | E36: =MONTH(Y36) -> 1 | F36: =F35+1 -> 45673 | G36: =TEXT(Z36,"ddd") -> Thu | J36: 48200 | L36: =IF(D36=0,0,$K$7) -> 87628.866 | M36: =IF(D36=0,0,J36-L36) -> -39428.866 | N36: =IFERROR(J36/L36,"¥0") -> 0.55004706 | P36: =IF(D36=0,0,SUM($L$21:L36)) -> 701030.93 | Q36: =IF(D36=0,0,SUM($J$21:J36)) -> 562450 | R36: =IF(D36=0,0,Q36-P36) -> -138580.93 | S36: =IF(D36=0,0,Q36/P36) -> 0.80231838 | U36: =IF(D36=0,0,SUM($L$21:L36)) -> 701030.93 | V36: =IF(D36=0,0,SUM($J$21:J36)) -> 562450 | W36: =IF(D36=0,0,V36-U36) -> -138580.93 | X36: =IF(D36=0,0,V36/U36) -> 0.80231838 | Y36: =Y35+1 -> 45673 | Z36: =Z35+1 -> 45673 | AA36: 3 | AB36: Tue | AC36: =IFERROR(AVERAGEIFS(J80:J110,D80:D110,1,G80:G110,"tue"),0) -> 70550 | AD36: =COUNTIFS(D80:D110,1,G80:G110,"tue") -> 4 | AE36: =($I$9*[1]リトローボ_実績_2024R6!AI35)/AD36 -> 0 | AF36: =AD36*AE36 -> 0
C37: 17 | D37: 1 | E37: =MONTH(Y37) -> 1 | F37: =F36+1 -> 45674 | G37: =TEXT(Z37,"ddd") -> Fri | J37: 68350 | L37: =IF(D37=0,0,$K$7) -> 87628.866 | M37: =IF(D37=0,0,J37-L37) -> -19278.866 | N37: =IFERROR(J37/L37,"¥0") -> 0.77999412 | P37: =IF(D37=0,0,SUM($L$21:L37)) -> 788659.79 | Q37: =IF(D37=0,0,SUM($J$21:J37)) -> 630800 | R37: =IF(D37=0,0,Q37-P37) -> -157859.79 | S37: =IF(D37=0,0,Q37/P37) -> 0.79983791 | U37: =IF(D37=0,0,SUM($L$21:L37)) -> 788659.79 | V37: =IF(D37=0,0,SUM($J$21:J37)) -> 630800 | W37: =IF(D37=0,0,V37-U37) -> -157859.79 | X37: =IF(D37=0,0,V37/U37) -> 0.79983791 | Y37: =Y36+1 -> 45674 | Z37: =Z36+1 -> 45674 | AA37: 3 | AB37: Wed | AC37: =IFERROR(AVERAGEIFS(J80:J110,D80:D110,1,G80:G110,"wed"),0) -> 59562.5 | AD37: =COUNTIFS(D80:D110,1,G80:G110,"wed") -> 4 | AE37: =($I$9*[1]リトローボ_実績_2024R6!AI36)/AD37 -> 0 | AF37: =AD37*AE37 -> 0
C38: 18 | D38: 1 | E38: =MONTH(Y38) -> 1 | F38: =F37+1 -> 45675 | G38: =TEXT(Z38,"ddd") -> Sat | J38: 45750 | L38: =IF(D38=0,0,$K$7) -> 87628.866 | M38: =IF(D38=0,0,J38-L38) -> -41878.866 | N38: =IFERROR(J38/L38,"¥0") -> 0.52208824 | P38: =IF(D38=0,0,SUM($L$21:L38)) -> 876288.66 | Q38: =IF(D38=0,0,SUM($J$21:J38)) -> 676550 | R38: =IF(D38=0,0,Q38-P38) -> -199738.66 | S38: =IF(D38=0,0,Q38/P38) -> 0.77206294 | U38: =IF(D38=0,0,SUM($L$21:L38)) -> 876288.66 | V38: =IF(D38=0,0,SUM($J$21:J38)) -> 676550 | W38: =IF(D38=0,0,V38-U38) -> -199738.66 | X38: =IF(D38=0,0,V38/U38) -> 0.77206294 | Y38: =Y37+1 -> 45675 | Z38: =Z37+1 -> 45675 | AA38: 3 | AB38: Thu | AC38: =IFERROR(AVERAGEIFS(J80:J110,D80:D110,1,G80:G110,"thu"),0) -> 79837.5 | AD38: =COUNTIFS(D80:D110,1,G80:G110,"thu") -> 4 | AE38: =($I$9*[1]リトローボ_実績_2024R6!AI37)/AD38 -> 0 | AF38: =AD38*AE38 -> 0
C39: 19 | D39: 1 | E39: =MONTH(Y39) -> 1 | F39: =F38+1 -> 45676 | G39: =TEXT(Z39,"ddd") -> Sun | J39: 50250 | L39: =IF(D39=0,0,$K$7) -> 87628.866 | M39: =IF(D39=0,0,J39-L39) -> -37378.866 | N39: =IFERROR(J39/L39,"¥0") -> 0.57344118 | P39: =IF(D39=0,0,SUM($L$21:L39)) -> 963917.53 | Q39: =IF(D39=0,0,SUM($J$21:J39)) -> 726800 | R39: =IF(D39=0,0,Q39-P39) -> -237117.53 | S39: =IF(D39=0,0,Q39/P39) -> 0.75400642 | U39: =IF(D39=0,0,SUM($L$21:L39)) -> 963917.53 | V39: =IF(D39=0,0,SUM($J$21:J39)) -> 726800 | W39: =IF(D39=0,0,V39-U39) -> -237117.53 | X39: =IF(D39=0,0,V39/U39) -> 0.75400642 | Y39: =Y38+1 -> 45676 | Z39: =Z38+1 -> 45676 | AA39: 3 | AB39: Fri | AC39: =IFERROR(AVERAGEIFS(J80:J110,D80:D110,1,G80:G110,"fri"),0) -> 123225 | AD39: =COUNTIFS(D80:D110,1,G80:G110,"fri") -> 4 | AE39: =($I$9*[1]リトローボ_実績_2024R6!AI38)/AD39 -> 0 | AF39: =AD39*AE39 -> 0
C40: 20 | D40: 1 | E40: =MONTH(Y40) -> 1 | F40: =F39+1 -> 45677 | G40: =TEXT(Z40,"ddd") -> Mon | J40: 90400 | L40: =IF(D40=0,0,$K$7) -> 87628.866 | M40: =IF(D40=0,0,J40-L40) -> 2771.134 | N40: =IFERROR(J40/L40,"¥0") -> 1.0316235 | P40: =IF(D40=0,0,SUM($L$21:L40)) -> 1051546.4 | Q40: =IF(D40=0,0,SUM($J$21:J40)) -> 817200 | R40: =IF(D40=0,0,Q40-P40) -> -234346.39 | S40: =IF(D40=0,0,Q40/P40) -> 0.77714118 | U40: =IF(D40=0,0,SUM($L$21:L40)) -> 1051546.4 | V40: =IF(D40=0,0,SUM($J$21:J40)) -> 817200 | W40: =IF(D40=0,0,V40-U40) -> -234346.39 | X40: =IF(D40=0,0,V40/U40) -> 0.77714118 | Y40: =Y39+1 -> 45677 | Z40: =Z39+1 -> 45677 | AA40: 3 | AB40: Sat | AC40: =IFERROR(AVERAGEIFS(J80:J110,D80:D110,1,G80:G110,"sat"),0) -> 65640 | AD40: =COUNTIFS(D80:D110,1,G80:G110,"sat") -> 5 | AE40: =($I$9*[1]リトローボ_実績_2024R6!AI39)/AD40 -> 0 | AF40: =AD40*AE40 -> 0 | AG40: 3月目標売り上げ
C41: 21 | D41: 1 | E41: =MONTH(Y41) -> 1 | F41: =F40+1 -> 45678 | G41: =TEXT(Z41,"ddd") -> Tue | J41: 89450 | L41: =IF(D41=0,0,$K$7) -> 87628.866 | M41: =IF(D41=0,0,J41-L41) -> 1821.134 | N41: =IFERROR(J41/L41,"¥0") -> 1.0207824 | P41: =IF(D41=0,0,SUM($L$21:L41)) -> 1139175.3 | Q41: =IF(D41=0,0,SUM($J$21:J41)) -> 906650 | R41: =IF(D41=0,0,Q41-P41) -> -232525.26 | S41: =IF(D41=0,0,Q41/P41) -> 0.79588281 | U41: =IF(D41=0,0,SUM($L$21:L41)) -> 1139175.3 | V41: =IF(D41=0,0,SUM($J$21:J41)) -> 906650 | W41: =IF(D41=0,0,V41-U41) -> -232525.26 | X41: =IF(D41=0,0,V41/U41) -> 0.79588281 | Y41: =Y40+1 -> 45678 | Z41: =Z40+1 -> 45678 | AA41: 3 | AB41: Sun | AC41: =IFERROR(AVERAGEIFS(J80:J110,D80:D110,1,G80:G110,"sun"),0) -> 99520 | AD41: =IFERROR(COUNTIFS(D80:D110,1,G80:G110,"sun"),0) -> 5 | AE41: =IFERROR(($I$9*[1]リトローボ_実績_2024R6!AI40)/AD41,0) -> 0 | AF41: =SUM(AF35:AF40) -> 0 | AG41: =I9 -> 2680412.4
C42: 22 | D42: 1 | E42: =MONTH(Y42) -> 1 | F42: =F41+1 -> 45679 | G42: =TEXT(Z42,"ddd") -> Wed | J42: 134500 | L42: =IF(D42=0,0,$K$7) -> 87628.866 | M42: =IF(D42=0,0,J42-L42) -> 46871.134 | N42: =IFERROR(J42/L42,"¥0") -> 1.5348824 | P42: =IF(D42=0,0,SUM($L$21:L42)) -> 1226804.1 | Q42: =IF(D42=0,0,SUM($J$21:J42)) -> 1041150 | R42: =IF(D42=0,0,Q42-P42) -> -185654.12 | S42: =IF(D42=0,0,Q42/P42) -> 0.84866849 | U42: =IF(D42=0,0,SUM($L$21:L42)) -> 1226804.1 | V42: =IF(D42=0,0,SUM($J$21:J42)) -> 1041150 | W42: =IF(D42=0,0,V42-U42) -> -185654.12 | X42: =IF(D42=0,0,V42/U42) -> 0.84866849 | Y42: =Y41+1 -> 45679 | Z42: =Z41+1 -> 45679 | AA42: 4 | AB42: Mon | AC42: =IFERROR(AVERAGEIFS(J111:J140,D111:D140,1,G111:G140,"mon"),0) -> 0 | AD42: =COUNTIFS(D111:D140,1,G111:G140,"Mon") -> 0 | AE42: =IFERROR(($I$10*[1]リトローボ_実績_2024R6!AI41)/AD42,0) -> 0 | AF42: =AD42*AE42 -> 0 | AG42: 111〜140
C43: 23 | D43: 1 | E43: =MONTH(Y43) -> 1 | F43: =F42+1 -> 45680 | G43: =TEXT(Z43,"ddd") -> Thu | J43: 85000 | L43: =IF(D43=0,0,$K$7) -> 87628.866 | M43: =IF(D43=0,0,J43-L43) -> -2628.866 | N43: =IFERROR(J43/L43,"¥0") -> 0.97 | P43: =IF(D43=0,0,SUM($L$21:L43)) -> 1314433 | Q43: =IF(D43=0,0,SUM($J$21:J43)) -> 1126150 | R43: =IF(D43=0,0,Q43-P43) -> -188282.99 | S43: =IF(D43=0,0,Q43/P43) -> 0.85675725 | U43: =IF(D43=0,0,SUM($L$21:L43)) -> 1314433 | V43: =IF(D43=0,0,SUM($J$21:J43)) -> 1126150 | W43: =IF(D43=0,0,V43-U43) -> -188282.99 | X43: =IF(D43=0,0,V43/U43) -> 0.85675725 | Y43: =Y42+1 -> 45680 | Z43: =Z42+1 -> 45680 | AA43: 4 | AB43: Tue | AC43: =IFERROR(AVERAGEIFS(J111:J140,D111:D140,1,G111:G140,"tue"),0) -> 77012.5 | AD43: =COUNTIFS(D111:D140,1,G111:G140,"tue") -> 4 | AE43: =($I$10*[1]リトローボ_実績_2024R6!AI42)/AD43 -> 0 | AF43: =AD43*AE43 -> 0
...

Sheet 実績_2024R6
B2: 45292 | E2: ①年間営業日 | G2: ②年間目標売上 | I2: 年間売上％設定 | M2: 年間売上合計 | O2: 年間実質売上 | Q2: 年間利益率 | R2: 年間予想利益額
E3: =SUM(F6:F17) -> 291 | G3: =M3 -> 29397780 | I3: =SUM(AD6:AD17)*100 -> 0.9999996 | K3: =G3*I3 -> 29397768 | M3: =SUM(J20:J385) -> 29397780 | O3: =M3-G3 -> 0 | Q3: 0.21 | R3: =M3*Q3 -> 6173533.8
B5: 平均日次売上目標額 | E5: 月 | F5: 月次営業日数 | G5: 平均月間売上目標額 | H5: 月次繁閑期%設定 | J5: 月次目標売上 | K5: 日次目標売上 | M5: 月次売上 | N5: 月間差額 | P5: 月次実質% | R5: 1日の売上目標値 参考例 | AC5: =TEXT(K6,"¥0") -> ¥90921
B6: ② ÷ ① | E6: 1月 | F6: =COUNTIF(D20:D50,1) -> 21 | G6: =$B$7*F6 -> 2121489.3 | H6: 0.9 | J6: =G6*H6 -> 1909340.4 | K6: =J6/F6 -> 90920.969 | M6: =SUM(J20:J50) -> 1903700 | N6: =M6-J6 -> -5640.3505 | P6: =M6/G6 -> 0.89734132 | R6: 目標売上 | T6: ¥233564 | V6: 0.76 | AC6: =TEXT(K7,"¥0") -> ¥85870 | AD6: =(H6/100)*AE6 -> 0.0007499997 | AE6: 0.0833333
B7: =G3/E3 -> 101023.3 | E7: 2月 | F7: =COUNTIF(D51:D79,1) -> 25 | G7: =$B$7*F7 -> 2525582.5 | H7: 0.85 | J7: =G7*H7 -> 2146745.1 | K7: =J7/F7 -> 85869.804 | M7: =SUM(J51:J79) -> 2252350 | N7: =M7-J7 -> 105604.9 | P7: =M7/G7 -> 0.89181408 | T7: =T6*V6 -> 177508.64 | AC7: =TEXT(K8,"¥0") -> ¥101023 | AD7: =(H7/100)*AE7 -> 0.00070833305 | AE7: 0.0833333
E8: 3月 | F8: =COUNTIF(D80:D110,1) -> 25 | G8: =$B$7*F8 -> 2525582.5 | H8: 1 | J8: =G8*H8 -> 2525582.5 | K8: =J8/F8 -> 101023.3 | M8: =SUM(J80:J110) -> 2500050 | N8: =M8-J8 -> -25532.474 | P8: =M8/G8 -> 0.98989046 | R8: 差額 | T8: =T9-T6 -> 87436 | AC8: =TEXT(K9,"¥0") -> ¥106074 | AD8: =(H8/100)*AE8 -> 0.000833333 | AE8: 0.0833333
E9: 4月 | F9: =COUNTIF(D111:D140,1) -> 25 | G9: =$B$7*F9 -> 2525582.5 | H9: 1.05 | J9: =G9*H9 -> 2651861.6 | K9: =J9/F9 -> 106074.46 | M9: =SUM(J111:J140) -> 2732600 | N9: =M9-J9 -> 80738.402 | P9: =M9/G9 -> 1.0819682 | R9: 仮1日売上総合計 | T9: =SUM(V11:V16) -> 321000 | AC9: =TEXT(K10,"¥0") -> ¥101023 | AD9: =(H9/100)*AE9 -> 0.00087499965 | AE9: 0.0833333
E10: 5月 | F10: =COUNTIF(D141:D171,1) -> 25 | G10: =$B$7*F10 -> 2525582.5 | H10: 1 | J10: =G10*H10 -> 2525582.5 | K10: =J10/F10 -> 101023.3 | M10: =SUM(J141:J171) -> 2920150 | N10: =M10-J10 -> 394567.53 | P10: =M10/G10 -> 1.1562283 | R10: 項目 | S10: 仮客単価 | T10: 集客数 | V10: 仮1日の売上小計 | AC10: =TEXT(K11,"¥0") -> ¥90921 | AD10: =(H10/100)*AE10 -> 0.000833333 | AE10: 0.0833333
E11: 6月 | F11: =COUNTIF(D172:D201,1) -> 26 | G11: =$B$7*F11 -> 2626605.8 | H11: 0.9 | J11: =G11*H11 -> 2363945.2 | K11: =J11/F11 -> 90920.969 | M11: =SUM(J172:J201) -> 3064200 | N11: =M11-J11 -> 700254.8 | P11: =M11/G11 -> 1.1666006 | R11: ランチ | S11: 1100 | T11: 60 | V11: =S11*T11 -> 66000 | AC11: =TEXT(K12,"¥0") -> ¥95972 | AD11: =(H11/100)*AE11 -> 0.0007499997 | AE11: 0.0833333
E12: 7月 | F12: =COUNTIF(D202:D232,1) -> 25 | G12: =$B$7*F12 -> 2525582.5 | H12: 0.95 | J12: =G12*H12 -> 2399303.4 | K12: =J12/F12 -> 95972.134 | M12: =SUM(J202:J232) -> 2392050 | N12: =M12-J12 -> -7253.3505 | P12: =M12/G12 -> 0.94712805 | R12: ディナー | S12: 4500 | T12: 20 | V12: =S12*T12 -> 90000 | AC12: =TEXT(K13,"¥0") -> ¥80819 | AD12: =(H12/100)*AE12 -> 0.00079166635 | AE12: 0.0833333
E13: 8月 | F13: =COUNTIF(D233:D263,1) -> 22 | G13: =$B$7*F13 -> 2222512.6 | H13: 0.8 | J13: =G13*H13 -> 1778010.1 | K13: =J13/F13 -> 80818.639 | M13: =SUM(J233:J263) -> 2064530 | N13: =M13-J13 -> 286519.94 | P13: =M13/G13 -> 0.92891713 | R13: Party 5500 | S13: 5500 | T13: 30 | V13: =S13*T13 -> 165000 | AC13: =TEXT(K14,"¥0") -> ¥95972 | AD13: =(H13/100)*AE13 -> 0.0006666664 | AE13: 0.0833333
E14: 9 月 | F14: =COUNTIF(D264:D293,1) -> 23 | G14: =$B$7*F14 -> 2323535.9 | H14: 0.95 | J14: =G14*H14 -> 2207359.1 | K14: =J14/F14 -> 95972.134 | M14: =SUM(J264:J293) -> 2319650 | N14: =M14-J14 -> 112290.92 | P14: =M14/G14 -> 0.9983276 | T14: 0 | V14: =S14*T14 -> 0 | AC14: =TEXT(K15,"¥0") -> ¥126279 | AD14: =(H14/100)*AE14 -> 0.00079166635 | AE14: 0.0833333
E15: 10月 | F15: =COUNTIF(D294:D324,1) -> 26 | G15: =$B$7*F15 -> 2626605.8 | H15: 1.25 | J15: =G15*H15 -> 3283257.2 | K15: =J15/F15 -> 126279.12 | M15: =SUM(J294:J324) -> 2672000 | N15: =M15-J15 -> -611257.22 | P15: =M15/G15 -> 1.0172825 | T15: 0 | V15: =S15*T15 -> 0 | AC15: =TEXT(K16,"¥0") -> ¥106074 | AD15: =(H15/100)*AE15 -> 0.0010416662 | AE15: 0.0833333
E16: 11月 | F16: =COUNTIF(D325:D354,1) -> 24 | G16: =$B$7*F16 -> 2424559.2 | H16: 1.05 | J16: =G16*H16 -> 2545787.1 | K16: =J16/F16 -> 106074.46 | M16: =SUM(J325:J354) -> 2210250 | N16: =M16-J16 -> -335537.13 | P16: =M16/G16 -> 0.91160901 | T16: 0 | V16: =S16*T16 -> 0 | AC16: =TEXT(K17,"¥0") -> ¥131330 | AD16: =(H16/100)*AE16 -> 0.00087499965 | AE16: 0.0833333
E17: 12月 | F17: =COUNTIF(D355:D385,1) -> 24 | G17: =$B$7*F17 -> 2424559.2 | H17: 1.3 | J17: =G17*H17 -> 3151926.9 | K17: =J17/F17 -> 131330.29 | M17: =SUM(J355:J385) -> 2366250 | N17: =M17-J17 -> -785676.93 | P17: =M17/G17 -> 0.97595061 | AD17: =(H17/100)*AE17 -> 0.0010833329 | AE17: 0.0833333
E19: 月 | F19: 日程 | G19: 曜日 | H19: 休店日理由 | J19: Daily売上入力 | L19: 目標売上 KPI | M19: 日次実質売上 | N19: 実質% | P19: 月次目標売上 | Q19: 月次実質売上 | R19: 月次差額(勝率) | S19: 月次実質% | U19: 年次目標売上 | V19: 年次実質売上 | W19: 年次差額(勝率) | X19: 年次実質% | AC19: 月 | AD19: 曜日 | AE19: 平均売上 | AF19: 曜日回数 | AH19: 曜日合計額 | AI19: 加重比率
C20: 1 | D20: 0 | E20: =TEXT(AA20,"m") -> 1 | F20: =B2 -> 45292 | G20: =TEXT(Z20,"ddd") -> Mon | H20: 元旦 | J20: 0 | L20: =IF(D20=0,0,$K$6) -> 0 | M20: =IF(D20=0,0,J20-L20) -> 0 | N20: =IFERROR(J20/L20,"0%") -> 0% | P20: =IF(D20=0,0,$K$6) -> 0 | Q20: =IF(D20=0,0,$J$20) -> 0 | R20: =IF(D20=0,0,Q20-P20) -> 0 | S20: =IFERROR(Q20/P20,"0%") -> 0% | U20: =IF(D20=0,0,$L$20) -> 0 | V20: =IF(D20=0,0,$J$20) -> 0 | W20: =IF(D20=0,0,V20-U20) -> 0 | X20: =IFERROR(V20/U20,"0%") -> 0% | Z20: =B2 -> 45292 | AA20: =B2 -> 45292 | AB20: 45292 | AC20: 1 | AD20: 月 | AE20: =IFERROR(AVERAGEIFS(J20:J50,D20:D50,1,G20:G50,"mon"),0) -> 0 | AF20: =COUNTIFS(D20:D50,1,G20:G50,"Mon") -> 0 | AG20: =SUMIFS(J20:J50,D20:D50,1,G20:G50,"mon") -> 0 | AH20: =AE20*AF20 -> 0 | AI20: =AH20/$M$6 -> 0 | AJ20: =SUM(AI20:AI26) -> 1
C21: =C20+1 -> 2 | D21: 0 | E21: =TEXT(AA21,"m") -> 1 | F21: =F20+1 -> 45293 | G21: =TEXT(Z21,"ddd") -> Tue | H21: 休み | J21: 0 | L21: =IF(D21=0,0,$K$6) -> 0 | M21: =IF(D21=0,0,J21-L21) -> 0 | N21: =IFERROR(J21/L21,"0%") -> 0% | P21: =IF(D21=0,0,SUM($L$20:L21)) -> 0 | Q21: =IF(D21=0,0,SUM($J$20:J21)) -> 0 | R21: =IF(D21=0,0,Q21-P21) -> 0 | S21: =IFERROR(Q21/P21,"0%") -> 0% | U21: =IF(D21=0,0,SUM($L$20:L21)) -> 0 | V21: =IF(D21=0,0,SUM($J$20:J21)) -> 0 | W21: =IF(D21=0,0,V21-U21) -> 0 | X21: =IFERROR(V21/U21,"0%") -> 0% | Z21: =Z20+1 -> 45293 | AA21: =AA20+1 -> 45293 | AB21: 45293 | AC21: 1 | AD21: 火 | AE21: =IFERROR(AVERAGEIFS(J20:J50,D20:D50,1,G20:G50,"tue"),0) -> 88337.5 | AF21: =COUNTIFS(D20:D50,1,G20:G50,"Tue") -> 4 | AH21: =AE21*AF21 -> 353350 | AI21: =AH21/$M$6 -> 0.18561223
C22: =C21+1 -> 3 | D22: 0 | E22: =TEXT(AA22,"m") -> 1 | F22: =F21+1 -> 45294 | G22: =TEXT(Z22,"ddd") -> Wed | H22: 休み | J22: 0 | L22: =IF(D22=0,0,$K$6) -> 0 | M22: =IF(D22=0,0,J22-L22) -> 0 | N22: =IFERROR(J22/L22,"0%") -> 0% | P22: =IF(D22=0,0,SUM($L$20:L22)) -> 0 | Q22: =IF(D22=0,0,SUM($J$20:J22)) -> 0 | R22: =IF(D22=0,0,Q22-P22) -> 0 | S22: =IFERROR(Q22/P22,"0%") -> 0% | U22: =IF(D22=0,0,SUM($L$20:L22)) -> 0 | V22: =IF(D22=0,0,SUM($J$20:J22)) -> 0 | W22: =IF(D22=0,0,V22-U22) -> 0 | X22: =IFERROR(V22/U22,"0%") -> 0% | Z22: =Z21+1 -> 45294 | AA22: =AA21+1 -> 45294 | AB22: 45294 | AC22: 1 | AD22: 水 | AE22: =IFERROR(AVERAGEIFS(J20:J50,D20:D50,1,G20:G50,"wed"),0) -> 90283.333 | AF22: =COUNTIFS(D20:D50,1,G20:G50,"wed") -> 3 | AH22: =AE22*AF22 -> 270850 | AI22: =AH22/$M$6 -> 0.14227557
C23: =C22+1 -> 4 | D23: 0 | E23: =TEXT(AA23,"m") -> 1 | F23: =F22+1 -> 45295 | G23: =TEXT(Z23,"ddd") -> Thu | H23: 祝日 | J23: 0 | L23: =IF(D23=0,0,$K$6) -> 0 | M23: =IF(D23=0,0,J23-L23) -> 0 | N23: =IFERROR(J23/L23,"0%") -> 0% | P23: =IF(D23=0,0,SUM($L$20:L23)) -> 0 | Q23: =IF(D23=0,0,SUM($J$20:J23)) -> 0 | R23: =IF(D23=0,0,Q23-P23) -> 0 | S23: =IFERROR(Q23/P23,"0%") -> 0% | U23: =IF(D23=0,0,SUM($L$20:L23)) -> 0 | V23: =IF(D23=0,0,SUM($J$20:J23)) -> 0 | W23: =IF(D23=0,0,V23-U23) -> 0 | X23: =IFERROR(V23/U23,"0%") -> 0% | Z23: =Z22+1 -> 45295 | AA23: =AA22+1 -> 45295 | AB23: 45295 | AC23: 1 | AD23: 木 | AE23: =IFERROR(AVERAGEIFS(J20:J50,D20:D50,1,G20:G50,"thu"),0) -> 56700 | AF23: =COUNTIFS(D20:D50,1,G20:G50,"thu") -> 3 | AH23: =AE23*AF23 -> 170100 | AI23: =AH23/$M$6 -> 0.089352314
C24: =C23+1 -> 5 | D24: 1 | E24: =TEXT(AA24,"m") -> 1 | F24: =F23+1 -> 45296 | G24: =TEXT(Z24,"ddd") -> Fri | J24: 122350 | L24: =IF(D24=0,0,$K$6) -> 90920.969 | M24: =IF(D24=0,0,J24-L24) -> 31429.031 | N24: =IFERROR(J24/L24,"0%") -> 1.3456742 | P24: =IF(D24=0,0,SUM($L$20:L24)) -> 90920.969 | Q24: =IF(D24=0,0,SUM($J$20:J24)) -> 122350 | R24: =IF(D24=0,0,Q24-P24) -> 31429.031 | S24: =IFERROR(Q24/P24,"0%") -> 1.3456742 | U24: =IF(D24=0,0,SUM($L$20:L24)) -> 90920.969 | V24: =IF(D24=0,0,SUM($J$20:J24)) -> 122350 | W24: =IF(D24=0,0,V24-U24) -> 31429.031 | X24: =IFERROR(V24/U24,"0%") -> 1.3456742 | Z24: =Z23+1 -> 45296 | AA24: =AA23+1 -> 45296 | AB24: 45296 | AC24: 1 | AD24: 金 | AE24: =IFERROR(AVERAGEIFS(J20:J50,D20:D50,1,G20:G50,"fri"),0) -> 128412.5 | AF24: =COUNTIFS(D20:D50,1,G20:G50,"fri") -> 4 | AH24: =AE24*AF24 -> 513650 | AI24: =AH24/$M$6 -> 0.26981667
C25: =C24+1 -> 6 | D25: 0 | E25: =TEXT(AA25,"m") -> 1 | F25: =F24+1 -> 45297 | G25: =TEXT(Z25,"ddd") -> Sat | J25: 0 | L25: =IF(D25=0,0,$K$6) -> 0 | M25: =IF(D25=0,0,J25-L25) -> 0 | N25: =IFERROR(J25/L25,"0%") -> 0% | P25: =IF(D25=0,0,SUM($L$20:L25)) -> 0 | Q25: =IF(D25=0,0,SUM($J$20:J25)) -> 0 | R25: =IF(D25=0,0,Q25-P25) -> 0 | S25: =IFERROR(Q25/P25,"0%") -> 0% | U25: =IF(D25=0,0,SUM($L$20:L25)) -> 0 | V25: =IF(D25=0,0,SUM($J$20:J25)) -> 0 | W25: =IF(D25=0,0,V25-U25) -> 0 | X25: =IFERROR(V25/U25,"0%") -> 0% | Z25: =Z24+1 -> 45297 | AA25: =AA24+1 -> 45297 | AB25: 45297 | AC25: 1 | AD25: 土 | AE25: =IFERROR(AVERAGEIFS(J20:J50,D20:D50,1,G20:G50,"sat"),0) -> 80700 | AF25: =COUNTIFS(D20:D50,1,G20:G50,"sat") -> 3 | AH25: =AE25*AF25 -> 242100 | AI25: =AH25/$M$6 -> 0.1271734
C26: =C25+1 -> 7 | D26: 1 | E26: =TEXT(AA26,"m") -> 1 | F26: =F25+1 -> 45298 | G26: =TEXT(Z26,"ddd") -> Sun | H26: 日曜日 | J26: 63100 | L26: =IF(D26=0,0,$K$6) -> 90920.969 | M26: =IF(D26=0,0,J26-L26) -> -27820.969 | N26: =IFERROR(J26/L26,"0%") -> 0.69400932 | P26: =IF(D26=0,0,SUM($L$20:L26)) -> 181841.94 | Q26: =IF(D26=0,0,SUM($J$20:J26)) -> 185450 | R26: =IF(D26=0,0,Q26-P26) -> 3608.0619 | S26: =IFERROR(Q26/P26,"0%") -> 1.0198417 | U26: =IF(D26=0,0,SUM($L$20:L26)) -> 181841.94 | V26: =IF(D26=0,0,SUM($J$20:J26)) -> 185450 | W26: =IF(D26=0,0,V26-U26) -> 3608.0619 | X26: =IFERROR(V26/U26,"0%") -> 1.0198417 | Z26: =Z25+1 -> 45298 | AA26: =AA25+1 -> 45298 | AB26: 45298 | AC26: 1 | AD26: 日 | AE26: =IFERROR(AVERAGEIFS(J20:J50,D20:D50,1,G20:G50,"sun"),0) -> 88412.5 | AF26: =IFERROR(COUNTIFS(D20:D50,1,G20:G50,"sun"),0) -> 4 | AH26: =AE26*AF26 -> 353650 | AI26: =AH26/$M$6 -> 0.18576982
C27: =C26+1 -> 8 | D27: 0 | E27: =TEXT(AA27,"m") -> 1 | F27: =F26+1 -> 45299 | G27: =TEXT(Z27,"ddd") -> Mon | L27: =IF(D27=0,0,$K$6) -> 0 | M27: =IF(D27=0,0,J27-L27) -> 0 | N27: =IFERROR(J27/L27,"0%") -> 0% | P27: =IF(D27=0,0,SUM($L$20:L27)) -> 0 | Q27: =IF(D27=0,0,SUM($J$20:J27)) -> 0 | R27: =IF(D27=0,0,Q27-P27) -> 0 | S27: =IFERROR(Q27/P27,"0%") -> 0% | U27: =IF(D27=0,0,SUM($L$20:L27)) -> 0 | V27: =IF(D27=0,0,SUM($J$20:J27)) -> 0 | W27: =IF(D27=0,0,V27-U27) -> 0 | X27: =IFERROR(V27/U27,"0%") -> 0% | Z27: =Z26+1 -> 45299 | AA27: =AA26+1 -> 45299 | AB27: 45299 | AC27: 2 | AD27: 月 | AE27: =IFERROR(AVERAGEIFS(J51:J79,D51:D79,1,G51:G79,"mon"),0) -> 0 | AF27: =COUNTIFS(D51:D79,1,G51:G79,"Mon") -> 0 | AH27: =AE27*AF27 -> 0 | AI27: =AH27/$M$7 -> 0 | AJ27: =SUM(AI27:AI33) -> 1 | AK27: 51〜79
C28: =C27+1 -> 9 | D28: 1 | E28: =TEXT(AA28,"m") -> 1 | F28: =F27+1 -> 45300 | G28: =TEXT(Z28,"ddd") -> Tue | J28: 130500 | L28: =IF(D28=0,0,$K$6) -> 90920.969 | M28: =IF(D28=0,0,J28-L28) -> 39579.031 | N28: =IFERROR(J28/L28,"0%") -> 1.4353125 | P28: =IF(D28=0,0,SUM($L$20:L28)) -> 272762.91 | Q28: =IF(D28=0,0,SUM($J$20:J28)) -> 315950 | R28: =IF(D28=0,0,Q28-P28) -> 43187.093 | S28: =IFERROR(Q28/P28,"0%") -> 1.158332 | U28: =IF(D28=0,0,SUM($L$20:L28)) -> 272762.91 | V28: =IF(D28=0,0,SUM($J$20:J28)) -> 315950 | W28: =IF(D28=0,0,V28-U28) -> 43187.093 | X28: =IFERROR(V28/U28,"0%") -> 1.158332 | Z28: =Z27+1 -> 45300 | AA28: =AA27+1 -> 45300 | AB28: 45300 | AC28: 2 | AD28: 火 | AE28: =AVERAGEIFS(J51:J79,D51:D79,1,G51:G79,"tue") -> 66212.5 | AF28: =COUNTIFS(D51:D79,1,G51:G79,"tue") -> 4 | AH28: =AE28*AF28 -> 264850 | AI28: =AH28/$M$7 -> 0.1175883
C29: =C28+1 -> 10 | D29: 1 | E29: =TEXT(AA29,"m") -> 1 | F29: =F28+1 -> 45301 | G29: =TEXT(Z29,"ddd") -> Wed | J29: 106200 | L29: =IF(D29=0,0,$K$6) -> 90920.969 | M29: =IF(D29=0,0,J29-L29) -> 15279.031 | N29: =IFERROR(J29/L29,"0%") -> 1.1680474 | P29: =IF(D29=0,0,SUM($L$20:L29)) -> 363683.88 | Q29: =IF(D29=0,0,SUM($J$20:J29)) -> 422150 | R29: =IF(D29=0,0,Q29-P29) -> 58466.124 | S29: =IFERROR(Q29/P29,"0%") -> 1.1607608 | U29: =IF(D29=0,0,SUM($L$20:L29)) -> 363683.88 | V29: =IF(D29=0,0,SUM($J$20:J29)) -> 422150 | W29: =IF(D29=0,0,V29-U29) -> 58466.124 | X29: =IFERROR(V29/U29,"0%") -> 1.1607608 | Z29: =Z28+1 -> 45301 | AA29: =AA28+1 -> 45301 | AB29: 45301 | AC29: 2 | AD29: 水 | AE29: =AVERAGEIFS(J51:J79,D51:D79,1,G51:G79,"wed") -> 86962.5 | AF29: =COUNTIFS(D51:D79,1,G51:G79,"wed") -> 4 | AH29: =AE29*AF29 -> 347850 | AI29: =AH29/$M$7 -> 0.1544387
C30: =C29+1 -> 11 | D30: 1 | E30: =TEXT(AA30,"m") -> 1 | F30: =F29+1 -> 45302 | G30: =TEXT(Z30,"ddd") -> Thu | J30: 61950 | L30: =IF(D30=0,0,$K$6) -> 90920.969 | M30: =IF(D30=0,0,J30-L30) -> -28970.969 | N30: =IFERROR(J30/L30,"0%") -> 0.68136097 | P30: =IF(D30=0,0,SUM($L$20:L30)) -> 454604.85 | Q30: =IF(D30=0,0,SUM($J$20:J30)) -> 484100 | R30: =IF(D30=0,0,Q30-P30) -> 29495.155 | S30: =IFERROR(Q30/P30,"0%") -> 1.0648809 | U30: =IF(D30=0,0,SUM($L$20:L30)) -> 454604.85 | V30: =IF(D30=0,0,SUM($J$20:J30)) -> 484100 | W30: =IF(D30=0,0,V30-U30) -> 29495.155 | X30: =IFERROR(V30/U30,"0%") -> 1.0648809 | Z30: =Z29+1 -> 45302 | AA30: =AA29+1 -> 45302 | AB30: 45302 | AC30: 2 | AD30: 木 | AE30: =AVERAGEIFS(J51:J79,D51:D79,1,G51:G79,"thu") -> 95650 | AF30: =COUNTIFS(D51:D79,1,G51:G79,"thu") -> 5 | AH30: =AE30*AF30 -> 478250 | AI30: =AH30/$M$7 -> 0.21233378
C31: =C30+1 -> 12 | D31: 1 | E31: =TEXT(AA31,"m") -> 1 | F31: =F30+1 -> 45303 | G31: =TEXT(Z31,"ddd") -> Fri | J31: 132500 | L31: =IF(D31=0,0,$K$6) -> 90920.969 | M31: =IF(D31=0,0,J31-L31) -> 41579.031 | N31: =IFERROR(J31/L31,"0%") -> 1.4573096 | P31: =IF(D31=0,0,SUM($L$20:L31)) -> 545525.81 | Q31: =IF(D31=0,0,SUM($J$20:J31)) -> 616600 | R31: =IF(D31=0,0,Q31-P31) -> 71074.186 | S31: =IFERROR(Q31/P31,"0%") -> 1.1302857 | U31: =IF(D31=0,0,SUM($L$20:L31)) -> 545525.81 | V31: =IF(D31=0,0,SUM($J$20:J31)) -> 616600 | W31: =IF(D31=0,0,V31-U31) -> 71074.186 | X31: =IFERROR(V31/U31,"0%") -> 1.1302857 | Z31: =Z30+1 -> 45303 | AA31: =AA30+1 -> 45303 | AB31: 45303 | AC31: 2 | AD31: 金 | AE31: =AVERAGEIFS(J51:J79,D51:D79,1,G51:G79,"fri") -> 113575 | AF31: =COUNTIFS(D51:D79,1,G51:G79,"fri") -> 4 | AH31: =AE31*AF31 -> 454300 | AI31: =AH31/$M$7 -> 0.20170045
C32: =C31+1 -> 13 | D32: 1 | E32: =TEXT(AA32,"m") -> 1 | F32: =F31+1 -> 45304 | G32: =TEXT(Z32,"ddd") -> Sat | J32: 86150 | L32: =IF(D32=0,0,$K$6) -> 90920.969 | M32: =IF(D32=0,0,J32-L32) -> -4770.9691 | N32: =IFERROR(J32/L32,"0%") -> 0.9475262 | P32: =IF(D32=0,0,SUM($L$20:L32)) -> 636446.78 | Q32: =IF(D32=0,0,SUM($J$20:J32)) -> 702750 | R32: =IF(D32=0,0,Q32-P32) -> 66303.216 | S32: =IFERROR(Q32/P32,"0%") -> 1.1041772 | U32: =IF(D32=0,0,SUM($L$20:L32)) -> 636446.78 | V32: =IF(D32=0,0,SUM($J$20:J32)) -> 702750 | W32: =IF(D32=0,0,V32-U32) -> 66303.216 | X32: =IFERROR(V32/U32,"0%") -> 1.1041772 | Z32: =Z31+1 -> 45304 | AA32: =AA31+1 -> 45304 | AB32: 45304 | AC32: 2 | AD32: 土 | AE32: =AVERAGEIFS(J51:J79,D51:D79,1,G51:G79,"sat") -> 73337.5 | AF32: =COUNTIFS(D51:D79,1,G51:G79,"sat") -> 4 | AH32: =AE32*AF32 -> 293350 | AI32: =AH32/$M$7 -> 0.13024175
C33: =C32+1 -> 14 | D33: 1 | E33: =TEXT(AA33,"m") -> 1 | F33: =F32+1 -> 45305 | G33: =TEXT(Z33,"ddd") -> Sun | J33: 79100 | L33: =IF(D33=0,0,$K$6) -> 90920.969 | M33: =IF(D33=0,0,J33-L33) -> -11820.969 | N33: =IFERROR(J33/L33,"0%") -> 0.86998633 | P33: =IF(D33=0,0,SUM($L$20:L33)) -> 727367.75 | Q33: =IF(D33=0,0,SUM($J$20:J33)) -> 781850 | R33: =IF(D33=0,0,Q33-P33) -> 54482.247 | S33: =IFERROR(Q33/P33,"0%") -> 1.0749033 | U33: =IF(D33=0,0,SUM($L$20:L33)) -> 727367.75 | V33: =IF(D33=0,0,SUM($J$20:J33)) -> 781850 | W33: =IF(D33=0,0,V33-U33) -> 54482.247 | X33: =IFERROR(V33/U33,"0%") -> 1.0749033 | Z33: =Z32+1 -> 45305 | AA33: =AA32+1 -> 45305 | AB33: 45305 | AC33: 2 | AD33: 日 | AE33: =IFERROR(AVERAGEIFS(J51:J79,D51:D79,1,G51:G79,"sun"),0) -> 103437.5 | AF33: =IFERROR(COUNTIFS(D51:D79,1,G51:G79,"sun"),0) -> 4 | AH33: =AE33*AF33 -> 413750 | AI33: =AH33/$M$7 -> 0.18369703
C34: =C33+1 -> 15 | D34: 0 | E34: =TEXT(AA34,"m") -> 1 | F34: =F33+1 -> 45306 | G34: =TEXT(Z34,"ddd") -> Mon | L34: =IF(D34=0,0,$K$6) -> 0 | M34: =IF(D34=0,0,J34-L34) -> 0 | N34: =IFERROR(J34/L34,"0%") -> 0% | P34: =IF(D34=0,0,SUM($L$20:L34)) -> 0 | Q34: =IF(D34=0,0,SUM($J$20:J34)) -> 0 | R34: =IF(D34=0,0,Q34-P34) -> 0 | S34: =IFERROR(Q34/P34,"0%") -> 0% | U34: =IF(D34=0,0,SUM($L$20:L34)) -> 0 | V34: =IF(D34=0,0,SUM($J$20:J34)) -> 0 | W34: =IF(D34=0,0,V34-U34) -> 0 | X34: =IFERROR(V34/U34,"0%") -> 0% | Z34: =Z33+1 -> 45306 | AA34: =AA33+1 -> 45306 | AB34: 45306 | AC34: 3 | AD34: 月 | AE34: =IFERROR(AVERAGEIFS(J80:J110,D80:D110,1,G80:G110,"mon"),0) -> 0 | AF34: =COUNTIFS( D80:D110,1,G80:G110,"Mon") -> 0 | AH34: =AE34*AF34 -> 0 | AI34: =AH34/$M$8 -> 0 | AJ34: =SUM(AI34:AI40) -> 0.7752245 | AK34: 80〜110
C35: =C34+1 -> 16 | D35: 1 | E35: =TEXT(AA35,"m") -> 1 | F35: =F34+1 -> 45307 | G35: =TEXT(Z35,"ddd") -> Tue | J35: 62550 | L35: =IF(D35=0,0,$K$6) -> 90920.969 | M35: =IF(D35=0,0,J35-L35) -> -28370.969 | N35: =IFERROR(J35/L35,"0%") -> 0.68796011 | P35: =IF(D35=0,0,SUM($L$20:L35)) -> 818288.72 | Q35: =IF(D35=0,0,SUM($J$20:J35)) -> 844400 | R35: =IF(D35=0,0,Q35-P35) -> 26111.278 | S35: =IFERROR(Q35/P35,"0%") -> 1.0319096 | U35: =IF(D35=0,0,SUM($L$20:L35)) -> 818288.72 | V35: =IF(D35=0,0,SUM($J$20:J35)) -> 844400 | W35: =IF(D35=0,0,V35-U35) -> 26111.278 | X35: =IFERROR(V35/U35,"0%") -> 1.0319096 | Z35: =Z34+1 -> 45307 | AA35: =AA34+1 -> 45307 | AB35: 45307 | AC35: 3 | AD35: 火 | AE35: =AVERAGEIFS(J80:J110,D80:D110,1,G80:G110,"tue") -> 67850 | AF35: =COUNTIFS( D80:D110,1,G80:G110,"tue") -> 3 | AH35: =AE35*AF35 -> 203550 | AI35: =AH35/$M$8 -> 0.081418372
C36: =C35+1 -> 17 | D36: 1 | E36: =TEXT(AA36,"m") -> 1 | F36: =F35+1 -> 45308 | G36: =TEXT(Z36,"ddd") -> Wed | J36: 88700 | L36: =IF(D36=0,0,$K$6) -> 90920.969 | M36: =IF(D36=0,0,J36-L36) -> -2220.9691 | N36: =IFERROR(J36/L36,"0%") -> 0.97557253 | P36: =IF(D36=0,0,SUM($L$20:L36)) -> 909209.69 | Q36: =IF(D36=0,0,SUM($J$20:J36)) -> 933100 | R36: =IF(D36=0,0,Q36-P36) -> 23890.309 | S36: =IFERROR(Q36/P36,"0%") -> 1.0262759 | U36: =IF(D36=0,0,SUM($L$20:L36)) -> 909209.69 | V36: =IF(D36=0,0,SUM($J$20:J36)) -> 933100 | W36: =IF(D36=0,0,V36-U36) -> 23890.309 | X36: =IFERROR(V36/U36,"0%") -> 1.0262759 | Z36: =Z35+1 -> 45308 | AA36: =AA35+1 -> 45308 | AB36: 45308 | AC36: 3 | AD36: 水 | AE36: =AVERAGEIFS(J80:J110,D80:D110,1,G80:G110,"wed") -> 82283.333 | AF36: =COUNTIFS( D80:D110,1,G80:G110,"wed") -> 3 | AH36: =AE36*AF36 -> 246850 | AI36: =AH36/$M$8 -> 0.098738025
C37: =C36+1 -> 18 | D37: 1 | E37: =TEXT(AA37,"m") -> 1 | F37: =F36+1 -> 45309 | G37: =TEXT(Z37,"ddd") -> Thu | J37: 83850 | L37: =IF(D37=0,0,$K$6) -> 90920.969 | M37: =IF(D37=0,0,J37-L37) -> -7070.9691 | N37: =IFERROR(J37/L37,"0%") -> 0.9222295 | P37: =IF(D37=0,0,SUM($L$20:L37)) -> 1000130.7 | Q37: =IF(D37=0,0,SUM($J$20:J37)) -> 1016950 | R37: =IF(D37=0,0,Q37-P37) -> 16819.34 | S37: =IFERROR(Q37/P37,"0%") -> 1.0168171 | U37: =IF(D37=0,0,SUM($L$20:L37)) -> 1000130.7 | V37: =IF(D37=0,0,SUM($J$20:J37)) -> 1016950 | W37: =IF(D37=0,0,V37-U37) -> 16819.34 | X37: =IFERROR(V37/U37,"0%") -> 1.0168171 | Z37: =Z36+1 -> 45309 | AA37: =AA36+1 -> 45309 | AB37: 45309 | AC37: 3 | AD37: 木 | AE37: =AVERAGEIFS(J80:J110,D80:D110,1,G80:G110,"thu") -> 67162.5 | AF37: =COUNTIFS( D80:D110,1,G80:G110,"thu") -> 4 | AH37: =AE37*AF37 -> 268650 | AI37: =AH37/$M$8 -> 0.10745785
C38: =C37+1 -> 19 | D38: 1 | E38: =TEXT(AA38,"m") -> 1 | F38: =F37+1 -> 45310 | G38: =TEXT(Z38,"ddd") -> Fri | J38: 157100 | L38: =IF(D38=0,0,$K$6) -> 90920.969 | M38: =IF(D38=0,0,J38-L38) -> 66179.031 | N38: =IFERROR(J38/L38,"0%") -> 1.7278742 | P38: =IF(D38=0,0,SUM($L$20:L38)) -> 1091051.6 | Q38: =IF(D38=0,0,SUM($J$20:J38)) -> 1174050 | R38: =IF(D38=0,0,Q38-P38) -> 82998.371 | S38: =IFERROR(Q38/P38,"0%") -> 1.0760719 | U38: =IF(D38=0,0,SUM($L$20:L38)) -> 1091051.6 | V38: =IF(D38=0,0,SUM($J$20:J38)) -> 1174050 | W38: =IF(D38=0,0,V38-U38) -> 82998.371 | X38: =IFERROR(V38/U38,"0%") -> 1.0760719 | Z38: =Z37+1 -> 45310 | AA38: =AA37+1 -> 45310 | AB38: 45310 | AC38: 3 | AD38: 金 | AE38: =AVERAGEIFS(J80:J110,D80:D110,1,G80:G110,"fri") -> 144820 | AF38: =COUNTIFS( D80:D110,1,G80:G110,"fri") -> 5 | AH38: =AE38*AF38 -> 724100 | AI38: =AH38/$M$8 -> 0.28963421
C39: =C38+1 -> 20 | D39: 1 | E39: =TEXT(AA39,"m") -> 1 | F39: =F38+1 -> 45311 | G39: =TEXT(Z39,"ddd") -> Sat | J39: 76850 | L39: =IF(D39=0,0,$K$6) -> 90920.969 | M39: =IF(D39=0,0,J39-L39) -> -14070.969 | N39: =IFERROR(J39/L39,"0%") -> 0.84523956 | P39: =IF(D39=0,0,SUM($L$20:L39)) -> 1181972.6 | Q39: =IF(D39=0,0,SUM($J$20:J39)) -> 1250900 | R39: =IF(D39=0,0,Q39-P39) -> 68927.402 | S39: =IFERROR(Q39/P39,"0%") -> 1.0583156 | U39: =IF(D39=0,0,SUM($L$20:L39)) -> 1181972.6 | V39: =IF(D39=0,0,SUM($J$20:J39)) -> 1250900 | W39: =IF(D39=0,0,V39-U39) -> 68927.402 | X39: =IFERROR(V39/U39,"0%") -> 1.0583156 | Z39: =Z38+1 -> 45311 | AA39: =AA38+1 -> 45311 | AB39: 45311 | AC39: 3 | AD39: 土 | AE39: =AVERAGEIFS(J80:J110,D80:D110,1,G80:G110,"sat") -> 98990 | AF39: =COUNTIFS( D80:D110,1,G80:G110,"sat") -> 5 | AH39: =AE39*AF39 -> 494950 | AI39: =AH39/$M$8 -> 0.19797604
C40: =C39+1 -> 21 | D40: 1 | E40: =TEXT(AA40,"m") -> 1 | F40: =F39+1 -> 45312 | G40: =TEXT(Z40,"ddd") -> Sun | H40: 日曜日 | J40: 101650 | L40: =IF(D40=0,0,$K$6) -> 90920.969 | M40: =IF(D40=0,0,J40-L40) -> 10729.031 | N40: =IFERROR(J40/L40,"0%") -> 1.1180039 | P40: =IF(D40=0,0,SUM($L$20:L40)) -> 1272893.6 | Q40: =IF(D40=0,0,SUM($J$20:J40)) -> 1352550 | R40: =IF(D40=0,0,Q40-P40) -> 79656.433 | S40: =IFERROR(Q40/P40,"0%") -> 1.062579 | U40: =IF(D40=0,0,SUM($L$20:L40)) -> 1272893.6 | V40: =IF(D40=0,0,SUM($J$20:J40)) -> 1352550 | W40: =IF(D40=0,0,V40-U40) -> 79656.433 | X40: =IFERROR(V40/U40,"0%") -> 1.062579 | Z40: =Z39+1 -> 45312 | AA40: =AA39+1 -> 45312 | AB40: 45312 | AC40: 3 | AD40: 日 | AE40: =IFERROR(AVERAGEIFS(J80:J110,D80:D110,3,G80:G110,"sun"),0) -> 0 | AF40: =IFERROR(COUNTIFS( D80:D110,1,G80:G110,"sun"),0) -> 5 | AH40: =AE40*AF40 -> 0 | AI40: =AH40/$M$8 -> 0
C41: =C40+1 -> 22 | D41: 0 | E41: =TEXT(AA41,"m") -> 1 | F41: =F40+1 -> 45313 | G41: =TEXT(Z41,"ddd") -> Mon | L41: =IF(D41=0,0,$K$6) -> 0 | M41: =IF(D41=0,0,J41-L41) -> 0 | N41: =IFERROR(J41/L41,"0%") -> 0% | P41: =IF(D41=0,0,SUM($L$20:L41)) -> 0 | Q41: =IF(D41=0,0,SUM($J$20:J41)) -> 0 | R41: =IF(D41=0,0,Q41-P41) -> 0 | S41: =IFERROR(Q41/P41,"0%") -> 0% | U41: =IF(D41=0,0,SUM($L$20:L41)) -> 0 | V41: =IF(D41=0,0,SUM($J$20:J41)) -> 0 | W41: =IF(D41=0,0,V41-U41) -> 0 | X41: =IFERROR(V41/U41,"0%") -> 0% | Z41: =Z40+1 -> 45313 | AA41: =AA40+1 -> 45313 | AB41: 45313 | AC41: 4 | AD41: 月 | AE41: =IFERROR(AVERAGEIFS(J111:J140,D111:D140,1,G111:G140,"mon"),0) -> 0 | AF41: =COUNTIFS(D111:D140,1,G111:G140,"Mon") -> 0 | AH41: =AE41*AF41 -> 0 | AI41: =AH41/$M$9 -> 0 | AJ41: =SUM(AI41:AI47) -> 1 | AK41: 111〜140
C42: =C41+1 -> 23 | D42: 1 | E42: =TEXT(AA42,"m") -> 1 | F42: =F41+1 -> 45314 | G42: =TEXT(Z42,"ddd") -> Tue | J42: 122600 | L42: =IF(D42=0,0,$K$6) -> 90920.969 | M42: =IF(D42=0,0,J42-L42) -> 31679.031 | N42: =IFERROR(J42/L42,"0%") -> 1.3484238 | P42: =IF(D42=0,0,SUM($L$20:L42)) -> 1363814.5 | Q42: =IF(D42=0,0,SUM($J$20:J42)) -> 1475150 | R42: =IF(D42=0,0,Q42-P42) -> 111335.46 | S42: =IFERROR(Q42/P42,"0%") -> 1.0816353 | U42: =IF(D42=0,0,SUM($L$20:L42)) -> 1363814.5 | V42: =IF(D42=0,0,SUM($J$20:J42)) -> 1475150 | W42: =IF(D42=0,0,V42-U42) -> 111335.46 | X42: =IFERROR(V42/U42,"0%") -> 1.0816353 | Z42: =Z41+1 -> 45314 | AA42: =AA41+1 -> 45314 | AB42: 45314 | AC42: 4 | AD42: 火 | AE42: =AVERAGEIFS(J111:J140,D111:D140,1,G111:G140,"tue") -> 102760 | AF42: =COUNTIFS(D111:D140,1,G111:G140,"tue") -> 5 | AH42: =AE42*AF42 -> 513800 | AI42: =AH42/$M$9 -> 0.18802606
C43: =C42+1 -> 24 | D43: 0 | E43: =TEXT(AA43,"m") -> 1 | F43: =F42+1 -> 45315 | G43: =TEXT(Z43,"ddd") -> Wed | L43: =IF(D43=0,0,$K$6) -> 0 | M43: =IF(D43=0,0,J43-L43) -> 0 | N43: =IFERROR(J43/L43,"0%") -> 0% | P43: =IF(D43=0,0,SUM($L$20:L43)) -> 0 | Q43: =IF(D43=0,0,SUM($J$20:J43)) -> 0 | R43: =IF(D43=0,0,Q43-P43) -> 0 | S43: =IFERROR(Q43/P43,"0%") -> 0% | U43: =IF(D43=0,0,SUM($L$20:L43)) -> 0 | V43: =IF(D43=0,0,SUM($J$20:J43)) -> 0 | W43: =IF(D43=0,0,V43-U43) -> 0 | X43: =IFERROR(V43/U43,"0%") -> 0% | Z43: =Z42+1 -> 45315 | AA43: =AA42+1 -> 45315 | AB43: 45315 | AC43: 4 | AD43: 水 | AE43: =AVERAGEIFS(J111:J140,D111:D140,1,G111:G140,"wed") -> 80675 | AF43: =COUNTIFS(D111:D140,1,G111:G140,"wed") -> 4 | AH43: =AE43*AF43 -> 322700 | AI43: =AH43/$M$9 -> 0.11809266
...

Sheet 適正原価＆人件費プリントアウト用
A1: =TODAY() -> 45975 | C1: 月 | H1: 営業日数 | I1: {=INDIRECT("'適正原価率表(仕入れお小遣い制度)'!C" & (2 * MONTH(A1) + 2))} -> 22
A2: 月次適正原価率表
B3: 月次 | F3: 日次
A4: フード | B4: {=INDEX('適正原価率表(仕入れお小遣い制度)'!I:I, MONTH(A1)*2+2)} -> 295576.49 | F4: {=INDEX('適正原価率表(仕入れお小遣い制度)'!J:J, MONTH(A1)*2+2)} -> 13435.295
A5: ドリンク | B5: {=INDEX('適正原価率表(仕入れお小遣い制度)'!I:I, MONTH(A1)*2+3)} -> 256557.25 | F5: {=INDEX('適正原価率表(仕入れお小遣い制度)'!J:J, MONTH(A1)*2+3)} -> 11661.693
A7: 月次適正人件費表
B8: 1日 | D8: フード | G8: ドリンク
A9: ランチ | B9: {=INDIRECT("'適正人件費表'!J" & (2 * MONTH(A1) + 2))} -> 3 | D9: =1 + IF(B9-4 >= 8, 1, 0) + IF(B9-4 >= 9, 1, 0) -> 1 | G9: =1 + IF(B9-4 >= 4, 1, 0) + IF(B9-4 >= 5, 1, 0) -> 1
A10: ディナー | D10: =1 + IF(B9-4 >= 6, 1, 0) + IF(B9-4 >= 7, 1, 0) -> 1 | G10: =1 + IF(B9-4 >= 1, 1, 0) + IF(B9-4 >= 2, 1, 0) + IF(B9-4 >= 3, 1, 0) -> 1

Sheet 月次累積原価率表
A1: 45658 | B1: 【食材費】フード適正早見表 | K1: 【食材費】ドリンク適正早見表
B3: 1月 | E3: フード目標日次 | F3: フード目標累計 | G3: フード実績 | H3: フード累積 | I3: 差額 | K3: =B3 -> 1月 | N3: ドリンク目標日次 | O3: ドリンク目標累計 | P3: ドリンク実績 | Q3: ドリンク累積 | R3: 差額
B4: =A1 -> 45658 | C4: =B4 -> 45658 | D4: =目標_2025R7!D21 -> 0 | E4: =IF(D4=1,'適正原価率表(仕入れお小遣い制度)'!$J$4,0) -> 0 | F4: =IF(D4=1,E4,0) -> 0 | H4: =IF(D4=1,G4,0) -> 0 | I4: =IF(D4=1,F4-H4,0) -> 0 | K4: =B4 -> 45658 | L4: =C4 -> 45658 | M4: =D4 -> 0 | N4: =IF(M4=1,'適正原価率表(仕入れお小遣い制度)'!$J$5,0) -> 0 | O4: =IF(M4=1,N4,0) -> 0 | Q4: =IF(M4=1,P4,0) -> 0 | R4: =IF(D4=1,O4-Q4,0) -> 0 | T4: =A1 -> 45658
B5: =B4+1 -> 45659 | C5: =B5 -> 45659 | D5: =目標_2025R7!D22 -> 0 | E5: =IF(D5=1,'適正原価率表(仕入れお小遣い制度)'!$J$4,0) -> 0 | F5: =IF(D5=1,SUM($E$4:E5),0) -> 0 | H5: =IF(D5=1,SUM($G$4:G5),0) -> 0 | I5: =IF(D5=1,F5-H5,0) -> 0 | K5: 45659 | L5: =C5 -> 45659 | M5: =D5 -> 0 | N5: =IF(M5=1,'適正原価率表(仕入れお小遣い制度)'!$J$5,0) -> 0 | O5: =IF(M5=1,SUM($N$4:N5),0) -> 0 | Q5: =IF(M5=1,SUM($P$4:P5),0) -> 0 | R5: =IF(D5=1,O5-Q5,0) -> 0 | T5: =T4+1 -> 45659
B6: =B5+1 -> 45660 | C6: =B6 -> 45660 | D6: =目標_2025R7!D23 -> 0 | E6: =IF(D6=1,'適正原価率表(仕入れお小遣い制度)'!$J$4,0) -> 0 | F6: =IF(D6=1,SUM($E$4:E6),0) -> 0 | H6: =IF(D6=1,SUM($G$4:G6),0) -> 0 | I6: =IF(D6=1,F6-H6,0) -> 0 | K6: 45660 | L6: =C6 -> 45660 | M6: =D6 -> 0 | N6: =IF(M6=1,'適正原価率表(仕入れお小遣い制度)'!$J$5,0) -> 0 | O6: =IF(M6=1,SUM($N$4:N6),0) -> 0 | Q6: =IF(M6=1,SUM($P$4:P6),0) -> 0 | R6: =IF(D6=1,O6-Q6,0) -> 0 | T6: =T5+1 -> 45660
B7: =B6+1 -> 45661 | C7: =B7 -> 45661 | D7: =目標_2025R7!D24 -> 0 | E7: =IF(D7=1,'適正原価率表(仕入れお小遣い制度)'!$J$4,0) -> 0 | F7: =IF(D7=1,SUM($E$4:E7),0) -> 0 | H7: =IF(D7=1,SUM($G$4:G7),0) -> 0 | I7: =IF(D7=1,F7-H7,0) -> 0 | K7: 45661 | L7: =C7 -> 45661 | M7: =D7 -> 0 | N7: =IF(M7=1,'適正原価率表(仕入れお小遣い制度)'!$J$5,0) -> 0 | O7: =IF(M7=1,SUM($N$4:N7),0) -> 0 | Q7: =IF(M7=1,SUM($P$4:P7),0) -> 0 | R7: =IF(D7=1,O7-Q7,0) -> 0 | T7: =T6+1 -> 45661
B8: =B7+1 -> 45662 | C8: =B8 -> 45662 | D8: =目標_2025R7!D25 -> 0 | E8: =IF(D8=1,'適正原価率表(仕入れお小遣い制度)'!$J$4,0) -> 0 | F8: =IF(D8=1,SUM($E$4:E8),0) -> 0 | H8: =IF(D8=1,SUM($G$4:G8),0) -> 0 | I8: =IF(D8=1,F8-H8,0) -> 0 | K8: 45662 | L8: =C8 -> 45662 | M8: =D8 -> 0 | N8: =IF(M8=1,'適正原価率表(仕入れお小遣い制度)'!$J$5,0) -> 0 | O8: =IF(M8=1,SUM($N$4:N8),0) -> 0 | Q8: =IF(M8=1,SUM($P$4:P8),0) -> 0 | R8: =IF(D8=1,O8-Q8,0) -> 0 | T8: =T7+1 -> 45662
B9: =B8+1 -> 45663 | C9: =B9 -> 45663 | D9: =目標_2025R7!D26 -> 0 | E9: =IF(D9=1,'適正原価率表(仕入れお小遣い制度)'!$J$4,0) -> 0 | F9: =IF(D9=1,SUM($E$4:E9),0) -> 0 | H9: =IF(D9=1,SUM($G$4:G9),0) -> 0 | I9: =IF(D9=1,F9-H9,0) -> 0 | K9: 45663 | L9: =C9 -> 45663 | M9: =D9 -> 0 | N9: =IF(M9=1,'適正原価率表(仕入れお小遣い制度)'!$J$5,0) -> 0 | O9: =IF(M9=1,SUM($N$4:N9),0) -> 0 | Q9: =IF(M9=1,SUM($P$4:P9),0) -> 0 | R9: =IF(D9=1,O9-Q9,0) -> 0 | T9: =T8+1 -> 45663
B10: =B9+1 -> 45664 | C10: =B10 -> 45664 | D10: =目標_2025R7!D27 -> 1 | E10: =IF(D10=1,'適正原価率表(仕入れお小遣い制度)'!$J$4,0) -> 11755.81 | F10: =IF(D10=1,SUM($E$4:E10),0) -> 11755.81 | H10: =IF(D10=1,SUM($G$4:G10),0) -> 0 | I10: =IF(D10=1,F10-H10,0) -> 11755.81 | K10: 45664 | L10: =C10 -> 45664 | M10: =D10 -> 1 | N10: =IF(M10=1,'適正原価率表(仕入れお小遣い制度)'!$J$5,0) -> 9688.5663 | O10: =IF(M10=1,SUM($N$4:N10),0) -> 9688.5663 | Q10: =IF(M10=1,SUM($P$4:P10),0) -> 0 | R10: =IF(D10=1,O10-Q10,0) -> 9688.5663 | T10: =T9+1 -> 45664
B11: =B10+1 -> 45665 | C11: =B11 -> 45665 | D11: =目標_2025R7!D28 -> 1 | E11: =IF(D11=1,'適正原価率表(仕入れお小遣い制度)'!$J$4,0) -> 11755.81 | F11: =IF(D11=1,SUM($E$4:E11),0) -> 23511.621 | H11: =IF(D11=1,SUM($G$4:G11),0) -> 0 | I11: =IF(D11=1,F11-H11,0) -> 23511.621 | K11: 45665 | L11: =C11 -> 45665 | M11: =D11 -> 1 | N11: =IF(M11=1,'適正原価率表(仕入れお小遣い制度)'!$J$5,0) -> 9688.5663 | O11: =IF(M11=1,SUM($N$4:N11),0) -> 19377.133 | Q11: =IF(M11=1,SUM($P$4:P11),0) -> 0 | R11: =IF(D11=1,O11-Q11,0) -> 19377.133 | T11: =T10+1 -> 45665
B12: =B11+1 -> 45666 | C12: =B12 -> 45666 | D12: =目標_2025R7!D29 -> 1 | E12: =IF(D12=1,'適正原価率表(仕入れお小遣い制度)'!$J$4,0) -> 11755.81 | F12: =IF(D12=1,SUM($E$4:E12),0) -> 35267.431 | H12: =IF(D12=1,SUM($G$4:G12),0) -> 0 | I12: =IF(D12=1,F12-H12,0) -> 35267.431 | K12: 45666 | L12: =C12 -> 45666 | M12: =D12 -> 1 | N12: =IF(M12=1,'適正原価率表(仕入れお小遣い制度)'!$J$5,0) -> 9688.5663 | O12: =IF(M12=1,SUM($N$4:N12),0) -> 29065.699 | Q12: =IF(M12=1,SUM($P$4:P12),0) -> 0 | R12: =IF(D12=1,O12-Q12,0) -> 29065.699 | T12: =T11+1 -> 45666
B13: =B12+1 -> 45667 | C13: =B13 -> 45667 | D13: =目標_2025R7!D30 -> 1 | E13: =IF(D13=1,'適正原価率表(仕入れお小遣い制度)'!$J$4,0) -> 11755.81 | F13: =IF(D13=1,SUM($E$4:E13),0) -> 47023.241 | H13: =IF(D13=1,SUM($G$4:G13),0) -> 0 | I13: =IF(D13=1,F13-H13,0) -> 47023.241 | K13: 45667 | L13: =C13 -> 45667 | M13: =D13 -> 1 | N13: =IF(M13=1,'適正原価率表(仕入れお小遣い制度)'!$J$5,0) -> 9688.5663 | O13: =IF(M13=1,SUM($N$4:N13),0) -> 38754.265 | Q13: =IF(M13=1,SUM($P$4:P13),0) -> 0 | R13: =IF(D13=1,O13-Q13,0) -> 38754.265 | T13: =T12+1 -> 45667
